Workbook

Sheet Summary
A1: #VALUE! | D1: Diriyah II Management Contracting – Opera House Concrete Daily Productivity February to March
A6: S/No. | B6: Levels | C6: Work | D6: Unit | E6: 46054 | AH6: 46082 | BN6: 46113 | CR6: May-26 | DW6: June | FA6: July | GF6: August
E7: 46054 | F7: 46055 | G7: 46056 | H7: 46057 | I7: 46058 | J7: 46059 | K7: 46060 | L7: 46061 | M7: 46062 | N7: 46063 | O7: 46064 | P7: 46065 | Q7: 46066 | R7: 46067 | S7: 46068 | T7: 46069 | U7: 46070 | V7: 46071 | W7: 46072 | X7: 46073 | Y7: 46074 | Z7: 46075 | AA7: 46076 | AB7: 46077 | AC7: 46078 | AD7: 46079 | AE7: 46080 | AF7: 46081 | AH7: 46082 | AI7: 46083 | AJ7: 46084 | AK7: 46085 | AL7: 46086 | AM7: 46087 | AN7: 46088 | AO7: 46089 | AP7: 46090 | AQ7: 46091 | AR7: 46092 | AS7: 46093 | AT7: 46094 | AU7: 46095 | AV7: 46096 | AW7: 46097 | AX7: 46098 | AY7: 46099 | AZ7: 46100 | BA7: 46101 | BB7: 46102 | BC7: 46103 | BD7: 46104 | BE7: 46105 | BF7: 46106 | BG7: 46107 | BH7: 46108 | BI7: 46109 | BJ7: 46110 | BK7: 46111 | BL7: 46112 | BN7: 46113 | BO7: 46114 | BP7: 46115 | BQ7: 46116 | BR7: 46117 | BS7: 46118 | BT7: 46119 | BU7: 46120 | BV7: 46121 | BW7: 46122 | BX7: 46123 | BY7: 46124 | BZ7: 46125 | CA7: 46126 | CB7: 46127 | CC7: 46128 | CD7: 46129 | CE7: 46130 | CF7: 46131 | CG7: 46132 | CH7: 46133 | CI7: 46134 | CJ7: 46135 | CK7: 46136 | CL7: 46137 | CM7: 46138 | CN7: 46139 | CO7: 46140 | CP7: 46141 | CQ7: 46142 | CR7: 46143 | CS7: 46144 | CT7: 46145 | CU7: 46146 | CV7: 46147 | CW7: 46148 | CX7: 46149 | CY7: 46150 | CZ7: 46151 | DA7: 46152 | DB7: 46153 | DC7: 46154 | DD7: 46155 | DE7: 46156 | DF7: 46157 | DG7: 46158 | DH7: 46159 | DI7: 46160 | DJ7: 46161 | DK7: 46162 | DL7: 46163 | DM7: 46164 | DN7: 46165 | DO7: 46166 | DP7: 46167 | DQ7: 46168 | DR7: 46169 | DS7: 46170 | DT7: 46171 | DU7: 46172 | DV7: 46173 | DW7: 46174 | DX7: 46175 | DY7: 46176 | DZ7: 46177 | EA7: 46178 | EB7: 46179 | EC7: 46180 | ED7: 46181 | EE7: 46182 | EF7: 46183 | EG7: 46184 | EH7: 46185 | EI7: 46186 | EJ7: 46187 | EK7: 46188 | EL7: 46189 | EM7: 46190 | EN7: 46191 | EO7: 46192 | EP7: 46193 | EQ7: 46194 | ER7: 46195 | ES7: 46196 | ET7: 46197 | EU7: 46198 | EV7: 46199 | EW7: 46200 | EX7: 46201 | EY7: 46202 | EZ7: 46203 | FA7: 46204 | FB7: 46205 | FC7: 46206 | FD7: 46207 | FE7: 46208 | FF7: 46209 | FG7: 46210 | FH7: 46211 | FI7: 46212 | FJ7: 46213 | FK7: 46214 | FL7: 46215 | FM7: 46216 | FN7: 46217 | FO7: 46218 | FP7: 46219 | FQ7: 46220 | FR7: 46221 | FS7: 46222 | FT7: 46223 | FU7: 46224 | FV7: 46225 | FW7: 46226 | FX7: 46227 | FY7: 46228 | FZ7: 46229 | GA7: 46230 | GB7: 46231 | GC7: 46232 | GD7: 46233 | GE7: 46234 | GF7: 46235 | GG7: 46236 | GH7: 46237 | GI7: 46238 | GJ7: 46239 | GK7: 46240 | GL7: 46241 | GM7: 46242 | GN7: 46243 | GO7: 46244 | GP7: 46245 | GQ7: 46246 | GR7: 46247 | GS7: 46248 | GT7: 46249 | GU7: 46250 | GV7: 46251 | GW7: 46252 | GX7: 46253 | GY7: 46254 | GZ7: Total
A8: Team 1 (Zone 2,3,5,6, & 7)
B9: B2 to B1 | C9: Columns | D9: Nos | E9: =+Columns!O75 -> 0 | F9: =+Columns!P75 -> 0 | G9: =+Columns!Q75 -> 0 | H9: =+Columns!R75 -> 0 | I9: =+Columns!S75 -> 0 | J9: =+Columns!T75 -> 0 | K9: =+Columns!U75 -> 0 | L9: =+Columns!V75 -> 0 | ... GE9: =+Columns!GO75 -> 0
C10: Internal Wall | D10: Lm | E10: =+'Internal Wall'!O88 -> 0 | F10: =+'Internal Wall'!P88 -> 10.2 | G10: =+'Internal Wall'!Q88 -> 0 | H10: =+'Internal Wall'!R88 -> 0 | I10: =+'Internal Wall'!S88 -> 0 | J10: =+'Internal Wall'!T88 -> 0 | K10: =+'Internal Wall'!U88 -> 0 | L10: =+'Internal Wall'!V88 -> 40.2 | ... AF10: =+'Internal Wall'!AP88 -> 0 | AG10: =+'Internal Wall'!BN88 -> 0 | AH10: =+'Internal Wall'!AR88 -> 4.5 | AI10: =+'Internal Wall'!AS88 -> 0 | AJ10: =+'Internal Wall'!AT88 -> 0 | AK10: =+'Internal Wall'!AU88 -> 6.1 | AL10: =+'Internal Wall'!AV88 -> 0 | AM10: =+'Internal Wall'!AW88 -> 0 | AN10: =+'Internal Wall'!AX88 -> 16 | AO10: =+'Internal Wall'!AY88 -> 0 | ... BL10: =+'Internal Wall'!BV88 -> 0 | BM10: =+'Internal Wall'!IR88 -> 0 | BN10: =+'Internal Wall'!BX88 -> 17 | BO10: =+'Internal Wall'!BY88 -> 0 | BP10: =+'Internal Wall'!BZ88 -> 0 | BQ10: =+'Internal Wall'!CA88 -> 0 | BR10: =+'Internal Wall'!CB88 -> 0 | BS10: =+'Internal Wall'!CC88 -> 0 | BT10: =+'Internal Wall'!CD88 -> 80 | BU10: =+'Internal Wall'!CE88 -> 3 | ... GE10: =+'Internal Wall'!GO88 -> 0
C11: External Wall | D11: Lm | E11: =+'External Wall'!O38 -> 16 | F11: =+'External Wall'!P38 -> 26 | G11: =+'External Wall'!Q38 -> 0 | H11: =+'External Wall'!R38 -> 0 | I11: =+'External Wall'!S38 -> 0 | J11: =+'External Wall'!T38 -> 0 | K11: =+'External Wall'!U38 -> 7.6 | L11: =+'External Wall'!V38 -> 0 | ... GE11: =+'External Wall'!GO38 -> 0
C12: Slab | D12: M2 | E12: =+Slab!O74 -> 0 | F12: =+Slab!P74 -> 0 | G12: =+Slab!Q74 -> 0 | H12: =+Slab!R74 -> 0 | I12: =+Slab!S74 -> 0 | J12: =+Slab!T74 -> 0 | K12: =+Slab!U74 -> 0 | L12: =+Slab!V74 -> 0 | ... GE12: =+Slab!GO74 -> 0
B14: B1 to GF | C14: Columns | D14: Nos | E14: =+Columns!O79 -> 2 | F14: =+Columns!P79 -> 2 | G14: =+Columns!Q79 -> 0 | H14: =+Columns!R79 -> 1 | I14: =+Columns!S79 -> 1 | J14: =+Columns!T79 -> 0 | K14: =+Columns!U79 -> 0 | L14: =+Columns!V79 -> 0 | ... GE14: =+Columns!GO79 -> 0
C15: Internal Wall | D15: Lm | E15: =+'Internal Wall'!O92 -> 0 | F15: =+'Internal Wall'!P92 -> 0 | G15: =+'Internal Wall'!Q92 -> 9.5 | H15: =+'Internal Wall'!R92 -> 0 | I15: =+'Internal Wall'!S92 -> 10 | J15: =+'Internal Wall'!T92 -> 0 | K15: =+'Internal Wall'!U92 -> 17.6 | L15: =+'Internal Wall'!V92 -> 0 | ... AF15: =+'Internal Wall'!AP92 -> 16.5 | AG15: =+'Internal Wall'!BN92 -> 0 | AH15: =+'Internal Wall'!AR92 -> 0 | AI15: =+'Internal Wall'!AS92 -> 0 | AJ15: =+'Internal Wall'!AT92 -> 21 | AK15: =+'Internal Wall'!AU92 -> 0 | AL15: =+'Internal Wall'!AV92 -> 0 | AM15: =+'Internal Wall'!AW92 -> 0 | AN15: =+'Internal Wall'!AX92 -> 20 | AO15: =+'Internal Wall'!AY92 -> 9.8 | ... BL15: =+'Internal Wall'!BV92 -> 0 | BM15: =+'Internal Wall'!IR92 -> 0 | BN15: =+'Internal Wall'!BX92 -> 0 | BO15: =+'Internal Wall'!BY92 -> 0 | BP15: =+'Internal Wall'!BZ92 -> 0 | BQ15: =+'Internal Wall'!CA92 -> 0 | BR15: =+'Internal Wall'!CB92 -> 22 | BS15: =+'Internal Wall'!CC92 -> 0 | BT15: =+'Internal Wall'!CD92 -> 0 | BU15: =+'Internal Wall'!CE92 -> 0 | ... GE15: =+'Internal Wall'!GO92 -> 0
C16: External Wall | D16: Lm | E16: =+'External Wall'!O42 -> 0 | F16: =+'External Wall'!P42 -> 0 | G16: =+'External Wall'!Q42 -> 0 | H16: =+'External Wall'!R42 -> 0 | I16: =+'External Wall'!S42 -> 0 | J16: =+'External Wall'!T42 -> 0 | K16: =+'External Wall'!U42 -> 0 | L16: =+'External Wall'!V42 -> 0 | ... GE16: =+'External Wall'!GO42 -> 0
C17: Slab | D17: M2 | E17: =+Slab!O78 -> 0 | F17: =+Slab!P78 -> 0 | G17: =+Slab!Q78 -> 0 | H17: =+Slab!R78 -> 0 | I17: =+Slab!S78 -> 0 | J17: =+Slab!T78 -> 0 | K17: =+Slab!U78 -> 0 | L17: =+Slab!V78 -> 0 | ... GE17: =+Slab!GO78 -> 0
B19: GF to L1 | C19: Columns | D19: Nos
C20: Internal Wall | D20: Lm | E20: =+'Internal Wall'!O96 -> 0 | F20: =+'Internal Wall'!P96 -> 0 | G20: =+'Internal Wall'!Q96 -> 0 | H20: =+'Internal Wall'!R96 -> 0 | I20: =+'Internal Wall'!S96 -> 0 | J20: =+'Internal Wall'!T96 -> 0 | K20: =+'Internal Wall'!U96 -> 0 | L20: =+'Internal Wall'!V96 -> 0 | ... AF20: =+'Internal Wall'!AP96 -> 0 | AG20: =+'Internal Wall'!BN97 -> 0 | AH20: =+'Internal Wall'!AR96 -> 0 | AI20: =+'Internal Wall'!AS96 -> 0 | AJ20: =+'Internal Wall'!AT96 -> 0 | AK20: =+'Internal Wall'!AU96 -> 0 | AL20: =+'Internal Wall'!AV96 -> 0 | AM20: =+'Internal Wall'!AW96 -> 0 | AN20: =+'Internal Wall'!AX96 -> 0 | AO20: =+'Internal Wall'!AY96 -> 0 | ... BL20: =+'Internal Wall'!BV96 -> 0 | BM20: =+'Internal Wall'!IR97 -> 0 | BN20: =+'Internal Wall'!BX96 -> 10 | BO20: =+'Internal Wall'!BY96 -> 12 | BP20: =+'Internal Wall'!BZ96 -> 0 | BQ20: =+'Internal Wall'!CA96 -> 0 | BR20: =+'Internal Wall'!CB96 -> 0 | BS20: =+'Internal Wall'!CC96 -> 0 | BT20: =+'Internal Wall'!CD96 -> 0 | BU20: =+'Internal Wall'!CE96 -> 22 | ... GE20: =+'Internal Wall'!GO96 -> 0
C21: External Wall | D21: Lm
C22: Slab | D22: M2
B24: L1 to GF | C24: Columns | D24: Nos
C25: Internal Wall | D25: Lm | E25: =+'Internal Wall'!O100 -> 0 | F25: =+'Internal Wall'!P100 -> 0 | G25: =+'Internal Wall'!Q100 -> 0 | H25: =+'Internal Wall'!R100 -> 0 | I25: =+'Internal Wall'!S100 -> 0 | J25: =+'Internal Wall'!T100 -> 0 | K25: =+'Internal Wall'!U100 -> 0 | L25: =+'Internal Wall'!V100 -> 0 | ... AF25: =+'Internal Wall'!AP100 -> 0 | AH25: =+'Internal Wall'!AR100 -> 0 | AI25: =+'Internal Wall'!AS100 -> 0 | AJ25: =+'Internal Wall'!AT100 -> 0 | AK25: =+'Internal Wall'!AU100 -> 0 | AL25: =+'Internal Wall'!AV100 -> 0 | AM25: =+'Internal Wall'!AW100 -> 0 | AN25: =+'Internal Wall'!AX100 -> 0 | AO25: =+'Internal Wall'!AY100 -> 0 | ... BL25: =+'Internal Wall'!BV100 -> 0 | BN25: =+'Internal Wall'!BX100 -> 0 | BO25: =+'Internal Wall'!BY100 -> 0 | BP25: =+'Internal Wall'!BZ100 -> 0 | BQ25: =+'Internal Wall'!CA100 -> 0 | BR25: =+'Internal Wall'!CB100 -> 0 | BS25: =+'Internal Wall'!CC100 -> 0 | BT25: =+'Internal Wall'!CD100 -> 0 | BU25: =+'Internal Wall'!CE100 -> 0 | ... GE25: =+'Internal Wall'!GO100 -> 0
C26: External Wall | D26: Lm
C27: Slab | D27: M2
B29: Summary up to L2 | C29: Columns | D29: Nos | E29: =+E9+E14+E19 -> 2 | F29: =+F9+F14+F19 -> 2 | G29: =+G9+G14+G19 -> 0 | H29: =+H9+H14+H19 -> 1 | I29: =+I9+I14+I19 -> 1 | J29: =+J9+J14+J19 -> 0 | K29: =+K9+K14+K19 -> 0 | L29: =+L9+L14+L19 -> 0 | ... AF29: =+AF9+AF14+AF19 -> 0 | AG29: =+AG9+AG14 -> 0 | AH29: =+AH9+AH14+AH19 -> 0 | AI29: =+AI9+AI14+AI19 -> 0 | AJ29: =+AJ9+AJ14+AJ19 -> 0 | AK29: =+AK9+AK14+AK19 -> 0 | AL29: =+AL9+AL14+AL19 -> 0 | AM29: =+AM9+AM14+AM19 -> 0 | AN29: =+AN9+AN14+AN19 -> 1 | AO29: =+AO9+AO14+AO19 -> 0 | ... BL29: =+BL9+BL14+BL19 -> 0 | BM29: =+BM9+BM14 -> 0 | BN29: =+BN9+BN14+BN19 -> 7 | BO29: =+BO9+BO14+BO19 -> 4 | BP29: =+BP9+BP14+BP19 -> 0 | BQ29: =+BQ9+BQ14+BQ19 -> 1 | BR29: =+BR9+BR14+BR19 -> 2 | BS29: =+BS9+BS14+BS19 -> 0 | BT29: =+BT9+BT14+BT19 -> 0 | BU29: =+BU9+BU14+BU19 -> 0 | ... GY29: =+GY9+GY14+GY19 -> 0 | GZ29: =SUM(E29:CZ29) -> 89
C30: Walls | D30: Lm | E30: =E10+E11+E15+E16+E20+E21+E25 -> 16 | F30: =F10+F11+F15+F16+F20+F21+F25 -> 36.2 | G30: =G10+G11+G15+G16+G20+G21+G25 -> 9.5 | H30: =H10+H11+H15+H16+H20+H21+H25 -> 0 | I30: =I10+I11+I15+I16+I20+I21+I25 -> 10 | J30: =J10+J11+J15+J16+J20+J21+J25 -> 0 | K30: =K10+K11+K15+K16+K20+K21+K25 -> 25.2 | L30: =L10+L11+L15+L16+L20+L21+L25 -> 40.2 | ... AF30: =AF10+AF11+AF15+AF16+AF20+AF21+AF25 -> 16.5 | AG30: =AG10+AG11+AG15+AG16 -> 0 | AH30: =AH10+AH11+AH15+AH16+AH20+AH21+AH25 -> 4.5 | AI30: =AI10+AI11+AI15+AI16+AI20+AI21+AI25 -> 0 | AJ30: =AJ10+AJ11+AJ15+AJ16+AJ20+AJ21+AJ25 -> 31.5 | AK30: =AK10+AK11+AK15+AK16+AK20+AK21+AK25 -> 8.6 | AL30: =AL10+AL11+AL15+AL16+AL20+AL21+AL25 -> 0 | AM30: =AM10+AM11+AM15+AM16+AM20+AM21+AM25 -> 0 | AN30: =AN10+AN11+AN15+AN16+AN20+AN21+AN25 -> 44 | AO30: =AO10+AO11+AO15+AO16+AO20+AO21+AO25 -> 9.8 | ... BL30: =BL10+BL11+BL15+BL16+BL20+BL21+BL25 -> 0 | BM30: =BM10+BM11+BM15+BM16 -> 0 | BN30: =BN10+BN11+BN15+BN16+BN20+BN21+BN25 -> 56.8 | BO30: =BO10+BO11+BO15+BO16+BO20+BO21+BO25 -> 12 | BP30: =BP10+BP11+BP15+BP16+BP20+BP21+BP25 -> 0 | BQ30: =BQ10+BQ11+BQ15+BQ16+BQ20+BQ21+BQ25 -> 19 | BR30: =BR10+BR11+BR15+BR16+BR20+BR21+BR25 -> 22 | BS30: =BS10+BS11+BS15+BS16+BS20+BS21+BS25 -> 27 | BT30: =BT10+BT11+BT15+BT16+BT20+BT21+BT25 -> 80 | BU30: =BU10+BU11+BU15+BU16+BU20+BU21+BU25 -> 28 | ... GY30: =GY10+GY11+GY15+GY16+GY20+GY21+GY25 -> 0 | GZ30: =SUM(E30:CZ30) -> 1868
C31: Slab | D31: M2 | E31: =+E12+E17+E22 -> 0 | F31: =+F12+F17+F22 -> 0 | G31: =+G12+G17+G22 -> 0 | H31: =+H12+H17+H22 -> 0 | I31: =+I12+I17+I22 -> 0 | J31: =+J12+J17+J22 -> 0 | K31: =+K12+K17+K22 -> 0 | L31: =+L12+L17+L22 -> 0 | ... AF31: =+AF12+AF17+AF22 -> 12 | AG31: =+AG12+AG17 -> 0 | AH31: =+AH12+AH17+AH22 -> 0 | AI31: =+AI12+AI17+AI22 -> 1467 | AJ31: =+AJ12+AJ17+AJ22 -> 0 | AK31: =+AK12+AK17+AK22 -> 0 | AL31: =+AL12+AL17+AL22 -> 0 | AM31: =+AM12+AM17+AM22 -> 0 | AN31: =+AN12+AN17+AN22 -> 0 | AO31: =+AO12+AO17+AO22 -> 0 | ... BL31: =+BL12+BL17+BL22 -> 50 | BM31: =+BM12+BM17 -> 0 | BN31: =+BN12+BN17+BN22 -> 0 | BO31: =+BO12+BO17+BO22 -> 0 | BP31: =+BP12+BP17+BP22 -> 0 | BQ31: =+BQ12+BQ17+BQ22 -> 0 | BR31: =+BR12+BR17+BR22 -> 0 | BS31: =+BS12+BS17+BS22 -> 0 | BT31: =+BT12+BT17+BT22 -> 0 | BU31: =+BU12+BU17+BU22 -> 0 | ... GY31: =+GY12+GY17+GY22 -> 0 | GZ31: =SUM(E31:CZ31) -> 10410
A33: Team 2 (Zone 1B,4,9,10)
B34: B2 to B1 | C34: Columns | D34: Nos | E34: =+Columns!O76 -> 1 | F34: =+Columns!P76 -> 0 | G34: =+Columns!Q76 -> 0 | H34: =+Columns!R76 -> 0 | I34: =+Columns!S76 -> 0 | J34: =+Columns!T76 -> 0 | K34: =+Columns!U76 -> 0 | L34: =+Columns!V76 -> 0 | ... DH34: =+Columns!DR76 -> 0 | DI34: =+Columns!HU76 -> 0 | DJ34: =+Columns!HV50 -> 0 | DK34: =+Columns!HW50 -> 0 | DL34: =+Columns!HX50 -> 0 | DM34: =+Columns!HY50 -> 0 | DN34: =+Columns!HZ50 -> 0 | DO34: =+Columns!IA50 -> 0 | DP34: =+Columns!IB50 -> 0 | DQ34: =+Columns!IC50 -> 0 | ... GY34: =+Columns!LK50 -> 0
C35: Internal Wall | D35: Lm | E35: =+'Internal Wall'!O89 -> 28.2 | F35: =+'Internal Wall'!P89 -> 0 | G35: =+'Internal Wall'!Q89 -> 0 | H35: =+'Internal Wall'!R89 -> 37.5 | I35: =+'Internal Wall'!S89 -> 0 | J35: =+'Internal Wall'!T89 -> 0 | K35: =+'Internal Wall'!U89 -> 40.9 | L35: =+'Internal Wall'!V89 -> 14 | ... AF35: =+'Internal Wall'!AP89 -> 3 | AG35: =+'Internal Wall'!BN89 -> 0 | AH35: =+'Internal Wall'!AR89 -> 0 | AI35: =+'Internal Wall'!AS89 -> 7.85 | AJ35: =+'Internal Wall'!AT89 -> 29 | AK35: =+'Internal Wall'!AU89 -> 0 | AL35: =+'Internal Wall'!AV89 -> 4 | AM35: =+'Internal Wall'!AW89 -> 0 | AN35: =+'Internal Wall'!AX89 -> 0 | AO35: =+'Internal Wall'!AY89 -> 46.25 | ... BL35: =+'Internal Wall'!BV89 -> 9.25 | BM35: =+'Internal Wall'!IR89 -> 0 | BN35: =+'Internal Wall'!BX89 -> 6.4 | BO35: =+'Internal Wall'!BY89 -> 5.05 | BP35: =+'Internal Wall'!BZ89 -> 0 | BQ35: =+'Internal Wall'!CA89 -> 11.5 | BR35: =+'Internal Wall'!CB89 -> 5 | BS35: =+'Internal Wall'!CC89 -> 11.7 | BT35: =+'Internal Wall'!CD89 -> 7 | BU35: =+'Internal Wall'!CE89 -> 6.65 | ... GY35: =+'Internal Wall'!HI89 -> 0
C36: External Wall | D36: Lm | E36: =+'External Wall'!O39 -> 5.1 | F36: =+'External Wall'!P39 -> 9 | G36: =+'External Wall'!Q39 -> 0 | H36: =+'External Wall'!R39 -> 0 | I36: =+'External Wall'!S39 -> 0 | J36: =+'External Wall'!T39 -> 0 | K36: =+'External Wall'!U39 -> 0 | L36: =+'External Wall'!V39 -> 0 | ... DH36: =+'External Wall'!DR39 -> 0 | DI36: =+'External Wall'!HU39 -> 0 | DJ36: =+'External Wall'!HV39 -> 0 | DK36: =+'External Wall'!HW39 -> 0 | DL36: =+'External Wall'!HX39 -> 0 | DM36: =+'External Wall'!HY39 -> 0 | DN36: =+'External Wall'!HZ39 -> 0 | DO36: =+'External Wall'!IA39 -> 0 | DP36: =+'External Wall'!IB39 -> 0 | ... GY36: =+'External Wall'!LK39 -> 0
C37: Slab | D37: M2 | E37: =+Slab!O75 -> 68 | F37: =+Slab!P75 -> 0 | G37: =+Slab!Q75 -> 0 | H37: =+Slab!R75 -> 0 | I37: =+Slab!S75 -> 0 | J37: =+Slab!T75 -> 0 | K37: =+Slab!U75 -> 0 | L37: =+Slab!V75 -> 0 | ... GY37: =+Slab!HI75 -> 0
B39: B1 to GF | C39: Columns | D39: Nos | E39: =+Columns!O80 -> 0 | F39: =+Columns!P80 -> 0 | G39: =+Columns!Q80 -> 0 | H39: =+Columns!R80 -> 0 | I39: =+Columns!S80 -> 0 | J39: =+Columns!T80 -> 0 | K39: =+Columns!U80 -> 0 | L39: =+Columns!V80 -> 0 | ... GY39: =+Columns!HI80 -> 0
C40: Internal Wall | D40: Lm | E40: =+'Internal Wall'!O93 -> 0 | F40: =+'Internal Wall'!P93 -> 0 | G40: =+'Internal Wall'!Q93 -> 0 | H40: =+'Internal Wall'!R93 -> 0 | I40: =+'Internal Wall'!S93 -> 0 | J40: =+'Internal Wall'!T93 -> 0 | K40: =+'Internal Wall'!U93 -> 0 | L40: =+'Internal Wall'!V93 -> 0 | ... AF40: =+'Internal Wall'!AP93 -> 0 | AG40: =+'Internal Wall'!BN93 -> 0 | AH40: =+'Internal Wall'!AR93 -> 0 | AI40: =+'Internal Wall'!AS93 -> 0 | AJ40: =+'Internal Wall'!AT93 -> 0 | AK40: =+'Internal Wall'!AU93 -> 0 | AL40: =+'Internal Wall'!AV93 -> 0 | AM40: =+'Internal Wall'!AW93 -> 0 | AN40: =+'Internal Wall'!AX93 -> 0 | AO40: =+'Internal Wall'!AY93 -> 0 | ... BL40: =+'Internal Wall'!BV93 -> 16 | BM40: =+'Internal Wall'!IR93 -> 0 | BN40: =+'Internal Wall'!BX93 -> 15 | BO40: =+'Internal Wall'!BY93 -> 14 | BP40: =+'Internal Wall'!BZ93 -> 0 | BQ40: =+'Internal Wall'!CA93 -> 0 | BR40: =+'Internal Wall'!CB93 -> 28 | BS40: =+'Internal Wall'!CC93 -> 0 | BT40: =+'Internal Wall'!CD93 -> 0 | BU40: =+'Internal Wall'!CE93 -> 0 | ... GY40: =+'Internal Wall'!HI93 -> 0
C41: External Wall | D41: Lm | E41: =+'External Wall'!O43 -> 0 | F41: =+'External Wall'!P43 -> 0 | G41: =+'External Wall'!Q43 -> 0 | H41: =+'External Wall'!R43 -> 0 | I41: =+'External Wall'!S43 -> 0 | J41: =+'External Wall'!T43 -> 0 | K41: =+'External Wall'!U43 -> 0 | L41: =+'External Wall'!V43 -> 0 | ... GY41: =+'External Wall'!HI43 -> 0
C42: Slab | D42: M2 | E42: =+Slab!O79 -> 0 | F42: =+Slab!P79 -> 0 | G42: =+Slab!Q79 -> 0 | H42: =+Slab!R79 -> 0 | I42: =+Slab!S79 -> 0 | J42: =+Slab!T79 -> 0 | K42: =+Slab!U79 -> 0 | L42: =+Slab!V79 -> 0 | ... GY42: =+Slab!HI79 -> 0
B44: GF to L1 | C44: Columns | D44: Nos
C45: Internal Wall | D45: Lm | E45: =+'Internal Wall'!O97 -> 0 | F45: =+'Internal Wall'!P97 -> 0 | G45: =+'Internal Wall'!Q97 -> 0 | H45: =+'Internal Wall'!R97 -> 0 | I45: =+'Internal Wall'!S97 -> 0 | J45: =+'Internal Wall'!T97 -> 0 | K45: =+'Internal Wall'!U97 -> 0 | L45: =+'Internal Wall'!V97 -> 0 | ... AF45: =+'Internal Wall'!AP97 -> 0 | AG45: =+'Internal Wall'!BN98 -> 0 | AH45: =+'Internal Wall'!AR97 -> 0 | AI45: =+'Internal Wall'!AS97 -> 0 | AJ45: =+'Internal Wall'!AT97 -> 0 | AK45: =+'Internal Wall'!AU97 -> 0 | AL45: =+'Internal Wall'!AV97 -> 0 | AM45: =+'Internal Wall'!AW97 -> 0 | AN45: =+'Internal Wall'!AX97 -> 0 | AO45: =+'Internal Wall'!AY97 -> 0 | ... BL45: =+'Internal Wall'!BV97 -> 0 | BM45: =+'Internal Wall'!IR98 -> 0 | BN45: =+'Internal Wall'!BX97 -> 0 | BO45: =+'Internal Wall'!BY97 -> 0 | BP45: =+'Internal Wall'!BZ97 -> 0 | BQ45: =+'Internal Wall'!CA97 -> 0 | BR45: =+'Internal Wall'!CB97 -> 11 | BS45: =+'Internal Wall'!CC97 -> 0 | BT45: =+'Internal Wall'!CD97 -> 0 | BU45: =+'Internal Wall'!CE97 -> 0 | ... GY45: =+'Internal Wall'!HI97 -> 0
C46: External Wall | D46: Lm
C47: Slab | D47: M2
B49: L1 to L2 | C49: Columns | D49: Nos
C50: Internal Wall | D50: Lm | E50: =+'Internal Wall'!O101 -> 0 | F50: =+'Internal Wall'!P101 -> 0 | G50: =+'Internal Wall'!Q101 -> 0 | H50: =+'Internal Wall'!R101 -> 0 | I50: =+'Internal Wall'!S101 -> 0 | J50: =+'Internal Wall'!T101 -> 0 | K50: =+'Internal Wall'!U101 -> 0 | L50: =+'Internal Wall'!V101 -> 0 | ... AF50: =+'Internal Wall'!AP101 -> 0 | AG50: =+'Internal Wall'!BN103 -> 0 | AH50: =+'Internal Wall'!AR101 -> 0 | AI50: =+'Internal Wall'!AS101 -> 0 | AJ50: =+'Internal Wall'!AT101 -> 0 | AK50: =+'Internal Wall'!AU101 -> 0 | AL50: =+'Internal Wall'!AV101 -> 0 | AM50: =+'Internal Wall'!AW101 -> 0 | AN50: =+'Internal Wall'!AX101 -> 0 | AO50: =+'Internal Wall'!AY101 -> 0 | ... BL50: =+'Internal Wall'!BV101 -> 0 | BM50: =+'Internal Wall'!IR103 -> 0 | BN50: =+'Internal Wall'!BX101 -> 0 | BO50: =+'Internal Wall'!BY101 -> 0 | BP50: =+'Internal Wall'!BZ101 -> 0 | BQ50: =+'Internal Wall'!CA101 -> 0 | BR50: =+'Internal Wall'!CB101 -> 0 | BS50: =+'Internal Wall'!CC101 -> 0 | BT50: =+'Internal Wall'!CD101 -> 0 | BU50: =+'Internal Wall'!CE101 -> 0 | ... GY50: =+'Internal Wall'!HI101 -> 0
C51: External Wall | D51: Lm
C52: Slab | D52: M2
...

Sheet Columns
A1: #VALUE! | D1: Diriyah II Management Contracting – Opera House Concrete Updates Columns Works
A6: S/No. | B6: Levels | C6: Zone | D6: Unit | E6: January | O6: February | AR6: March | BX6: April | DB6: May | EG6: June | FK6: July | GP6: August
E7: 24 | F7: 46047 | G7: 46048 | H7: 46049 | I7: 46050 | J7: 46051 | K7: 46052 | L7: 46053 | M7: Total | O7: 46054 | P7: 46055 | Q7: 46056 | R7: 46057 | S7: 46058 | T7: 46059 | U7: 46060 | V7: 46061 | W7: 46062 | X7: 46063 | Y7: 46064 | Z7: 46065 | AA7: 46066 | AB7: 46067 | AC7: 46068 | AD7: 46069 | AE7: 46070 | AF7: 46071 | AG7: 46072 | AH7: 46073 | AI7: 46074 | AJ7: 46075 | AK7: 46076 | AL7: 46077 | AM7: 46078 | AN7: 46079 | AO7: 46080 | AP7: 46081 | AR7: 46082 | AS7: 46083 | AT7: 46084 | AU7: 46085 | AV7: 46086 | AW7: 46087 | AX7: 46088 | AY7: 46089 | AZ7: 46090 | BA7: 46091 | BB7: 46092 | BC7: 46093 | BD7: 46094 | BE7: 46095 | BF7: 46096 | BG7: 46097 | BH7: 46098 | BI7: 46099 | BJ7: 46100 | BK7: 46101 | BL7: 46102 | BM7: 46103 | BN7: 46104 | BO7: 46105 | BP7: 46106 | BQ7: 46107 | BR7: 46108 | BS7: 46109 | BT7: 46110 | BU7: 46111 | BV7: 46112 | BX7: 46113 | BY7: 46114 | BZ7: 46115 | CA7: 46116 | CB7: 46117 | CC7: 46118 | CD7: 46119 | CE7: 46120 | CF7: 46121 | CG7: 46122 | CH7: 46123 | CI7: 46124 | CJ7: 46125 | CK7: 46126 | CL7: 46127 | CM7: 46128 | CN7: 46129 | CO7: 46130 | CP7: 46131 | CQ7: 46132 | CR7: 46133 | CS7: 46134 | CT7: 46135 | CU7: 46136 | CV7: 46137 | CW7: 46138 | CX7: 46139 | CY7: 46140 | CZ7: 46141 | DA7: 46142 | DB7: 46143 | DC7: 46144 | DD7: 46145 | DE7: 46146 | DF7: 46147 | DG7: 46148 | DH7: 46149 | DI7: 46150 | DJ7: 46151 | DK7: 46152 | DL7: 46153 | DM7: 46154 | DN7: 46155 | DO7: 46156 | DP7: 46157 | DQ7: 46158 | DR7: 46159 | DS7: 46160 | DT7: 46161 | DU7: 46162 | DV7: 46163 | DW7: 46164 | DX7: 46165 | DY7: 46166 | DZ7: 46167 | EA7: 46168 | EB7: 46169 | EC7: 46170 | ED7: 46171 | EE7: 46172 | EF7: 46173 | EG7: 46174 | EH7: 46175 | EI7: 46176 | EJ7: 46177 | EK7: 46178 | EL7: 46179 | EM7: 46180 | EN7: 46181 | EO7: 46182 | EP7: 46183 | EQ7: 46184 | ER7: 46185 | ES7: 46186 | ET7: 46187 | EU7: 46188 | EV7: 46189 | EW7: 46190 | EX7: 46191 | EY7: 46192 | EZ7: 46193 | FA7: 46194 | FB7: 46195 | FC7: 46196 | FD7: 46197 | FE7: 46198 | FF7: 46199 | FG7: 46200 | FH7: 46201 | FI7: 46202 | FJ7: 46203 | FK7: 46204 | FL7: 46205 | FM7: 46206 | FN7: 46207 | FO7: 46208 | FP7: 46209 | FQ7: 46210 | FR7: 46211 | FS7: 46212 | FT7: 46213 | FU7: 46214 | FV7: 46215 | FW7: 46216 | FX7: 46217 | FY7: 46218 | FZ7: 46219 | GA7: 46220 | GB7: 46221 | GC7: 46222 | GD7: 46223 | GE7: 46224 | GF7: 46225 | GG7: 46226 | GH7: 46227 | GI7: 46228 | GJ7: 46229 | GK7: 46230 | GL7: 46231 | GM7: 46232 | GN7: 46233 | GO7: 46234 | GP7: 46235 | GQ7: 46236 | GR7: 46237 | GS7: 46238 | GT7: 46239 | GU7: 46240 | GV7: 46241 | GW7: 46242 | GX7: 46243 | GY7: 46244 | GZ7: 46245 | HA7: 46246 | HB7: 46247 | HC7: 46248 | HD7: 46249 | HE7: 46250 | HF7: 46251 | HG7: 46252 | HH7: 46253 | HI7: 46254 | HJ7: 46255 | HK7: 46256 | HL7: 46257 | HM7: 46258 | HN7: 46259 | HO7: 46260 | HP7: 46261 | HQ7: 46262 | HR7: 46263 | HS7: 46264 | HT7: 46265 | HU7: Total
A8: 1 | B8: B2 to B1 | C8: Zone 1 | D8: Nos. | E8: 0 | F8: 0 | G8: 0 | H8: 0 | I8: 0 | J8: 2 | K8: 0 | L8: 0 | M8: =SUM(E8:L8) -> 2 | O8: 0 | P8: 0 | Q8: 0 | R8: 0 | S8: 0 | T8: 0 | U8: 0 | V8: 0 | W8: 1 | X8: 0 | Y8: 0 | Z8: 4 | AA8: 0 | AB8: 1 | AC8: 0 | AD8: 0 | AE8: 1 | AF8: 0 | AG8: 0 | AH8: 0 | AI8: 0 | AJ8: 0 | AK8: 0 | AL8: 0 | AM8: 0 | AN8: 0 | AO8: 0 | AP8: 0 | AR8: 0 | AS8: 0 | AT8: 0 | AU8: 0 | AV8: 1 | AW8: 0 | AX8: 0 | AY8: 0 | AZ8: 0 | BA8: 0 | BB8: 0 | BC8: 0 | BD8: 0 | BE8: 0 | BF8: 0 | BG8: 0 | BH8: 0 | BI8: 0 | BJ8: 0 | BK8: 0 | BL8: 0 | BM8: 0 | BN8: 0 | BO8: 0 | BP8: 0 | BQ8: 0 | BR8: 0 | BS8: 3 | BT8: 0 | BU8: 0 | BV8: 0 | BX8: 0 | BY8: 0 | BZ8: 0 | CA8: 0 | CB8: 0 | CC8: 0 | CD8: 0 | CE8: 0 | CF8: 0 | CG8: 0 | CH8: 0 | CI8: 0 | CJ8: 0 | CK8: 0 | CL8: 0 | CM8: 0 | CN8: 0 | CO8: 0 | CP8: 0 | CQ8: 0 | CR8: 0 | CS8: 0 | CT8: 0 | CU8: 0 | CV8: 1 | CW8: 0 | CX8: 0 | CY8: 0 | CZ8: 0 | DA8: 0 | DB8: 0 | DC8: 0 | DD8: 0 | DE8: 0 | DF8: 0 | DG8: 0 | DH8: 0 | DI8: 0 | DJ8: 0 | DK8: 0 | DL8: 2 | DM8: 0 | DN8: 0 | DO8: 0 | DP8: 0 | DQ8: 0 | DR8: 0 | DS8: 0 | DT8: 0 | DU8: 0 | DV8: 0 | DW8: 0 | DX8: 0 | DY8: 0 | DZ8: 0 | EA8: 0 | EB8: 0 | EC8: 0 | ED8: 0 | EE8: 0 | EF8: 0 | EG8: 0 | EH8: 0 | EI8: 0 | EJ8: 0 | EK8: 0 | EL8: 0 | EM8: 0 | EN8: 0 | EO8: 0 | EP8: 0 | EQ8: 0 | ER8: 0 | ES8: 0 | ET8: 0 | EU8: 0 | EV8: 0 | EW8: 0 | EX8: 0 | EY8: 0 | EZ8: 0 | FA8: 0 | FB8: 0 | FC8: 0 | FD8: 0 | FE8: 0 | FF8: 0 | FG8: 0 | FH8: 0 | FI8: 0 | FJ8: 0 | FK8: 0 | FL8: 0 | FM8: 0 | FN8: 0 | FO8: 0 | FP8: 0 | FQ8: 0 | FR8: 0 | FS8: 0 | FT8: 0 | FU8: 0 | FV8: 0 | FW8: 0 | FX8: 0 | FY8: 0 | FZ8: 0 | GA8: 0 | GB8: 0 | GC8: 0 | GD8: 0 | GE8: 0 | GF8: 0 | GG8: 0 | GH8: 0 | GI8: 0 | GJ8: 0 | GK8: 0 | GL8: 0 | GM8: 0 | GN8: 0 | GO8: 0 | GP8: 0 | GQ8: 0 | GR8: 0 | GS8: 0 | GT8: 0 | GU8: 0 | GV8: 0 | GW8: 0 | GX8: 0 | GY8: 0 | GZ8: 0 | HA8: 0 | HB8: 0 | HC8: 0 | HD8: 0 | HE8: 0 | HF8: 0 | HG8: 0 | HH8: 0 | HU8: =SUM(O8:HT8) -> 14
A9: 2 | C9: Zone 2 | D9: Nos. | E9: 0 | F9: 0 | G9: 0 | H9: 0 | I9: 0 | J9: 0 | K9: 0 | L9: 0 | M9: =SUM(E9:L9) -> 0 | O9: 0 | P9: 0 | Q9: 0 | R9: 0 | S9: 0 | T9: 0 | U9: 0 | V9: 0 | W9: 0 | X9: 0 | Y9: 0 | Z9: 0 | AA9: 0 | AB9: 0 | AC9: 0 | AD9: 0 | AE9: 0 | AF9: 0 | AG9: 0 | AH9: 0 | AI9: 0 | AJ9: 0 | AK9: 0 | AL9: 0 | AM9: 0 | AN9: 0 | AO9: 0 | AP9: 0 | AR9: 0 | AS9: 0 | AT9: 0 | AU9: 0 | AV9: 0 | AW9: 0 | AX9: 0 | AY9: 0 | AZ9: 0 | BA9: 0 | BB9: 0 | BC9: 0 | BD9: 0 | BE9: 0 | BF9: 0 | BG9: 0 | BH9: 0 | BI9: 0 | BJ9: 0 | BK9: 0 | BL9: 0 | BM9: 0 | BN9: 0 | BO9: 0 | BP9: 0 | BQ9: 0 | BR9: 0 | BS9: 0 | BT9: 0 | BU9: 0 | BV9: 0 | BX9: 0 | BY9: 0 | BZ9: 0 | CA9: 0 | CB9: 0 | CC9: 0 | CD9: 0 | CE9: 0 | CF9: 0 | CG9: 0 | CH9: 0 | CI9: 0 | CJ9: 0 | CK9: 0 | CL9: 0 | CM9: 0 | CN9: 0 | CO9: 0 | CP9: 0 | CQ9: 0 | CR9: 0 | CS9: 0 | CT9: 0 | CU9: 0 | CV9: 0 | CW9: 0 | CX9: 0 | CY9: 0 | CZ9: 0 | DA9: 0 | DB9: 0 | DC9: 0 | DD9: 0 | DE9: 0 | DF9: 0 | DG9: 0 | DH9: 0 | DI9: 0 | DJ9: 0 | DK9: 0 | DL9: 0 | DM9: 0 | DN9: 0 | DO9: 0 | DP9: 0 | DQ9: 0 | DR9: 0 | DS9: 0 | DT9: 0 | DU9: 0 | DV9: 0 | DW9: 0 | DX9: 0 | DY9: 0 | DZ9: 0 | EA9: 0 | EB9: 0 | EC9: 0 | ED9: 0 | EE9: 0 | EF9: 0 | EG9: 0 | EH9: 0 | EI9: 0 | EJ9: 0 | EK9: 0 | EL9: 0 | EM9: 0 | EN9: 0 | EO9: 0 | EP9: 0 | EQ9: 0 | ER9: 0 | ES9: 0 | ET9: 0 | EU9: 0 | EV9: 0 | EW9: 0 | EX9: 0 | EY9: 0 | EZ9: 0 | FA9: 0 | FB9: 0 | FC9: 0 | FD9: 0 | FE9: 0 | FF9: 0 | FG9: 0 | FH9: 0 | FI9: 0 | FJ9: 0 | FK9: 0 | FL9: 0 | FM9: 0 | FN9: 0 | FO9: 0 | FP9: 0 | FQ9: 0 | FR9: 0 | FS9: 0 | FT9: 0 | FU9: 0 | FV9: 0 | FW9: 0 | FX9: 0 | FY9: 0 | FZ9: 0 | GA9: 0 | GB9: 0 | GC9: 0 | GD9: 0 | GE9: 0 | GF9: 0 | GG9: 0 | GH9: 0 | GI9: 0 | GJ9: 0 | GK9: 0 | GL9: 0 | GM9: 0 | GN9: 0 | GO9: 0 | GP9: 0 | GQ9: 0 | GR9: 0 | GS9: 0 | GT9: 0 | GU9: 0 | GV9: 0 | GW9: 0 | GX9: 0 | GY9: 0 | GZ9: 0 | HA9: 0 | HB9: 0 | HC9: 0 | HD9: 0 | HE9: 0 | HF9: 0 | HG9: 0 | HH9: 0 | HU9: =SUM(O9:HT9) -> 0
A10: 3 | C10: Zone 3 | D10: Nos. | E10: 0 | F10: 0 | G10: 0 | H10: 0 | I10: 0 | J10: 0 | K10: 0 | L10: 0 | M10: =SUM(E10:L10) -> 0 | O10: 0 | P10: 0 | Q10: 0 | R10: 0 | S10: 0 | T10: 0 | U10: 0 | V10: 0 | W10: 0 | X10: 0 | Y10: 0 | Z10: 0 | AA10: 0 | AB10: 0 | AC10: 0 | AD10: 0 | AE10: 0 | AF10: 0 | AG10: 0 | AH10: 0 | AI10: 0 | AJ10: 0 | AK10: 0 | AL10: 0 | AM10: 0 | AN10: 0 | AO10: 0 | AP10: 0 | AR10: 0 | AS10: 0 | AT10: 0 | AU10: 0 | AV10: 0 | AW10: 0 | AX10: 0 | AY10: 0 | AZ10: 0 | BA10: 0 | BB10: 0 | BC10: 0 | BD10: 0 | BE10: 0 | BF10: 0 | BG10: 0 | BH10: 0 | BI10: 0 | BJ10: 0 | BK10: 0 | BL10: 0 | BM10: 0 | BN10: 0 | BO10: 0 | BP10: 0 | BQ10: 0 | BR10: 0 | BS10: 0 | BT10: 0 | BU10: 0 | BV10: 0 | BX10: 0 | BY10: 0 | BZ10: 0 | CA10: 0 | CB10: 0 | CC10: 0 | CD10: 0 | CE10: 0 | CF10: 0 | CG10: 0 | CH10: 0 | CI10: 0 | CJ10: 0 | CK10: 0 | CL10: 0 | CM10: 0 | CN10: 0 | CO10: 0 | CP10: 0 | CQ10: 0 | CR10: 0 | CS10: 0 | CT10: 0 | CU10: 0 | CV10: 0 | CW10: 0 | CX10: 0 | CY10: 0 | CZ10: 0 | DA10: 0 | DB10: 0 | DC10: 0 | DD10: 0 | DE10: 0 | DF10: 0 | DG10: 0 | DH10: 0 | DI10: 0 | DJ10: 0 | DK10: 0 | DL10: 0 | DM10: 0 | DN10: 0 | DO10: 0 | DP10: 0 | DQ10: 0 | DR10: 0 | DS10: 0 | DT10: 0 | DU10: 0 | DV10: 0 | DW10: 0 | DX10: 0 | DY10: 0 | DZ10: 0 | EA10: 0 | EB10: 0 | EC10: 0 | ED10: 0 | EE10: 0 | EF10: 0 | EG10: 0 | EH10: 0 | EI10: 0 | EJ10: 0 | EK10: 0 | EL10: 0 | EM10: 0 | EN10: 0 | EO10: 0 | EP10: 0 | EQ10: 0 | ER10: 0 | ES10: 0 | ET10: 0 | EU10: 0 | EV10: 0 | EW10: 0 | EX10: 0 | EY10: 0 | EZ10: 0 | FA10: 0 | FB10: 0 | FC10: 0 | FD10: 0 | FE10: 0 | FF10: 0 | FG10: 0 | FH10: 0 | FI10: 0 | FJ10: 0 | FK10: 0 | FL10: 0 | FM10: 0 | FN10: 0 | FO10: 0 | FP10: 0 | FQ10: 0 | FR10: 0 | FS10: 0 | FT10: 0 | FU10: 0 | FV10: 0 | FW10: 0 | FX10: 0 | FY10: 0 | FZ10: 0 | GA10: 0 | GB10: 0 | GC10: 0 | GD10: 0 | GE10: 0 | GF10: 0 | GG10: 0 | GH10: 0 | GI10: 0 | GJ10: 0 | GK10: 0 | GL10: 0 | GM10: 0 | GN10: 0 | GO10: 0 | GP10: 0 | GQ10: 0 | GR10: 0 | GS10: 0 | GT10: 0 | GU10: 0 | GV10: 0 | GW10: 0 | GX10: 0 | GY10: 0 | GZ10: 0 | HA10: 0 | HB10: 0 | HC10: 0 | HD10: 0 | HE10: 0 | HF10: 0 | HG10: 0 | HH10: 0 | HU10: =SUM(O10:HT10) -> 0
A11: 4 | C11: Zone 4 | D11: Nos. | E11: 0 | F11: 0 | G11: 0 | H11: 0 | I11: 0 | J11: 0 | K11: 0 | L11: 0 | M11: =SUM(E11:L11) -> 0 | O11: 0 | P11: 0 | Q11: 0 | R11: 0 | S11: 0 | T11: 0 | U11: 0 | V11: 0 | W11: 0 | X11: 0 | Y11: 0 | Z11: 0 | AA11: 0 | AB11: 0 | AC11: 0 | AD11: 0 | AE11: 0 | AF11: 0 | AG11: 0 | AH11: 0 | AI11: 0 | AJ11: 0 | AK11: 0 | AL11: 0 | AM11: 0 | AN11: 0 | AO11: 0 | AP11: 0 | AR11: 0 | AS11: 0 | AT11: 0 | AU11: 0 | AV11: 0 | AW11: 0 | AX11: 0 | AY11: 0 | AZ11: 0 | BA11: 0 | BB11: 0 | BC11: 0 | BD11: 0 | BE11: 0 | BF11: 0 | BG11: 0 | BH11: 0 | BI11: 0 | BJ11: 0 | BK11: 0 | BL11: 0 | BM11: 0 | BN11: 0 | BO11: 0 | BP11: 0 | BQ11: 0 | BR11: 0 | BS11: 0 | BT11: 0 | BU11: 0 | BV11: 0 | BX11: 0 | BY11: 0 | BZ11: 0 | CA11: 0 | CB11: 0 | CC11: 0 | CD11: 0 | CE11: 0 | CF11: 0 | CG11: 0 | CH11: 0 | CI11: 0 | CJ11: 0 | CK11: 0 | CL11: 0 | CM11: 0 | CN11: 0 | CO11: 0 | CP11: 0 | CQ11: 0 | CR11: 0 | CS11: 0 | CT11: 0 | CU11: 0 | CV11: 0 | CW11: 0 | CX11: 0 | CY11: 0 | CZ11: 0 | DA11: 0 | DB11: 0 | DC11: 0 | DD11: 0 | DE11: 0 | DF11: 0 | DG11: 0 | DH11: 0 | DI11: 0 | DJ11: 0 | DK11: 0 | DL11: 0 | DM11: 0 | DN11: 0 | DO11: 0 | DP11: 0 | DQ11: 0 | DR11: 0 | DS11: 0 | DT11: 0 | DU11: 0 | DV11: 0 | DW11: 0 | DX11: 0 | DY11: 0 | DZ11: 0 | EA11: 0 | EB11: 0 | EC11: 0 | ED11: 0 | EE11: 0 | EF11: 0 | EG11: 0 | EH11: 0 | EI11: 0 | EJ11: 0 | EK11: 0 | EL11: 0 | EM11: 0 | EN11: 0 | EO11: 0 | EP11: 0 | EQ11: 0 | ER11: 0 | ES11: 0 | ET11: 0 | EU11: 0 | EV11: 0 | EW11: 0 | EX11: 0 | EY11: 0 | EZ11: 0 | FA11: 0 | FB11: 0 | FC11: 0 | FD11: 0 | FE11: 0 | FF11: 0 | FG11: 0 | FH11: 0 | FI11: 0 | FJ11: 0 | FK11: 0 | FL11: 0 | FM11: 0 | FN11: 0 | FO11: 0 | FP11: 0 | FQ11: 0 | FR11: 0 | FS11: 0 | FT11: 0 | FU11: 0 | FV11: 0 | FW11: 0 | FX11: 0 | FY11: 0 | FZ11: 0 | GA11: 0 | GB11: 0 | GC11: 0 | GD11: 0 | GE11: 0 | GF11: 0 | GG11: 0 | GH11: 0 | GI11: 0 | GJ11: 0 | GK11: 0 | GL11: 0 | GM11: 0 | GN11: 0 | GO11: 0 | GP11: 0 | GQ11: 0 | GR11: 0 | GS11: 0 | GT11: 0 | GU11: 0 | GV11: 0 | GW11: 0 | GX11: 0 | GY11: 0 | GZ11: 0 | HA11: 0 | HB11: 0 | HC11: 0 | HD11: 0 | HE11: 0 | HF11: 0 | HG11: 0 | HH11: 0 | HU11: =SUM(O11:HT11) -> 0
A12: 5 | C12: Zone 5 | D12: Nos. | E12: 0 | F12: 0 | G12: 0 | H12: 0 | I12: 0 | J12: 0 | K12: 0 | L12: 0 | M12: =SUM(E12:L12) -> 0 | O12: 0 | P12: 0 | Q12: 0 | R12: 0 | S12: 0 | T12: 0 | U12: 0 | V12: 0 | W12: 0 | X12: 0 | Y12: 0 | Z12: 0 | AA12: 0 | AB12: 0 | AC12: 0 | AD12: 0 | AE12: 0 | AF12: 0 | AG12: 0 | AH12: 0 | AI12: 0 | AJ12: 0 | AK12: 0 | AL12: 0 | AM12: 0 | AN12: 0 | AO12: 0 | AP12: 0 | AR12: 0 | AS12: 0 | AT12: 0 | AU12: 0 | AV12: 0 | AW12: 0 | AX12: 0 | AY12: 0 | AZ12: 0 | BA12: 0 | BB12: 0 | BC12: 0 | BD12: 0 | BE12: 0 | BF12: 0 | BG12: 0 | BH12: 0 | BI12: 0 | BJ12: 0 | BK12: 0 | BL12: 0 | BM12: 0 | BN12: 0 | BO12: 3 | BP12: 0 | BQ12: 0 | BR12: 0 | BS12: 0 | BT12: 0 | BU12: 0 | BV12: 0 | BX12: 2 | BY12: 0 | BZ12: 0 | CA12: 0 | CB12: 0 | CC12: 0 | CD12: 0 | CE12: 0 | CF12: 0 | CG12: 0 | CH12: 0 | CI12: 0 | CJ12: 0 | CK12: 0 | CL12: 0 | CM12: 0 | CN12: 0 | CO12: 0 | CP12: 0 | CQ12: 0 | CR12: 0 | CS12: 0 | CT12: 0 | CU12: 0 | CV12: 0 | CW12: 0 | CX12: 0 | CY12: 0 | CZ12: 0 | DA12: 5 | DB12: 0 | DC12: 0 | DD12: 0 | DE12: 0 | DF12: 0 | DG12: 0 | DH12: 0 | DI12: 0 | DJ12: 0 | DK12: 0 | DL12: 0 | DM12: 0 | DN12: 0 | DO12: 0 | DP12: 0 | DQ12: 0 | DR12: 0 | DS12: 0 | DT12: 0 | DU12: 0 | DV12: 0 | DW12: 0 | DX12: 0 | DY12: 0 | DZ12: 0 | EA12: 0 | EB12: 0 | EC12: 0 | ED12: 0 | EE12: 0 | EF12: 0 | EG12: 0 | EH12: 0 | EI12: 0 | EJ12: 0 | EK12: 0 | EL12: 0 | EM12: 0 | EN12: 0 | EO12: 0 | EP12: 0 | EQ12: 0 | ER12: 0 | ES12: 0 | ET12: 0 | EU12: 0 | EV12: 0 | EW12: 0 | EX12: 0 | EY12: 0 | EZ12: 0 | FA12: 0 | FB12: 0 | FC12: 0 | FD12: 0 | FE12: 0 | FF12: 0 | FG12: 0 | FH12: 0 | FI12: 0 | FJ12: 0 | FK12: 0 | FL12: 0 | FM12: 0 | FN12: 0 | FO12: 0 | FP12: 0 | FQ12: 0 | FR12: 0 | FS12: 0 | FT12: 0 | FU12: 0 | FV12: 0 | FW12: 0 | FX12: 0 | FY12: 0 | FZ12: 0 | GA12: 0 | GB12: 0 | GC12: 0 | GD12: 0 | GE12: 0 | GF12: 0 | GG12: 0 | GH12: 0 | GI12: 0 | GJ12: 0 | GK12: 0 | GL12: 0 | GM12: 0 | GN12: 0 | GO12: 0 | GP12: 0 | GQ12: 0 | GR12: 0 | GS12: 0 | GT12: 0 | GU12: 0 | GV12: 0 | GW12: 0 | GX12: 0 | GY12: 0 | GZ12: 0 | HA12: 0 | HB12: 0 | HC12: 0 | HD12: 0 | HE12: 0 | HF12: 0 | HG12: 0 | HH12: 0 | HU12: =SUM(O12:HT12) -> 10
A13: 6 | C13: Zone 6 | D13: Nos. | E13: 0 | F13: 0 | G13: 0 | H13: 0 | I13: 0 | J13: 0 | K13: 0 | L13: 0 | M13: =SUM(E13:L13) -> 0 | O13: 0 | P13: 0 | Q13: 0 | R13: 0 | S13: 0 | T13: 0 | U13: 0 | V13: 0 | W13: 0 | X13: 0 | Y13: 0 | Z13: 0 | AA13: 0 | AB13: 0 | AC13: 0 | AD13: 0 | AE13: 0 | AF13: 0 | AG13: 0 | AH13: 0 | AI13: 0 | AJ13: 0 | AK13: 0 | AL13: 0 | AM13: 0 | AN13: 0 | AO13: 0 | AP13: 0 | AR13: 0 | AS13: 0 | AT13: 0 | AU13: 0 | AV13: 0 | AW13: 0 | AX13: 0 | AY13: 0 | AZ13: 0 | BA13: 0 | BB13: 0 | BC13: 0 | BD13: 0 | BE13: 0 | BF13: 0 | BG13: 0 | BH13: 0 | BI13: 0 | BJ13: 0 | BK13: 0 | BL13: 0 | BM13: 0 | BN13: 0 | BO13: 0 | BP13: 0 | BQ13: 0 | BR13: 0 | BS13: 0 | BT13: 0 | BU13: 0 | BV13: 0 | BX13: 0 | BY13: 0 | BZ13: 0 | CA13: 0 | CB13: 0 | CC13: 0 | CD13: 0 | CE13: 0 | CF13: 0 | CG13: 0 | CH13: 0 | CI13: 0 | CJ13: 0 | CK13: 0 | CL13: 0 | CM13: 0 | CN13: 0 | CO13: 0 | CP13: 0 | CQ13: 0 | CR13: 0 | CS13: 0 | CT13: 0 | CU13: 0 | CV13: 0 | CW13: 0 | CX13: 0 | CY13: 0 | CZ13: 0 | DA13: 0 | DB13: 0 | DC13: 0 | DD13: 0 | DE13: 0 | DF13: 0 | DG13: 0 | DH13: 0 | DI13: 0 | DJ13: 0 | DK13: 0 | DL13: 0 | DM13: 0 | DN13: 0 | DO13: 0 | DP13: 0 | DQ13: 0 | DR13: 0 | DS13: 0 | DT13: 0 | DU13: 0 | DV13: 0 | DW13: 0 | DX13: 0 | DY13: 0 | DZ13: 0 | EA13: 0 | EB13: 0 | EC13: 0 | ED13: 0 | EE13: 0 | EF13: 0 | EG13: 0 | EH13: 0 | EI13: 0 | EJ13: 0 | EK13: 0 | EL13: 0 | EM13: 0 | EN13: 0 | EO13: 0 | EP13: 0 | EQ13: 0 | ER13: 0 | ES13: 0 | ET13: 0 | EU13: 0 | EV13: 0 | EW13: 0 | EX13: 0 | EY13: 0 | EZ13: 0 | FA13: 0 | FB13: 0 | FC13: 0 | FD13: 0 | FE13: 0 | FF13: 0 | FG13: 0 | FH13: 0 | FI13: 0 | FJ13: 0 | FK13: 0 | FL13: 0 | FM13: 0 | FN13: 0 | FO13: 0 | FP13: 0 | FQ13: 0 | FR13: 0 | FS13: 0 | FT13: 0 | FU13: 0 | FV13: 0 | FW13: 0 | FX13: 0 | FY13: 0 | FZ13: 0 | GA13: 0 | GB13: 0 | GC13: 0 | GD13: 0 | GE13: 0 | GF13: 0 | GG13: 0 | GH13: 0 | GI13: 0 | GJ13: 0 | GK13: 0 | GL13: 0 | GM13: 0 | GN13: 0 | GO13: 0 | GP13: 0 | GQ13: 0 | GR13: 0 | GS13: 0 | GT13: 0 | GU13: 0 | GV13: 0 | GW13: 0 | GX13: 0 | GY13: 0 | GZ13: 0 | HA13: 0 | HB13: 0 | HC13: 0 | HD13: 0 | HE13: 0 | HF13: 0 | HG13: 0 | HH13: 0 | HU13: =SUM(O13:HT13) -> 0
A14: 7 | C14: Zone 7 | D14: Nos. | E14: 0 | F14: 0 | G14: 0 | H14: 0 | I14: 0 | J14: 0 | K14: 0 | L14: 0 | M14: =SUM(E14:L14) -> 0 | O14: 0 | P14: 0 | Q14: 0 | R14: 0 | S14: 0 | T14: 0 | U14: 0 | V14: 0 | W14: 0 | X14: 0 | Y14: 0 | Z14: 0 | AA14: 0 | AB14: 0 | AC14: 0 | AD14: 0 | AE14: 0 | AF14: 0 | AG14: 0 | AH14: 0 | AI14: 0 | AJ14: 0 | AK14: 0 | AL14: 0 | AM14: 0 | AN14: 0 | AO14: 0 | AP14: 0 | AR14: 0 | AS14: 0 | AT14: 0 | AU14: 0 | AV14: 0 | AW14: 0 | AX14: 0 | AY14: 0 | AZ14: 0 | BA14: 0 | BB14: 0 | BC14: 0 | BD14: 0 | BE14: 0 | BF14: 0 | BG14: 0 | BH14: 0 | BI14: 0 | BJ14: 0 | BK14: 0 | BL14: 0 | BM14: 0 | BN14: 0 | BO14: 0 | BP14: 0 | BQ14: 0 | BR14: 0 | BS14: 0 | BT14: 0 | BU14: 0 | BV14: 0 | BX14: 0 | BY14: 0 | BZ14: 0 | CA14: 0 | CB14: 0 | CC14: 0 | CD14: 0 | CE14: 0 | CF14: 0 | CG14: 0 | CH14: 0 | CI14: 0 | CJ14: 0 | CK14: 0 | CL14: 0 | CM14: 0 | CN14: 0 | CO14: 0 | CP14: 0 | CQ14: 0 | CR14: 0 | CS14: 0 | CT14: 0 | CU14: 0 | CV14: 0 | CW14: 0 | CX14: 0 | CY14: 0 | CZ14: 0 | DA14: 0 | DB14: 0 | DC14: 0 | DD14: 0 | DE14: 0 | DF14: 0 | DG14: 0 | DH14: 0 | DI14: 0 | DJ14: 0 | DK14: 0 | DL14: 0 | DM14: 0 | DN14: 0 | DO14: 0 | DP14: 0 | DQ14: 0 | DR14: 0 | DS14: 0 | DT14: 0 | DU14: 0 | DV14: 0 | DW14: 0 | DX14: 0 | DY14: 0 | DZ14: 0 | EA14: 0 | EB14: 0 | EC14: 0 | ED14: 0 | EE14: 0 | EF14: 0 | EG14: 0 | EH14: 0 | EI14: 0 | EJ14: 0 | EK14: 0 | EL14: 0 | EM14: 0 | EN14: 0 | EO14: 0 | EP14: 0 | EQ14: 0 | ER14: 0 | ES14: 0 | ET14: 0 | EU14: 0 | EV14: 0 | EW14: 0 | EX14: 0 | EY14: 0 | EZ14: 0 | FA14: 0 | FB14: 0 | FC14: 0 | FD14: 0 | FE14: 0 | FF14: 0 | FG14: 0 | FH14: 0 | FI14: 0 | FJ14: 0 | FK14: 0 | FL14: 0 | FM14: 0 | FN14: 0 | FO14: 0 | FP14: 0 | FQ14: 0 | FR14: 0 | FS14: 0 | FT14: 0 | FU14: 0 | FV14: 0 | FW14: 0 | FX14: 0 | FY14: 0 | FZ14: 0 | GA14: 0 | GB14: 0 | GC14: 0 | GD14: 0 | GE14: 0 | GF14: 0 | GG14: 0 | GH14: 0 | GI14: 0 | GJ14: 0 | GK14: 0 | GL14: 0 | GM14: 0 | GN14: 0 | GO14: 0 | GP14: 0 | GQ14: 0 | GR14: 0 | GS14: 0 | GT14: 0 | GU14: 0 | GV14: 0 | GW14: 0 | GX14: 0 | GY14: 0 | GZ14: 0 | HA14: 0 | HB14: 0 | HC14: 0 | HD14: 0 | HE14: 0 | HF14: 0 | HG14: 0 | HH14: 0 | HU14: =SUM(O14:HT14) -> 0
A15: 8 | C15: Zone 8 | D15: Nos. | E15: 0 | F15: 0 | G15: 0 | H15: 0 | I15: 0 | J15: 0 | K15: 0 | L15: 0 | M15: =SUM(E15:L15) -> 0 | O15: 0 | P15: 0 | Q15: 0 | R15: 0 | S15: 0 | T15: 0 | U15: 0 | V15: 0 | W15: 0 | X15: 0 | Y15: 0 | Z15: 0 | AA15: 0 | AB15: 0 | AC15: 0 | AD15: 0 | AE15: 0 | AF15: 0 | AG15: 0 | AH15: 0 | AI15: 0 | AJ15: 0 | AK15: 0 | AL15: 0 | AM15: 0 | AN15: 0 | AO15: 0 | AP15: 0 | AR15: 0 | AS15: 0 | AT15: 0 | AU15: 0 | AV15: 0 | AW15: 0 | AX15: 0 | AY15: 0 | AZ15: 0 | BA15: 0 | BB15: 0 | BC15: 0 | BD15: 0 | BE15: 0 | BF15: 0 | BG15: 0 | BH15: 0 | BI15: 0 | BJ15: 0 | BK15: 0 | BL15: 0 | BM15: 0 | BN15: 0 | BO15: 0 | BP15: 0 | BQ15: 0 | BR15: 0 | BS15: 0 | BT15: 0 | BU15: 0 | BV15: 0 | BX15: 0 | BY15: 0 | BZ15: 0 | CA15: 0 | CB15: 0 | CC15: 0 | CD15: 0 | CE15: 0 | CF15: 0 | CG15: 0 | CH15: 0 | CI15: 0 | CJ15: 0 | CK15: 0 | CL15: 0 | CM15: 0 | CN15: 0 | CO15: 0 | CP15: 0 | CQ15: 0 | CR15: 0 | CS15: 0 | CT15: 0 | CU15: 0 | CV15: 0 | CW15: 0 | CX15: 0 | CY15: 0 | CZ15: 0 | DA15: 0 | DB15: 0 | DC15: 0 | DD15: 0 | DE15: 0 | DF15: 0 | DG15: 0 | DH15: 0 | DI15: 0 | DJ15: 0 | DK15: 0 | DL15: 0 | DM15: 0 | DN15: 0 | DO15: 0 | DP15: 0 | DQ15: 0 | DR15: 0 | DS15: 0 | DT15: 0 | DU15: 0 | DV15: 0 | DW15: 0 | DX15: 0 | DY15: 0 | DZ15: 0 | EA15: 0 | EB15: 0 | EC15: 0 | ED15: 0 | EE15: 0 | EF15: 0 | EG15: 0 | EH15: 0 | EI15: 0 | EJ15: 0 | EK15: 0 | EL15: 0 | EM15: 0 | EN15: 0 | EO15: 0 | EP15: 0 | EQ15: 0 | ER15: 0 | ES15: 0 | ET15: 0 | EU15: 0 | EV15: 0 | EW15: 0 | EX15: 0 | EY15: 0 | EZ15: 0 | FA15: 0 | FB15: 0 | FC15: 0 | FD15: 0 | FE15: 0 | FF15: 0 | FG15: 0 | FH15: 0 | FI15: 0 | FJ15: 0 | FK15: 0 | FL15: 0 | FM15: 0 | FN15: 0 | FO15: 0 | FP15: 0 | FQ15: 0 | FR15: 0 | FS15: 0 | FT15: 0 | FU15: 0 | FV15: 0 | FW15: 0 | FX15: 0 | FY15: 0 | FZ15: 0 | GA15: 0 | GB15: 0 | GC15: 0 | GD15: 0 | GE15: 0 | GF15: 0 | GG15: 0 | GH15: 0 | GI15: 0 | GJ15: 0 | GK15: 0 | GL15: 0 | GM15: 0 | GN15: 0 | GO15: 0 | GP15: 0 | GQ15: 0 | GR15: 0 | GS15: 0 | GT15: 0 | GU15: 0 | GV15: 0 | GW15: 0 | GX15: 0 | GY15: 0 | GZ15: 0 | HA15: 0 | HB15: 0 | HC15: 0 | HD15: 0 | HE15: 0 | HF15: 0 | HG15: 0 | HH15: 0 | HU15: =SUM(O15:HT15) -> 0
A16: 9 | C16: Zone 9 | D16: Nos. | E16: 0 | F16: 0 | G16: 0 | H16: 0 | I16: 0 | J16: 0 | K16: 0 | L16: 0 | M16: =SUM(E16:L16) -> 0 | O16: 1 | P16: 0 | Q16: 0 | R16: 0 | S16: 0 | T16: 0 | U16: 0 | V16: 0 | W16: 0 | X16: 0 | Y16: 0 | Z16: 0 | AA16: 0 | AB16: 0 | AC16: 0 | AD16: 0 | AE16: 0 | AF16: 0 | AG16: 0 | AH16: 0 | AI16: 0 | AJ16: 0 | AK16: 0 | AL16: 0 | AM16: 0 | AN16: 0 | AO16: 0 | AP16: 0 | AR16: 0 | AS16: 0 | AT16: 0 | AU16: 0 | AV16: 0 | AW16: 0 | AX16: 0 | AY16: 0 | AZ16: 0 | BA16: 0 | BB16: 0 | BC16: 0 | BD16: 0 | BE16: 0 | BF16: 0 | BG16: 0 | BH16: 0 | BI16: 0 | BJ16: 0 | BK16: 0 | BL16: 0 | BM16: 0 | BN16: 0 | BO16: 0 | BP16: 0 | BQ16: 0 | BR16: 0 | BS16: 0 | BT16: 0 | BU16: 0 | BV16: 0 | BX16: 0 | BY16: 0 | BZ16: 0 | CA16: 0 | CB16: 0 | CC16: 0 | CD16: 1 | CE16: 0 | CF16: 0 | CG16: 0 | CH16: 0 | CI16: 0 | CJ16: 0 | CK16: 0 | CL16: 0 | CM16: 0 | CN16: 0 | CO16: 0 | CP16: 0 | CQ16: 0 | CR16: 0 | CS16: 0 | CT16: 0 | CU16: 0 | CV16: 0 | CW16: 0 | CX16: 0 | CY16: 0 | CZ16: 0 | DA16: 0 | DB16: 0 | DC16: 0 | DD16: 0 | DE16: 0 | DF16: 0 | DG16: 0 | DH16: 0 | DI16: 0 | DJ16: 0 | DK16: 0 | DL16: 0 | DM16: 0 | DN16: 0 | DO16: 0 | DP16: 0 | DQ16: 0 | DR16: 0 | DS16: 0 | DT16: 0 | DU16: 0 | DV16: 0 | DW16: 0 | DX16: 0 | DY16: 0 | DZ16: 0 | EA16: 0 | EB16: 0 | EC16: 0 | ED16: 0 | EE16: 0 | EF16: 0 | EG16: 0 | EH16: 0 | EI16: 0 | EJ16: 0 | EK16: 0 | EL16: 0 | EM16: 0 | EN16: 0 | EO16: 0 | EP16: 0 | EQ16: 0 | ER16: 0 | ES16: 0 | ET16: 0 | EU16: 0 | EV16: 0 | EW16: 0 | EX16: 0 | EY16: 0 | EZ16: 0 | FA16: 0 | FB16: 0 | FC16: 0 | FD16: 0 | FE16: 0 | FF16: 0 | FG16: 0 | FH16: 0 | FI16: 0 | FJ16: 0 | FK16: 0 | FL16: 0 | FM16: 0 | FN16: 0 | FO16: 0 | FP16: 0 | FQ16: 0 | FR16: 0 | FS16: 0 | FT16: 0 | FU16: 0 | FV16: 0 | FW16: 0 | FX16: 0 | FY16: 0 | FZ16: 0 | GA16: 0 | GB16: 0 | GC16: 0 | GD16: 0 | GE16: 0 | GF16: 0 | GG16: 0 | GH16: 0 | GI16: 0 | GJ16: 0 | GK16: 0 | GL16: 0 | GM16: 0 | GN16: 0 | GO16: 0 | GP16: 0 | GQ16: 0 | GR16: 0 | GS16: 0 | GT16: 0 | GU16: 0 | GV16: 0 | GW16: 0 | GX16: 0 | GY16: 0 | GZ16: 0 | HA16: 0 | HB16: 0 | HC16: 0 | HD16: 0 | HE16: 0 | HF16: 0 | HG16: 0 | HH16: 0 | HU16: =SUM(O16:HT16) -> 2
A17: 10 | C17: Zone 10 | D17: Nos. | E17: 0 | F17: 0 | G17: 0 | H17: 0 | I17: 0 | J17: 0 | K17: 0 | L17: 0 | M17: =SUM(E17:L17) -> 0 | O17: 0 | P17: 0 | Q17: 0 | R17: 0 | S17: 0 | T17: 0 | U17: 0 | V17: 0 | W17: 0 | X17: 0 | Y17: 0 | Z17: 0 | AA17: 0 | AB17: 0 | AC17: 0 | AD17: 0 | AE17: 0 | AF17: 0 | AG17: 0 | AH17: 0 | AI17: 0 | AJ17: 0 | AK17: 0 | AL17: 0 | AM17: 0 | AN17: 0 | AO17: 0 | AP17: 0 | AR17: 0 | AS17: 0 | AT17: 0 | AU17: 0 | AV17: 0 | AW17: 0 | AX17: 0 | AY17: 0 | AZ17: 0 | BA17: 0 | BB17: 0 | BC17: 0 | BD17: 0 | BE17: 0 | BF17: 0 | BG17: 0 | BH17: 0 | BI17: 0 | BJ17: 0 | BK17: 0 | BL17: 0 | BM17: 0 | BN17: 0 | BO17: 0 | BP17: 0 | BQ17: 0 | BR17: 0 | BS17: 0 | BT17: 0 | BU17: 0 | BV17: 0 | BX17: 0 | BY17: 0 | BZ17: 0 | CA17: 0 | CB17: 0 | CC17: 0 | CD17: 0 | CE17: 0 | CF17: 0 | CG17: 0 | CH17: 0 | CI17: 0 | CJ17: 0 | CK17: 0 | CL17: 0 | CM17: 0 | CN17: 0 | CO17: 0 | CP17: 0 | CQ17: 0 | CR17: 0 | CS17: 0 | CT17: 0 | CU17: 0 | CV17: 0 | CW17: 0 | CX17: 0 | CY17: 0 | CZ17: 0 | DA17: 0 | DB17: 0 | DC17: 0 | DD17: 0 | DE17: 0 | DF17: 0 | DG17: 0 | DH17: 0 | DI17: 0 | DJ17: 0 | DK17: 0 | DL17: 0 | DM17: 0 | DN17: 0 | DO17: 0 | DP17: 0 | DQ17: 0 | DR17: 0 | DS17: 0 | DT17: 0 | DU17: 0 | DV17: 0 | DW17: 0 | DX17: 0 | DY17: 0 | DZ17: 0 | EA17: 0 | EB17: 0 | EC17: 0 | ED17: 0 | EE17: 0 | EF17: 0 | EG17: 0 | EH17: 0 | EI17: 0 | EJ17: 0 | EK17: 0 | EL17: 0 | EM17: 0 | EN17: 0 | EO17: 0 | EP17: 0 | EQ17: 0 | ER17: 0 | ES17: 0 | ET17: 0 | EU17: 0 | EV17: 0 | EW17: 0 | EX17: 0 | EY17: 0 | EZ17: 0 | FA17: 0 | FB17: 0 | FC17: 0 | FD17: 0 | FE17: 0 | FF17: 0 | FG17: 0 | FH17: 0 | FI17: 0 | FJ17: 0 | FK17: 0 | FL17: 0 | FM17: 0 | FN17: 0 | FO17: 0 | FP17: 0 | FQ17: 0 | FR17: 0 | FS17: 0 | FT17: 0 | FU17: 0 | FV17: 0 | FW17: 0 | FX17: 0 | FY17: 0 | FZ17: 0 | GA17: 0 | GB17: 0 | GC17: 0 | GD17: 0 | GE17: 0 | GF17: 0 | GG17: 0 | GH17: 0 | GI17: 0 | GJ17: 0 | GK17: 0 | GL17: 0 | GM17: 0 | GN17: 0 | GO17: 0 | GP17: 0 | GQ17: 0 | GR17: 0 | GS17: 0 | GT17: 0 | GU17: 0 | GV17: 0 | GW17: 0 | GX17: 0 | GY17: 0 | GZ17: 0 | HA17: 0 | HB17: 0 | HC17: 0 | HD17: 0 | HE17: 0 | HF17: 0 | HG17: 0 | HH17: 0 | HU17: =SUM(O17:HT17) -> 0
A18: 11 | C18: Zone 11 | D18: Nos. | E18: 0 | F18: 0 | G18: 0 | H18: 0 | I18: 0 | J18: 0 | K18: 0 | L18: 0 | M18: =SUM(E18:L18) -> 0 | O18: 0 | P18: 0 | Q18: 0 | R18: 0 | S18: 0 | T18: 0 | U18: 0 | V18: 0 | W18: 0 | X18: 0 | Y18: 0 | Z18: 0 | AA18: 0 | AB18: 0 | AC18: 0 | AD18: 0 | AE18: 0 | AF18: 0 | AG18: 0 | AH18: 0 | AI18: 0 | AJ18: 0 | AK18: 0 | AL18: 0 | AM18: 0 | AN18: 0 | AO18: 0 | AP18: 0 | AR18: 0 | AS18: 0 | AT18: 0 | AU18: 0 | AV18: 0 | AW18: 0 | AX18: 0 | AY18: 0 | AZ18: 0 | BA18: 0 | BB18: 0 | BC18: 0 | BD18: 0 | BE18: 0 | BF18: 0 | BG18: 0 | BH18: 0 | BI18: 0 | BJ18: 0 | BK18: 0 | BL18: 0 | BM18: 0 | BN18: 0 | BO18: 0 | BP18: 0 | BQ18: 0 | BR18: 0 | BS18: 0 | BT18: 0 | BU18: 0 | BV18: 0 | BX18: 0 | BY18: 0 | BZ18: 0 | CA18: 0 | CB18: 0 | CC18: 0 | CD18: 0 | CE18: 0 | CF18: 0 | CG18: 0 | CH18: 0 | CI18: 0 | CJ18: 0 | CK18: 0 | CL18: 0 | CM18: 0 | CN18: 0 | CO18: 0 | CP18: 0 | CQ18: 0 | CR18: 0 | CS18: 0 | CT18: 0 | CU18: 0 | CV18: 0 | CW18: 0 | CX18: 0 | CY18: 0 | CZ18: 0 | DA18: 0 | DB18: 0 | DC18: 0 | DD18: 0 | DE18: 0 | DF18: 0 | DG18: 0 | DH18: 0 | DI18: 0 | DJ18: 0 | DK18: 0 | DL18: 0 | DM18: 0 | DN18: 0 | DO18: 0 | DP18: 0 | DQ18: 0 | DR18: 0 | DS18: 0 | DT18: 0 | DU18: 0 | DV18: 0 | DW18: 0 | DX18: 0 | DY18: 0 | DZ18: 0 | EA18: 0 | EB18: 0 | EC18: 0 | ED18: 0 | EE18: 0 | EF18: 0 | EG18: 0 | EH18: 0 | EI18: 0 | EJ18: 0 | EK18: 0 | EL18: 0 | EM18: 0 | EN18: 0 | EO18: 0 | EP18: 0 | EQ18: 0 | ER18: 0 | ES18: 0 | ET18: 0 | EU18: 0 | EV18: 0 | EW18: 0 | EX18: 0 | EY18: 0 | EZ18: 0 | FA18: 0 | FB18: 0 | FC18: 0 | FD18: 0 | FE18: 0 | FF18: 0 | FG18: 0 | FH18: 0 | FI18: 0 | FJ18: 0 | FK18: 0 | FL18: 0 | FM18: 0 | FN18: 0 | FO18: 0 | FP18: 0 | FQ18: 0 | FR18: 0 | FS18: 0 | FT18: 0 | FU18: 0 | FV18: 0 | FW18: 0 | FX18: 0 | FY18: 0 | FZ18: 0 | GA18: 0 | GB18: 0 | GC18: 0 | GD18: 0 | GE18: 0 | GF18: 0 | GG18: 0 | GH18: 0 | GI18: 0 | GJ18: 0 | GK18: 0 | GL18: 0 | GM18: 0 | GN18: 0 | GO18: 0 | GP18: 0 | GQ18: 0 | GR18: 0 | GS18: 0 | GT18: 0 | GU18: 0 | GV18: 0 | GW18: 0 | GX18: 0 | GY18: 0 | GZ18: 0 | HA18: 0 | HB18: 0 | HC18: 0 | HD18: 0 | HE18: 0 | HF18: 0 | HG18: 0 | HH18: 0 | HU18: =SUM(O18:HT18) -> 0
C19: Sub Total | D19: Nos. | E19: =SUM(E8:E18) -> 0 | F19: =SUM(F8:F18) -> 0 | G19: =SUM(G8:G18) -> 0 | H19: =SUM(H8:H18) -> 0 | I19: =SUM(I8:I18) -> 0 | J19: =SUM(J8:J18) -> 2 | K19: =SUM(K8:K18) -> 0 | L19: =SUM(L8:L18) -> 0 | M19: =SUM(M8:M18) -> 2 | O19: =SUM(O8:O18) -> 1 | P19: =SUM(P8:P18) -> 0 | Q19: =SUM(Q8:Q18) -> 0 | R19: =SUM(R8:R18) -> 0 | S19: =SUM(S8:S18) -> 0 | T19: =SUM(T8:T18) -> 0 | U19: =SUM(U8:U18) -> 0 | V19: =SUM(V8:V18) -> 0 | ... AP19: =SUM(AP8:AP18) -> 0 | AR19: =SUM(AR8:AR18) -> 0 | AS19: =SUM(AS8:AS18) -> 0 | AT19: =SUM(AT8:AT18) -> 0 | AU19: =SUM(AU8:AU18) -> 0 | AV19: =SUM(AV8:AV18) -> 1 | AW19: =SUM(AW8:AW18) -> 0 | AX19: =SUM(AX8:AX18) -> 0 | AY19: =SUM(AY8:AY18) -> 0 | ... BV19: =SUM(BV8:BV18) -> 0 | BX19: =SUM(BX8:BX18) -> 2 | BY19: =SUM(BY8:BY18) -> 0 | BZ19: =SUM(BZ8:BZ18) -> 0 | CA19: =SUM(CA8:CA18) -> 0 | CB19: =SUM(CB8:CB18) -> 0 | CC19: =SUM(CC8:CC18) -> 0 | CD19: =SUM(CD8:CD18) -> 1 | CE19: =SUM(CE8:CE18) -> 0 | ... CG19: =SUM(CG8:CG18) -> 0 | CH19: 0 | CI19: =SUM(CI8:CI18) -> 0 | CJ19: =SUM(CJ8:CJ18) -> 0 | CK19: =SUM(CK8:CK18) -> 0 | CL19: =SUM(CL8:CL18) -> 0 | CM19: =SUM(CM8:CM18) -> 0 | CN19: =SUM(CN8:CN18) -> 0 | CO19: =SUM(CO8:CO18) -> 0 | CP19: =SUM(CP8:CP18) -> 0 | ... HH19: =SUM(HH8:HH18) -> 0 | HU19: =SUM(HU8:HU18) -> 26
A21: 1 | B21: B1 to GF | C21: Zone 1 | D21: Nos. | E21: 0 | F21: 0 | G21: 0 | H21: 0 | I21: 0 | J21: 0 | K21: 0 | L21: 0 | M21: =SUM(E21:L21) -> 0 | O21: 0 | P21: 0 | Q21: 0 | R21: 0 | S21: 0 | T21: 0 | U21: 0 | V21: 0 | W21: 0 | X21: 0 | Y21: 0 | Z21: 0 | AA21: 0 | AB21: 0 | AC21: 0 | AD21: 0 | AE21: 1 | AF21: 0 | AG21: 0 | AH21: 0 | AI21: 0 | AJ21: 0 | AK21: 0 | AL21: 0 | AM21: 0 | AN21: 0 | AO21: 0 | AP21: 0 | AR21: 0 | AS21: 0 | AT21: 0 | AU21: 0 | AV21: 0 | AW21: 0 | AX21: 0 | AY21: 0 | AZ21: 0 | BA21: 0 | BB21: 0 | BC21: 0 | BD21: 0 | BE21: 0 | BF21: 0 | BG21: 0 | BH21: 0 | BI21: 0 | BJ21: 0 | BK21: 0 | BL21: 0 | BM21: 0 | BN21: 0 | BO21: 0 | BP21: 0 | BQ21: 0 | BR21: 0 | BS21: 0 | BT21: 0 | BU21: 0 | BV21: 0 | BX21: 0 | BY21: 0 | BZ21: 0 | CA21: 0 | CB21: 0 | CC21: 0 | CD21: 1 | CE21: 0 | CF21: 0 | CG21: 0 | CH21: 0 | CI21: 0 | CJ21: 0 | CK21: 0 | CL21: 1 | CM21: 0 | CN21: 0 | CO21: 5 | CP21: 0 | CQ21: 0 | CR21: 0 | CS21: 0 | CT21: 0 | CU21: 0 | CV21: 0 | CW21: 4 | CX21: 3 | CY21: 0 | CZ21: 0 | DA21: 3 | DB21: 0 | DC21: 0 | DD21: 3 | DE21: 0 | DF21: 0 | DG21: 7 | DH21: 1 | DI21: 0 | DJ21: 0 | DK21: 0 | DL21: 4 | DM21: 0 | DN21: 1 | DO21: 0 | DP21: 0 | DQ21: 0 | DR21: 1 | DS21: 0 | DT21: 0 | DU21: 0 | DV21: 0 | DW21: 0 | DX21: 0 | DY21: 0 | DZ21: 0 | EA21: 0 | EB21: 0 | EC21: 0 | ED21: 0 | EE21: 0 | EF21: 0 | EG21: 0 | EH21: 0 | EI21: 0 | EJ21: 0 | EK21: 0 | EL21: 0 | EM21: 0 | EN21: 2 | EO21: 0 | EP21: 0 | EQ21: 0 | ER21: 0 | ES21: 0 | ET21: 0 | EU21: 0 | EV21: 0 | EW21: 0 | EX21: 0 | EY21: 0 | EZ21: 0 | FA21: 0 | FB21: 0 | FC21: 0 | FD21: 0 | FE21: 0 | FF21: 0 | FG21: 0 | FH21: 0 | FI21: 0 | FJ21: 0 | FK21: 0 | FL21: 0 | FM21: 0 | FN21: 0 | FO21: 0 | FP21: 0 | FQ21: 0 | FR21: 0 | FS21: 0 | FT21: 0 | FU21: 0 | FV21: 0 | FW21: 0 | FX21: 0 | FY21: 0 | FZ21: 0 | GA21: 0 | GB21: 0 | GC21: 0 | GD21: 0 | GE21: 0 | GF21: 0 | GG21: 0 | GH21: 0 | GI21: 0 | GJ21: 0 | GK21: 0 | GL21: 0 | GM21: 0 | GN21: 0 | GO21: 0 | GP21: 0 | GQ21: 0 | GR21: 0 | GS21: 0 | GT21: 0 | GU21: 0 | GV21: 0 | GW21: 0 | GX21: 0 | GY21: 0 | GZ21: 0 | HA21: 0 | HB21: 0 | HC21: 0 | HD21: 0 | HE21: 0 | HF21: 0 | HG21: 0 | HH21: 0 | HU21: =SUM(O21:HT21) -> 37
A22: 2 | C22: Zone 2 | D22: Nos. | E22: 0 | F22: 0 | G22: 0 | H22: 0 | I22: 0 | J22: 0 | K22: 0 | L22: 0 | M22: =SUM(E22:L22) -> 0 | O22: 0 | P22: 0 | Q22: 0 | R22: 0 | S22: 0 | T22: 0 | U22: 0 | V22: 0 | W22: 0 | X22: 0 | Y22: 0 | Z22: 0 | AA22: 0 | AB22: 0 | AC22: 0 | AD22: 0 | AE22: 0 | AF22: 0 | AG22: 0 | AH22: 0 | AI22: 0 | AJ22: 0 | AK22: 0 | AL22: 0 | AM22: 0 | AN22: 0 | AO22: 0 | AP22: 0 | AR22: 0 | AS22: 0 | AT22: 0 | AU22: 0 | AV22: 0 | AW22: 0 | AX22: 0 | AY22: 0 | AZ22: 0 | BA22: 0 | BB22: 0 | BC22: 0 | BD22: 0 | BE22: 0 | BF22: 0 | BG22: 0 | BH22: 0 | BI22: 0 | BJ22: 0 | BK22: 0 | BL22: 0 | BM22: 0 | BN22: 0 | BO22: 0 | BP22: 0 | BQ22: 0 | BR22: 0 | BS22: 0 | BT22: 0 | BU22: 0 | BV22: 0 | BX22: 0 | BY22: 0 | BZ22: 0 | CA22: 0 | CB22: 0 | CC22: 0 | CD22: 0 | CE22: 0 | CF22: 0 | CG22: 0 | CH22: 0 | CI22: 0 | CJ22: 0 | CK22: 0 | CL22: 0 | CM22: 0 | CN22: 0 | CO22: 0 | CP22: 0 | CQ22: 0 | CR22: 0 | CS22: 0 | CT22: 0 | CU22: 0 | CV22: 0 | CW22: 0 | CX22: 0 | CY22: 0 | CZ22: 0 | DA22: 0 | DB22: 0 | DC22: 0 | DD22: 0 | DE22: 0 | DF22: 0 | DG22: 0 | DH22: 0 | DI22: 0 | DJ22: 0 | DK22: 0 | DL22: 0 | DM22: 0 | DN22: 0 | DO22: 0 | DP22: 0 | DQ22: 0 | DR22: 0 | DS22: 0 | DT22: 0 | DU22: 0 | DV22: 0 | DW22: 0 | DX22: 0 | DY22: 0 | DZ22: 0 | EA22: 0 | EB22: 0 | EC22: 0 | ED22: 0 | EE22: 0 | EF22: 0 | EG22: 0 | EH22: 0 | EI22: 0 | EJ22: 0 | EK22: 0 | EL22: 0 | EM22: 0 | EN22: 0 | EO22: 0 | EP22: 0 | EQ22: 0 | ER22: 0 | ES22: 0 | ET22: 0 | EU22: 0 | EV22: 0 | EW22: 0 | EX22: 0 | EY22: 0 | EZ22: 0 | FA22: 0 | FB22: 0 | FC22: 0 | FD22: 0 | FE22: 0 | FF22: 0 | FG22: 0 | FH22: 0 | FI22: 0 | FJ22: 0 | FK22: 0 | FL22: 0 | FM22: 0 | FN22: 0 | FO22: 0 | FP22: 0 | FQ22: 0 | FR22: 0 | FS22: 0 | FT22: 0 | FU22: 0 | FV22: 0 | FW22: 0 | FX22: 0 | FY22: 0 | FZ22: 0 | GA22: 0 | GB22: 0 | GC22: 0 | GD22: 0 | GE22: 0 | GF22: 0 | GG22: 0 | GH22: 0 | GI22: 0 | GJ22: 0 | GK22: 0 | GL22: 0 | GM22: 0 | GN22: 0 | GO22: 0 | GP22: 0 | GQ22: 0 | GR22: 0 | GS22: 0 | GT22: 0 | GU22: 0 | GV22: 0 | GW22: 0 | GX22: 0 | GY22: 0 | GZ22: 0 | HA22: 0 | HB22: 0 | HC22: 0 | HD22: 0 | HE22: 0 | HF22: 0 | HG22: 0 | HH22: 0 | HU22: =SUM(O22:HT22) -> 0
A23: 3 | C23: Zone 3 | D23: Nos. | E23: 0 | F23: 0 | G23: 0 | H23: 2 | I23: 4 | J23: 0 | K23: 0 | L23: 4 | M23: =SUM(E23:L23) -> 10 | O23: 2 | P23: 2 | Q23: 0 | R23: 1 | S23: 1 | T23: 0 | U23: 0 | V23: 0 | W23: 0 | X23: 0 | Y23: 0 | Z23: 0 | AA23: 0 | AB23: 0 | AC23: 0 | AD23: 0 | AE23: 0 | AF23: 0 | AG23: 0 | AH23: 0 | AI23: 0 | AJ23: 0 | AK23: 0 | AL23: 0 | AM23: 0 | AN23: 0 | AO23: 0 | AP23: 0 | AR23: 0 | AS23: 0 | AT23: 0 | AU23: 0 | AV23: 0 | AW23: 0 | AX23: 1 | AY23: 0 | AZ23: 0 | BA23: 0 | BB23: 0 | BC23: 0 | BD23: 0 | BE23: 0 | BF23: 0 | BG23: 0 | BH23: 0 | BI23: 0 | BJ23: 0 | BK23: 0 | BL23: 0 | BM23: 0 | BN23: 0 | BO23: 0 | BP23: 0 | BQ23: 0 | BR23: 0 | BS23: 0 | BT23: 0 | BU23: 0 | BV23: 0 | BX23: 0 | BY23: 0 | BZ23: 0 | CA23: 0 | CB23: 0 | CC23: 0 | CD23: 0 | CE23: 0 | CF23: 0 | CG23: 0 | CH23: 0 | CI23: 0 | CJ23: 0 | CK23: 0 | CL23: 0 | CM23: 0 | CN23: 0 | CO23: 0 | CP23: 0 | CQ23: 0 | CR23: 0 | CS23: 0 | CT23: 0 | CU23: 0 | CV23: 0 | CW23: 0 | CX23: 0 | CY23: 0 | CZ23: 0 | DA23: 0 | DB23: 0 | DC23: 1 | DD23: 0 | DE23: 0 | DF23: 0 | DG23: 0 | DH23: 0 | DI23: 0 | DJ23: 0 | DK23: 0 | DL23: 0 | DM23: 0 | DN23: 0 | DO23: 0 | DP23: 0 | DQ23: 0 | DR23: 0 | DS23: 0 | DT23: 0 | DU23: 0 | DV23: 0 | DW23: 0 | DX23: 0 | DY23: 0 | DZ23: 0 | EA23: 0 | EB23: 0 | EC23: 0 | ED23: 0 | EE23: 0 | EF23: 0 | EG23: 0 | EH23: 0 | EI23: 0 | EJ23: 0 | EK23: 0 | EL23: 0 | EM23: 0 | EN23: 0 | EO23: 0 | EP23: 0 | EQ23: 0 | ER23: 0 | ES23: 0 | ET23: 0 | EU23: 0 | EV23: 0 | EW23: 0 | EX23: 0 | EY23: 0 | EZ23: 0 | FA23: 0 | FB23: 0 | FC23: 0 | FD23: 0 | FE23: 0 | FF23: 0 | FG23: 0 | FH23: 0 | FI23: 0 | FJ23: 0 | FK23: 0 | FL23: 0 | FM23: 0 | FN23: 0 | FO23: 0 | FP23: 0 | FQ23: 0 | FR23: 0 | FS23: 0 | FT23: 0 | FU23: 0 | FV23: 0 | FW23: 0 | FX23: 0 | FY23: 0 | FZ23: 0 | GA23: 0 | GB23: 0 | GC23: 0 | GD23: 0 | GE23: 0 | GF23: 0 | GG23: 0 | GH23: 0 | GI23: 0 | GJ23: 0 | GK23: 0 | GL23: 0 | GM23: 0 | GN23: 0 | GO23: 0 | GP23: 0 | GQ23: 0 | GR23: 0 | GS23: 0 | GT23: 0 | GU23: 0 | GV23: 0 | GW23: 0 | GX23: 0 | GY23: 0 | GZ23: 0 | HA23: 0 | HB23: 0 | HC23: 0 | HD23: 0 | HE23: 0 | HF23: 0 | HG23: 0 | HH23: 0 | HU23: =SUM(O23:HT23) -> 8
A24: 4 | C24: Zone 4 | D24: Nos. | E24: 0 | F24: 0 | G24: 0 | H24: 0 | I24: 0 | J24: 0 | K24: 0 | L24: 0 | M24: =SUM(E24:L24) -> 0 | O24: 0 | P24: 0 | Q24: 0 | R24: 0 | S24: 0 | T24: 0 | U24: 0 | V24: 0 | W24: 0 | X24: 0 | Y24: 0 | Z24: 0 | AA24: 0 | AB24: 0 | AC24: 0 | AD24: 0 | AE24: 0 | AF24: 6 | AG24: 0 | AH24: 0 | AI24: 0 | AJ24: 0 | AK24: 0 | AL24: 0 | AM24: 0 | AN24: 0 | AO24: 0 | AP24: 0 | AR24: 0 | AS24: 0 | AT24: 0 | AU24: 0 | AV24: 0 | AW24: 0 | AX24: 0 | AY24: 0 | AZ24: 0 | BA24: 4 | BB24: 0 | BC24: 0 | BD24: 0 | BE24: 0 | BF24: 0 | BG24: 0 | BH24: 0 | BI24: 0 | BJ24: 0 | BK24: 0 | BL24: 0 | BM24: 0 | BN24: 0 | BO24: 0 | BP24: 0 | BQ24: 0 | BR24: 0 | BS24: 0 | BT24: 0 | BU24: 0 | BV24: 0 | BX24: 0 | BY24: 0 | BZ24: 0 | CA24: 0 | CB24: 0 | CC24: 0 | CD24: 1 | CE24: 0 | CF24: 0 | CG24: 0 | CH24: 0 | CI24: 0 | CJ24: 0 | CK24: 0 | CL24: 1 | CM24: 0 | CN24: 0 | CO24: 0 | CP24: 0 | CQ24: 0 | CR24: 0 | CS24: 0 | CT24: 0 | CU24: 0 | CV24: 0 | CW24: 0 | CX24: 0 | CY24: 0 | CZ24: 0 | DA24: 0 | DB24: 0 | DC24: 0 | DD24: 0 | DE24: 0 | DF24: 0 | DG24: 0 | DH24: 0 | DI24: 0 | DJ24: 0 | DK24: 0 | DL24: 0 | DM24: 0 | DN24: 0 | DO24: 0 | DP24: 0 | DQ24: 0 | DR24: 0 | DS24: 0 | DT24: 0 | DU24: 0 | DV24: 0 | DW24: 0 | DX24: 0 | DY24: 0 | DZ24: 0 | EA24: 0 | EB24: 0 | EC24: 0 | ED24: 0 | EE24: 0 | EF24: 0 | EG24: 0 | EH24: 0 | EI24: 0 | EJ24: 0 | EK24: 0 | EL24: 0 | EM24: 0 | EN24: 0 | EO24: 0 | EP24: 0 | EQ24: 0 | ER24: 0 | ES24: 0 | ET24: 0 | EU24: 0 | EV24: 0 | EW24: 0 | EX24: 0 | EY24: 0 | EZ24: 0 | FA24: 0 | FB24: 0 | FC24: 0 | FD24: 0 | FE24: 0 | FF24: 0 | FG24: 0 | FH24: 0 | FI24: 0 | FJ24: 0 | FK24: 0 | FL24: 0 | FM24: 0 | FN24: 0 | FO24: 0 | FP24: 0 | FQ24: 0 | FR24: 0 | FS24: 0 | FT24: 0 | FU24: 0 | FV24: 0 | FW24: 0 | FX24: 0 | FY24: 0 | FZ24: 0 | GA24: 0 | GB24: 0 | GC24: 0 | GD24: 0 | GE24: 0 | GF24: 0 | GG24: 0 | GH24: 0 | GI24: 0 | GJ24: 0 | GK24: 0 | GL24: 0 | GM24: 0 | GN24: 0 | GO24: 0 | GP24: 0 | GQ24: 0 | GR24: 0 | GS24: 0 | GT24: 0 | GU24: 0 | GV24: 0 | GW24: 0 | GX24: 0 | GY24: 0 | GZ24: 0 | HA24: 0 | HB24: 0 | HC24: 0 | HD24: 0 | HE24: 0 | HF24: 0 | HG24: 0 | HH24: 0 | HU24: =SUM(O24:HT24) -> 12
A25: 5 | C25: Zone 5 | D25: Nos. | E25: 0 | F25: 0 | G25: 0 | H25: 0 | I25: 0 | J25: 0 | K25: 0 | L25: 0 | M25: =SUM(E25:L25) -> 0 | O25: 0 | P25: 0 | Q25: 0 | R25: 0 | S25: 0 | T25: 0 | U25: 0 | V25: 0 | W25: 0 | X25: 0 | Y25: 0 | Z25: 0 | AA25: 0 | AB25: 0 | AC25: 0 | AD25: 0 | AE25: 0 | AF25: 0 | AG25: 0 | AH25: 0 | AI25: 0 | AJ25: 0 | AK25: 0 | AL25: 0 | AM25: 0 | AN25: 0 | AO25: 0 | AP25: 0 | AR25: 0 | AS25: 0 | AT25: 0 | AU25: 0 | AV25: 0 | AW25: 0 | AX25: 0 | AY25: 0 | AZ25: 0 | BA25: 0 | BB25: 0 | BC25: 0 | BD25: 0 | BE25: 0 | BF25: 0 | BG25: 0 | BH25: 0 | BI25: 0 | BJ25: 0 | BK25: 0 | BL25: 0 | BM25: 0 | BN25: 0 | BO25: 0 | BP25: 0 | BQ25: 0 | BR25: 0 | BS25: 0 | BT25: 0 | BU25: 0 | BV25: 0 | BX25: 5 | BY25: 4 | BZ25: 0 | CA25: 1 | CB25: 2 | CC25: 0 | CD25: 0 | CE25: 0 | CF25: 0 | CG25: 0 | CH25: 0 | CI25: 4 | CJ25: 2 | CK25: 0 | CL25: 0 | CM25: 0 | CN25: 0 | CO25: 0 | CP25: 0 | CQ25: 0 | CR25: 0 | CS25: 0 | CT25: 0 | CU25: 0 | CV25: 0 | CW25: 0 | CX25: 0 | CY25: 0 | CZ25: 0 | DA25: 0 | DB25: 0 | DC25: 0 | DD25: 0 | DE25: 0 | DF25: 0 | DG25: 1 | DH25: 4 | DI25: 0 | DJ25: 9 | DK25: 5 | DL25: 1 | DM25: 4 | DN25: 0 | DO25: 1 | DP25: 0 | DQ25: 0 | DR25: 0 | DS25: 0 | DT25: 0 | DU25: 0 | DV25: 0 | DW25: 0 | DX25: 0 | DY25: 0 | DZ25: 0 | EA25: 0 | EB25: 0 | EC25: 0 | ED25: 0 | EE25: 0 | EF25: 0 | EG25: 0 | EH25: 0 | EI25: 0 | EJ25: 0 | EK25: 0 | EL25: 0 | EM25: 0 | EN25: 0 | EO25: 0 | EP25: 0 | EQ25: 0 | ER25: 0 | ES25: 0 | ET25: 0 | EU25: 0 | EV25: 0 | EW25: 0 | EX25: 0 | EY25: 0 | EZ25: 0 | FA25: 0 | FB25: 0 | FC25: 0 | FD25: 0 | FE25: 0 | FF25: 0 | FG25: 0 | FH25: 0 | FI25: 0 | FJ25: 0 | FK25: 0 | FL25: 0 | FM25: 0 | FN25: 0 | FO25: 0 | FP25: 0 | FQ25: 0 | FR25: 0 | FS25: 0 | FT25: 0 | FU25: 0 | FV25: 0 | FW25: 0 | FX25: 0 | FY25: 0 | FZ25: 0 | GA25: 0 | GB25: 0 | GC25: 0 | GD25: 0 | GE25: 0 | GF25: 0 | GG25: 0 | GH25: 0 | GI25: 0 | GJ25: 0 | GK25: 0 | GL25: 0 | GM25: 0 | GN25: 0 | GO25: 0 | GP25: 0 | GQ25: 0 | GR25: 0 | GS25: 0 | GT25: 0 | GU25: 0 | GV25: 0 | GW25: 0 | GX25: 0 | GY25: 0 | GZ25: 0 | HA25: 0 | HB25: 0 | HC25: 0 | HD25: 0 | HE25: 0 | HF25: 0 | HG25: 0 | HH25: 0 | HU25: =SUM(O25:HT25) -> 43
A26: 6 | C26: Zone 6 | D26: Nos. | E26: 0 | F26: 0 | G26: 0 | H26: 0 | I26: 0 | J26: 0 | K26: 0 | L26: 0 | M26: =SUM(E26:L26) -> 0 | O26: 0 | P26: 0 | Q26: 0 | R26: 0 | S26: 0 | T26: 0 | U26: 0 | V26: 0 | W26: 0 | X26: 0 | Y26: 0 | Z26: 0 | AA26: 0 | AB26: 0 | AC26: 0 | AD26: 0 | AE26: 0 | AF26: 0 | AG26: 0 | AH26: 0 | AI26: 0 | AJ26: 0 | AK26: 0 | AL26: 0 | AM26: 0 | AN26: 0 | AO26: 0 | AP26: 0 | AR26: 0 | AS26: 0 | AT26: 0 | AU26: 0 | AV26: 0 | AW26: 0 | AX26: 0 | AY26: 0 | AZ26: 5 | BA26: 2 | BB26: 3 | BC26: 2 | BD26: 0 | BE26: 2 | BF26: 0 | BG26: 2 | BH26: 2 | BI26: 0 | BJ26: 0 | BK26: 0 | BL26: 0 | BM26: 0 | BN26: 0 | BO26: 5 | BP26: 3 | BQ26: 0 | BR26: 0 | BS26: 0 | BT26: 0 | BU26: 0 | BV26: 0 | BX26: 0 | BY26: 0 | BZ26: 0 | CA26: 0 | CB26: 0 | CC26: 0 | CD26: 0 | CE26: 0 | CF26: 0 | CG26: 0 | CH26: 0 | CI26: 0 | CJ26: 0 | CK26: 0 | CL26: 0 | CM26: 0 | CN26: 0 | CO26: 0 | CP26: 0 | CQ26: 0 | CR26: 0 | CS26: 0 | CT26: 0 | CU26: 0 | CV26: 0 | CW26: 0 | CX26: 0 | CY26: 0 | CZ26: 0 | DA26: 0 | DB26: 0 | DC26: 0 | DD26: 0 | DE26: 0 | DF26: 0 | DG26: 0 | DH26: 0 | DI26: 0 | DJ26: 0 | DK26: 0 | DL26: 0 | DM26: 0 | DN26: 0 | DO26: 0 | DP26: 0 | DQ26: 0 | DR26: 0 | DS26: 0 | DT26: 0 | DU26: 0 | DV26: 0 | DW26: 0 | DX26: 0 | DY26: 0 | DZ26: 0 | EA26: 0 | EB26: 0 | EC26: 0 | ED26: 0 | EE26: 0 | EF26: 0 | EG26: 0 | EH26: 0 | EI26: 0 | EJ26: 0 | EK26: 0 | EL26: 0 | EM26: 0 | EN26: 0 | EO26: 0 | EP26: 0 | EQ26: 0 | ER26: 0 | ES26: 0 | ET26: 0 | EU26: 0 | EV26: 0 | EW26: 0 | EX26: 0 | EY26: 0 | EZ26: 0 | FA26: 0 | FB26: 0 | FC26: 0 | FD26: 0 | FE26: 0 | FF26: 0 | FG26: 0 | FH26: 0 | FI26: 0 | FJ26: 0 | FK26: 0 | FL26: 0 | FM26: 0 | FN26: 0 | FO26: 0 | FP26: 0 | FQ26: 0 | FR26: 0 | FS26: 0 | FT26: 0 | FU26: 0 | FV26: 0 | FW26: 0 | FX26: 0 | FY26: 0 | FZ26: 0 | GA26: 0 | GB26: 0 | GC26: 0 | GD26: 0 | GE26: 0 | GF26: 0 | GG26: 0 | GH26: 0 | GI26: 0 | GJ26: 0 | GK26: 0 | GL26: 0 | GM26: 0 | GN26: 0 | GO26: 0 | GP26: 0 | GQ26: 0 | GR26: 0 | GS26: 0 | GT26: 0 | GU26: 0 | GV26: 0 | GW26: 0 | GX26: 0 | GY26: 0 | GZ26: 0 | HA26: 0 | HB26: 0 | HC26: 0 | HD26: 0 | HE26: 0 | HF26: 0 | HG26: 0 | HH26: 0 | HU26: =SUM(O26:HT26) -> 26
