Workbook
Name ___fac01: #REF!
Name __NCR1: #REF!
Name __NCR2: #REF!
Name __RFI2: #REF!
Name _dd: #REF!
Name _fac01: #REF!
Name attend: #REF!
Name Cat: #REF!
Name category: #REF!
Name CM: #REF!
Name CTI: #REF!
Name DCC: #REF!
Name disc: #REF!
Name Discipline: #REF!
Name e: #REF!
Name Element: #REF!
Name Elements: #REF!
Name Facility: #REF!
Name FC: #REF!
Name foss: #REF!
Name hse: #REF!
Name HSEf: #REF!
Name IRLog: #REF!
Name jfsfsfjsf: #REF!
Name l: #REF!
Name LIST: #REF!
Name LOG: #REF!
Name NCR: #REF!
Name NCRs: #REF!
Name o: #REF!
Name pivot: #REF!
Name PMC_Project_Manager: #REF!
Name Reasons: #REF!
Name reject: #REF!
Name rep: #REF!
Name rev: #REF!
Name Revision: #REF!
Name RFI: #REF!
Name RFIs: #REF!
Name rrr: #REF!
Name SE: #REF!
Name ss: #REF!
Name status: #REF!
Name status2: #REF!
Name subcat: #REF!
Name SubCategory: #REF!
Name Submittal: #REF!
Name Test: #REF!
Name TM: #REF!
Name TMgmt: #REF!
Name type: #REF!
Name Typw: #REF!
Name ujj: #REF!
Name Weekends: #REF!
Name Weeks: #REF!
Name wer: #REF!
Name xxx: #REF!

Sheet GRAND MOSQUE
A1: Section 1: General Information
A2: Report Number: | E2: Report Date:
A3: Project Name: | B3: Diriyah II Grand Mosque | E3: Project Number: | F3: 110
A4: PMC: | B4: DII-Jasara | C4: CSC: | D4: X-ARCHITECTS | E4: Contractor: | F4: MAG-MAN JV
A5: Section 2: QMS and Submittals Status
B6: Total | C6: Code A | D6: Code B | E6: Code C | F6: Code D | G6: Approved % (A & B) | H6: Remarks/Justifications
A7: PEP | B7: =SUM(C7:F7) -> 1 | C7: 0 | D7: 1 | E7: 0 | F7: 0 | G7: =IFERROR((C7+D7)/B7, "0") -> 1
A8: PQP | B8: =SUM(C8:F8) -> 3 | C8: 2 | D8: 1 | E8: 0 | F8: 0 | G8: =IFERROR((C8+D8)/B8, "0") -> 1
A9: QA/QC Procedures | B9: =SUM(C9:F9) -> 11 | C9: 3 | D9: 8 | E9: 0 | F9: 0 | G9: =IFERROR((C9+D9)/B9, "0") -> 1
A10: MS | B10: =SUM(C10:F10) -> 71 | C10: 13 | D10: 46 | E10: 9 | F10: 3 | G10: =IFERROR((C10+D10)/B10, "0") -> 0.83098592
A11: ITP | B11: =SUM(C11:F11) -> 55 | C11: 4 | D11: 50 | E11: 1 | F11: 0 | G11: =IFERROR((C11+D11)/B11, "0") -> 0.98181818
A12: MAR | B12: =SUM(C12:F12) -> 171 | C12: 1 | D12: 120 | E12: 43 | F12: 7 | G12: =IFERROR((C12+D12)/B12, "0") -> 0.70760234
A13: RFR | B13: =SUM(C13:F13) -> 0 | C13: 0 | D13: 0 | E13: 0 | F13: 0 | G13: =IFERROR((C13+D13)/B13, "0") -> 0
A14: SDW | B14: =SUM(C14:F14) -> 853 | C14: 1 | D14: 612 | E14: 223 | F14: 17 | G14: =IFERROR((C14+D14)/B14, "0") -> 0.71864009
A15: Section 3: Non-Conformance Reports (NCRs)
B16: Raised NCRs | C16: Open | D16: Closed | E16: Closed On-Time | F16: Closed % | G16: Closed On-Time % | H16: Raised WIRs | I16: Defect Rate % | J16: Overdue Open NCRs | K16: Remarks/Justifications
A17: This month | B17: 13 | C17: 13 | D17: 3 | E17: 0 | F17: =IFERROR(D17/B17, "NA") -> 0.23076923 | G17: =IFERROR(E17/(D17+J17), "NA") -> 0 | H17: =B25 -> 258 | I17: =IFERROR(B17/H17, "NA") -> 0.050387597
A18: Cumulative | B18: 34 | C18: 11 | D18: 23 | E18: 3 | F18: =IFERROR(D18/B18, "NA") -> 0.67647059 | G18: =IFERROR(E18/(D18+J18), "NA") -> 0.13043478 | H18: =B26 -> 1171 | I18: =IFERROR(B18/H18, "NA") -> 0.029035013
A19: Section 4: Material Inspection Request (MIRs)
B20: Raised MIRs | C20: Approved (A & B) | D20: Approved 1st Time | E20: Approved % | F20: Approved 1st Time % | G20: Remarks/Justifications
A21: This month | B21: 20 | C21: 12 | D21: 12 | E21: =IFERROR(C21/B21, "NA") -> 0.6 | F21: =IFERROR(D21/C21, "NA") -> 1
A22: Cumulative | B22: 114 | C22: 94 | D22: 81 | E22: =IFERROR(C22/B22, "NA") -> 0.8245614 | F22: =IFERROR(D22/C22, "NA") -> 0.86170213
A23: Section 5: Work Inspection Request (WIRs)
B24: Raised WIRs | C24: Approved (A & B) | D24: Approved 1st Time | E24: Approved % | F24: Approved 1st Time % | G24: Remarks/Justifications
A25: This month | B25: 258 | C25: 158 | D25: 139 | E25: =IFERROR(C25/B25, "NA") -> 0.6124031 | F25: =IFERROR(D25/C25, "NA") -> 0.87974684
A26: Cumulative | B26: 1171 | C26: 1007 | D26: 910 | E26: =IFERROR(C26/B26, "NA") -> 0.85994876 | F26: =IFERROR(D26/C26, "NA") -> 0.90367428
A27: Section 6: Request For Information (RFIs)
B28: Total | C28: Responded | D28: Responded on Time | E28: Responded % | F28: Responded on Time % | G28: Overdue Open RFIs | H28: Remarks/Justifications
A29: This month | B29: 13 | C29: 4 | D29: 4 | E29: =IFERROR(C29/B29, "-") -> 0.30769231 | F29: =IFERROR(D29/(C29+G29), "-") -> 1
A30: Cumulative | B30: 161 | C30: 140 | D30: 140 | E30: =IFERROR(C30/B30, "-") -> 0.86956522 | F30: =IFERROR(D30/(C30+G30), "-") -> 1
A31: Section 7: Status of Internal Audits
B32: Planned | C32: Conducted | D32: (%) Conducted | E32: Remarks/Justifications
A33: This Month | B33: 0 | C33: 0 | D33: =IFERROR(C33/B33, "NA") -> NA
A34: Cumulative | B34: 6 | C34: 1 | D34: =IFERROR(C34/B34, "NA") -> 0.16666667
A35: Section 8: Audit Findings - Corrective Actions (CARs)
B36: Total | C36: Open | D36: Closed | E36: Closed % | F36: Remarks/Justifications
A37: This Month | B37: 0 | E37: =IFERROR(D37/B37, "NA") -> NA
A38: Cumulative | B38: 0 | E38: =IFERROR(D38/B38, "NA") -> NA
A39: Section 9: Quality Issues and Mitigation Actions | E39: Mention top 5, and mention the total number
A40: SN. | B40: Quality Issues | C40: Mitigation Plan | D40: Status (Closed / Open)
...

Sheet Waldorf Astoria Hotel & Branded
A1: Section 1: General Information
A2: Report Number: | B2: ='GRAND MOSQUE'!B2 -> 0 | E2: Report Date: | F2: ='GRAND MOSQUE'!F2
A3: Project Name: | B3: Waldorf Astoria Hotel & Branded Residences | E3: Project Number: | F3: 108
A4: PMC: | B4: DII-Jasara | C4: CSC: | E4: Contractor:
A5: Section 2: QMS and Submittals Status
B6: Total | C6: Code A | D6: Code B | E6: Code C | F6: Code D | G6: Approved % (A & B) | H6: Remarks/Justifications
A7: PEP | B7: =SUM(C7:F7) -> 0 | G7: =IFERROR((C7+D7)/B7, "0") -> 0
A8: PQP | B8: =SUM(C8:F8) -> 0 | G8: =IFERROR((C8+D8)/B8, "0") -> 0
A9: QA/QC Procedures | B9: =SUM(C9:F9) -> 0 | G9: =IFERROR((C9+D9)/B9, "0") -> 0
A10: MS | B10: =SUM(C10:F10) -> 0 | G10: =IFERROR((C10+D10)/B10, "0") -> 0
A11: ITP | B11: =SUM(C11:F11) -> 0 | G11: =IFERROR((C11+D11)/B11, "0") -> 0
A12: MAR | B12: =SUM(C12:F12) -> 0 | G12: =IFERROR((C12+D12)/B12, "0") -> 0
A13: RFR | B13: =SUM(C13:F13) -> 0 | G13: =IFERROR((C13+D13)/B13, "0") -> 0
A14: SDW | B14: =SUM(C14:F14) -> 0 | G14: =IFERROR((C14+D14)/B14, "0") -> 0
A15: Section 3: Non-Conformance Reports (NCRs)
B16: Raised NCRs | C16: Open | D16: Closed | E16: Closed On-Time | F16: Closed % | G16: Closed On-Time % | H16: Raised WIRs | I16: Defect Rate % | J16: Overdue Open NCRs | K16: Remarks/Justifications
A17: This month | F17: =IFERROR(D17/B17, "NA") -> NA | G17: =IFERROR(E17/(D17+J17), "NA") -> NA | H17: =B25 -> 0 | I17: =IFERROR(B17/H17, "NA") -> NA
A18: Cumulative | F18: =IFERROR(D18/B18, "NA") -> NA | G18: =IFERROR(E18/(D18+J18), "NA") -> NA | H18: =B26 -> 0 | I18: =IFERROR(B18/H18, "NA") -> NA
A19: Section 4: Material Inspection Request (MIRs)
B20: Raised MIRs | C20: Approved (A & B) | D20: Approved 1st Time | E20: Approved % | F20: Approved 1st Time % | G20: Remarks/Justifications
A21: This month | E21: =IFERROR(C21/B21, "NA") -> NA | F21: =IFERROR(D21/C21, "NA") -> NA
A22: Cumulative | E22: =IFERROR(C22/B22, "NA") -> NA | F22: =IFERROR(D22/C22, "NA") -> NA
A23: Section 5: Work Inspection Request (WIRs)
B24: Raised WIRs | C24: Approved (A & B) | D24: Approved 1st Time | E24: Approved % | F24: Approved 1st Time % | G24: Remarks/Justifications
A25: This month | E25: =IFERROR(C25/B25, "NA") -> NA | F25: =IFERROR(D25/C25, "NA") -> NA
A26: Cumulative | E26: =IFERROR(C26/B26, "NA") -> NA | F26: =IFERROR(D26/C26, "NA") -> NA
A27: Section 6: Request For Information (RFIs)
B28: Total | C28: Responded | D28: Responded on Time | E28: Responded % | F28: Responded on Time % | G28: Overdue Open RFIs | H28: Remarks/Justifications
A29: This month | E29: =IFERROR(C29/B29, "-") -> - | F29: =IFERROR(D29/(C29+G29), "-") -> -
A30: Cumulative | E30: =IFERROR(C30/B30, "-") -> - | F30: =IFERROR(D30/(C30+G30), "-") -> -
A31: Section 7: Status of Internal Audits
B32: Planned | C32: Conducted | D32: (%) Conducted | E32: Remarks/Justifications
A33: This Month | D33: =IFERROR(C33/B33, "NA") -> NA
A34: Cumulative | D34: =IFERROR(C34/B34, "NA") -> NA
A35: Section 8: Audit Findings - Corrective Actions (CARs)
B36: Total | C36: Open | D36: Closed | E36: Closed % | F36: Remarks/Justifications
A37: This Month | E37: =IFERROR(D37/B37, "NA") -> NA
A38: Cumulative | E38: =IFERROR(D38/B38, "NA") -> NA
A39: Section 9: Quality Issues and Mitigation Actions | E39: Mention top 5, and mention the total number
A40: SN. | B40: Quality Issues | C40: Mitigation Plan | D40: Status (Closed / Open)
...

Sheet OPERA HOUSE 
A1: Section 1: General Information
A2: Report Number: | B2: ='GRAND MOSQUE'!B2 -> 0 | E2: Report Date: | F2: ='GRAND MOSQUE'!F2
A3: Project Name: | B3: Royal Diriyah Opera House | E3: Project Number: | F3: 105
A4: PMC: | B4: DII-Jasara | C4: CSC: | D4: Snohetta/ Saudi Diyar | E4: Contractor: | F4: ECM JV
A5: Section 2: QMS and Submittals Status
B6: Total | C6: Code A | D6: Code B | E6: Code C | F6: Code D | G6: Approved % (A & B) | H6: Remarks/Justifications
A7: PEP | B7: =SUM(C7:F7) -> 1 | C7: 0 | D7: 1 | E7: 0 | F7: 0 | G7: =IFERROR((C7+D7)/B7, "0") -> 1
A8: PQP | B8: =SUM(C8:F8) -> 1 | C8: 1 | D8: 0 | E8: 0 | F8: 0 | G8: =IFERROR((C8+D8)/B8, "0") -> 1
A9: QA/QC Procedures | B9: =SUM(C9:F9) -> 11 | C9: 0 | D9: 11 | E9: 0 | F9: 0 | G9: =IFERROR((C9+D9)/B9, "0") -> 1
A10: MS | B10: =SUM(C10:F10) -> 78 | C10: 26 | D10: 34 | E10: 18 | F10: 0 | G10: =IFERROR((C10+D10)/B10, "0") -> 0.76923077 | H10: The Process/ procedure's of Installation are either Incompete / Inaccurate
A11: ITP | B11: =SUM(C11:F11) -> 47 | C11: 16 | D11: 20 | E11: 10 | F11: 1 | G11: =IFERROR((C11+D11)/B11, "0") -> 0.76595745 | H11: The Inspection Hold points requires update
A12: MAR | B12: =SUM(C12:F12) -> 264 | C12: 2 | D12: 161 | E12: 90 | F12: 11 | G12: =IFERROR((C12+D12)/B12, "0") -> 0.61742424 | H12: The MAR's submitted by Sub-Contractors are not Reviewed
A13: RFR | B13: =SUM(C13:F13) -> 0 | C13: 0 | D13: 0 | E13: 0 | F13: 0 | G13: =IFERROR((C13+D13)/B13, "0") -> 0
A14: SDW | B14: =SUM(C14:F14) -> 7990 | C14: 1263 | D14: 5275 | E14: 1440 | F14: 12 | G14: =IFERROR((C14+D14)/B14, "0") -> 0.81827284 | H14: The Shop Drawings require detailed review by ECM Teams
A15: Section 3: Non-Conformance Reports (NCRs)
B16: Raised NCRs | C16: Open | D16: Closed | E16: Closed On-Time | F16: Closed % | G16: Closed On-Time % | H16: Raised WIRs | I16: Defect Rate % | J16: Overdue Open NCRs | K16: Remarks/Justifications
A17: This month | B17: 10 | C17: 10 | D17: 1 | E17: 0 | F17: =IFERROR(D17/B17, "NA") -> 0.1 | G17: =IFERROR(E17/(D17+J17), "NA") -> 0 | H17: =B25 -> 701 | I17: =IFERROR(B17/H17, "NA") -> 0.014265335
A18: Cumulative | B18: 41 | C18: 20 | D18: 21 | E18: 18 | F18: =IFERROR(D18/B18, "NA") -> 0.51219512 | G18: =IFERROR(E18/(D18+J18), "NA") -> 0.5625 | H18: =B26 -> 6315 | I18: =IFERROR(B18/H18, "NA") -> 0.0064924782 | J18: 11 | K18: Delayed CAPA & Correction by ECM JV
A19: Section 4: Material Inspection Request (MIRs)
B20: Raised MIRs | C20: Approved (A & B) | D20: Approved 1st Time | E20: Approved % | F20: Approved 1st Time % | G20: Remarks/Justifications
A21: This month | B21: 66 | C21: 54 | D21: 50 | E21: =IFERROR(C21/B21, "NA") -> 0.81818182 | F21: =IFERROR(D21/C21, "NA") -> 0.92592593
A22: Cumulative | B22: 385 | C22: 365 | D22: 315 | E22: =IFERROR(C22/B22, "NA") -> 0.94805195 | F22: =IFERROR(D22/C22, "NA") -> 0.8630137
A23: Section 5: Work Inspection Request (WIRs)
B24: Raised WIRs | C24: Approved (A & B) | D24: Approved 1st Time | E24: Approved % | F24: Approved 1st Time % | G24: Remarks/Justifications
A25: This month | B25: 701 | C25: 605 | D25: 550 | E25: =IFERROR(C25/B25, "NA") -> 0.86305278 | F25: =IFERROR(D25/C25, "NA") -> 0.90909091
A26: Cumulative | B26: 6315 | C26: 6051 | D26: 5218 | E26: =IFERROR(C26/B26, "NA") -> 0.95819477 | F26: =IFERROR(D26/C26, "NA") -> 0.8623368
A27: Section 6: Request For Information (RFIs)
B28: Total | C28: Responded | D28: Responded on Time | E28: Responded % | F28: Responded on Time % | G28: Overdue Open RFIs | H28: Remarks/Justifications
A29: This month | B29: 119 | C29: 93 | D29: 66 | E29: =IFERROR(C29/B29, "-") -> 0.78151261 | F29: =IFERROR(D29/(C29+G29), "-") -> 0.70967742
A30: Cumulative | B30: 1320 | C30: 1294 | D30: 882 | E30: =IFERROR(C30/B30, "-") -> 0.98030303 | F30: =IFERROR(D30/(C30+G30), "-") -> 0.68108108 | G30: 1
A31: Section 7: Status of Internal Audits
B32: Planned | C32: Conducted | D32: (%) Conducted | E32: Remarks/Justifications | G32: 21+11
A33: This Month | B33: 1 | C33: 1 | D33: =IFERROR(C33/B33, "NA") -> 1 | E33: Pending Audit Findings
A34: Cumulative | B34: 1 | C34: 1 | D34: =IFERROR(C34/B34, "NA") -> 1
A35: Section 8: Audit Findings - Corrective Actions (CARs)
B36: Total | C36: Open | D36: Closed | E36: Closed % | F36: Remarks/Justifications
A37: This Month | E37: =IFERROR(D37/B37, "NA") -> NA
A38: Cumulative | E38: =IFERROR(D38/B38, "NA") -> NA
A39: Section 9: Quality Issues and Mitigation Actions | E39: Mention top 5, and mention the total number
A40: SN. | B40: Quality Issues | C40: Mitigation Plan | D40: Status (Closed / Open)
...

Sheet District Level - BSW
A1: Section 1: General Information
A2: Report Number: | B2: ='GRAND MOSQUE'!B2 -> 0 | E2: Report Date: | F2: ='GRAND MOSQUE'!F2
A3: District Name: | B3: Boulevard Southwest | E3: District Abbreviation : | F3: BSW
A4: PMC: | B4: DII-Jasara | E4: Sub- Program: | F4: BV-Boulevard Community
A5: Section 2: QMS and Submittals Status
B6: Total | C6: Code A | D6: Code B | E6: Code C | F6: Code D | G6: Approved % (A & B) | H6: Remarks/Justifications
A7: PEP | B7: =SUM(C7:F7) -> #REF! | C7: ='OPERA HOUSE '!C7+#REF! -> #REF! | D7: ='OPERA HOUSE '!D7+#REF! -> #REF! | E7: ='OPERA HOUSE '!E7+#REF! -> #REF! | F7: ='OPERA HOUSE '!F7+#REF! -> #REF! | G7: =IFERROR((C7+D7)/B7, "0") -> 0
A8: PQP | B8: =SUM(C8:F8) -> #REF! | C8: ='OPERA HOUSE '!C8+#REF! -> #REF! | D8: ='OPERA HOUSE '!D8+#REF! -> #REF! | E8: ='OPERA HOUSE '!E8+#REF! -> #REF! | F8: ='OPERA HOUSE '!F8+#REF! -> #REF! | G8: =IFERROR((C8+D8)/B8, "0") -> 0
A9: QA/QC Procedures | B9: =SUM(C9:F9) -> #REF! | C9: ='OPERA HOUSE '!C9+#REF! -> #REF! | D9: ='OPERA HOUSE '!D9+#REF! -> #REF! | E9: ='OPERA HOUSE '!E9+#REF! -> #REF! | F9: ='OPERA HOUSE '!F9+#REF! -> #REF! | G9: =IFERROR((C9+D9)/B9, "0") -> 0
A10: MS | B10: =SUM(C10:F10) -> #REF! | C10: ='OPERA HOUSE '!C10+#REF! -> #REF! | D10: ='OPERA HOUSE '!D10+#REF! -> #REF! | E10: ='OPERA HOUSE '!E10+#REF! -> #REF! | F10: ='OPERA HOUSE '!F10+#REF! -> #REF! | G10: =IFERROR((C10+D10)/B10, "0") -> 0
A11: ITP | B11: =SUM(C11:F11) -> #REF! | C11: ='OPERA HOUSE '!C11+#REF! -> #REF! | D11: ='OPERA HOUSE '!D11+#REF! -> #REF! | E11: ='OPERA HOUSE '!E11+#REF! -> #REF! | F11: ='OPERA HOUSE '!F11+#REF! -> #REF! | G11: =IFERROR((C11+D11)/B11, "0") -> 0
A12: MAR | B12: =SUM(C12:F12) -> #REF! | C12: ='OPERA HOUSE '!C12+#REF! -> #REF! | D12: ='OPERA HOUSE '!D12+#REF! -> #REF! | E12: ='OPERA HOUSE '!E12+#REF! -> #REF! | F12: ='OPERA HOUSE '!F12+#REF! -> #REF! | G12: =IFERROR((C12+D12)/B12, "0") -> 0
A13: RFR | B13: =SUM(C13:F13) -> #REF! | C13: ='OPERA HOUSE '!C13+#REF! -> #REF! | D13: ='OPERA HOUSE '!D13+#REF! -> #REF! | E13: ='OPERA HOUSE '!E13+#REF! -> #REF! | F13: ='OPERA HOUSE '!F13+#REF! -> #REF! | G13: =IFERROR((C13+D13)/B13, "0") -> 0
A14: SDW | B14: =SUM(C14:F14) -> #REF! | C14: ='OPERA HOUSE '!C14+#REF! -> #REF! | D14: ='OPERA HOUSE '!D14+#REF! -> #REF! | E14: ='OPERA HOUSE '!E14+#REF! -> #REF! | F14: ='OPERA HOUSE '!F14+#REF! -> #REF! | G14: =IFERROR((C14+D14)/B14, "0") -> 0
A15: Section 3: Non-Conformance Reports (NCRs)
B16: Raised NCRs | C16: Open | D16: Closed | E16: Closed On-Time | F16: Closed % | G16: Closed On-Time % | H16: Raised WIRs | I16: Defect Rate % | J16: Overdue Open NCRs | K16: Remarks/Justifications
A17: This month | B17: ='OPERA HOUSE '!B17+#REF! -> #REF! | C17: ='OPERA HOUSE '!C17+#REF! -> #REF! | D17: ='OPERA HOUSE '!D17+#REF! -> #REF! | E17: ='OPERA HOUSE '!E17+#REF! -> #REF! | F17: =IFERROR(D17/B17, "NA") -> NA | G17: =IFERROR(E17/(D17+J17), "NA") -> NA | H17: =B25 -> #REF! | I17: =IFERROR(B17/H17, "NA") -> NA | J17: ='OPERA HOUSE '!J17+#REF! -> #REF!
A18: Cumulative | B18: ='OPERA HOUSE '!B18+#REF! -> #REF! | C18: ='OPERA HOUSE '!C18+#REF! -> #REF! | D18: ='OPERA HOUSE '!D18+#REF! -> #REF! | E18: ='OPERA HOUSE '!E18+#REF! -> #REF! | F18: =IFERROR(D18/B18, "NA") -> NA | G18: =IFERROR(E18/(D18+J18), "NA") -> NA | H18: =B26 -> #REF! | I18: =IFERROR(B18/H18, "NA") -> NA | J18: ='OPERA HOUSE '!J18+#REF! -> #REF!
A19: Section 4: Material Inspection Request (MIRs)
B20: Raised MIRs | C20: Approved (A & B) | D20: Approved 1st Time | E20: Approved % | F20: Approved 1st Time % | G20: Remarks/Justifications
A21: This month | B21: ='OPERA HOUSE '!B21+#REF! -> #REF! | C21: ='OPERA HOUSE '!C21+#REF! -> #REF! | D21: ='OPERA HOUSE '!D21+#REF! -> #REF! | E21: =IFERROR(C21/B21, "NA") -> NA | F21: =IFERROR(D21/C21, "NA") -> NA
A22: Cumulative | B22: ='OPERA HOUSE '!B22+#REF! -> #REF! | C22: ='OPERA HOUSE '!C22+#REF! -> #REF! | D22: ='OPERA HOUSE '!D22+#REF! -> #REF! | E22: =IFERROR(C22/B22, "NA") -> NA | F22: =IFERROR(D22/C22, "NA") -> NA
A23: Section 5: Work Inspection Request (WIRs)
B24: Raised WIRs | C24: Approved (A & B) | D24: Approved 1st Time | E24: Approved % | F24: Approved 1st Time % | G24: Remarks/Justifications
A25: This month | B25: ='OPERA HOUSE '!B25+#REF! -> #REF! | C25: ='OPERA HOUSE '!C25+#REF! -> #REF! | D25: ='OPERA HOUSE '!D25+#REF! -> #REF! | E25: =IFERROR(C25/B25, "NA") -> NA | F25: =IFERROR(D25/C25, "NA") -> NA
A26: Cumulative | B26: ='OPERA HOUSE '!B26+#REF! -> #REF! | C26: ='OPERA HOUSE '!C26+#REF! -> #REF! | D26: ='OPERA HOUSE '!D26+#REF! -> #REF! | E26: =IFERROR(C26/B26, "NA") -> NA | F26: =IFERROR(D26/C26, "NA") -> NA
A27: Section 6: Request For Information (RFIs)
B28: Total | C28: Responded | D28: Responded on Time | E28: Responded % | F28: Responded on Time % | G28: Overdue Open RFIs | H28: Remarks/Justifications
A29: This month | B29: ='OPERA HOUSE '!B29+#REF! -> #REF! | C29: ='OPERA HOUSE '!C29+#REF! -> #REF! | D29: ='OPERA HOUSE '!D29+#REF! -> #REF! | E29: =IFERROR(C29/B29, "-") -> - | F29: =IFERROR(D29/(C29+G29), "-") -> - | G29: ='OPERA HOUSE '!G29+#REF! -> #REF!
A30: Cumulative | B30: ='OPERA HOUSE '!B30+#REF! -> #REF! | C30: ='OPERA HOUSE '!C30+#REF! -> #REF! | D30: ='OPERA HOUSE '!D30+#REF! -> #REF! | E30: =IFERROR(C30/B30, "-") -> - | F30: =IFERROR(D30/(C30+G30), "-") -> - | G30: ='OPERA HOUSE '!G30+#REF! -> #REF!
A31: Section 7: Status of Internal Audits
B32: Planned | C32: Conducted | D32: (%) Conducted | E32: Remarks/Justifications
A33: This Month | B33: ='OPERA HOUSE '!B33+#REF! -> #REF! | C33: ='OPERA HOUSE '!C33+#REF! -> #REF! | D33: =IFERROR(C33/B33, "NA") -> NA
A34: Cumulative | B34: ='OPERA HOUSE '!B34+#REF! -> #REF! | C34: ='OPERA HOUSE '!C34+#REF! -> #REF! | D34: =IFERROR(C34/B34, "NA") -> NA
A35: Section 8: Audit Findings - Corrective Actions (CARs)
B36: Total | C36: Open | D36: Closed | E36: Closed % | F36: Remarks/Justifications
A37: This Month | B37: ='OPERA HOUSE '!B37+#REF! -> #REF! | C37: ='OPERA HOUSE '!C37+#REF! -> #REF! | D37: ='OPERA HOUSE '!D37+#REF! -> #REF! | E37: =IFERROR(D37/B37, "NA") -> NA
A38: Cumulative | B38: ='OPERA HOUSE '!B38+#REF! -> #REF! | C38: ='OPERA HOUSE '!C38+#REF! -> #REF! | D38: ='OPERA HOUSE '!D38+#REF! -> #REF! | E38: =IFERROR(D38/B38, "NA") -> NA
A39: Section 9: Quality Issues and Mitigation Actions | E39: Mention top 5, and mention the total number
A40: SN. | B40: Quality Issues | C40: Mitigation Plan | D40: Status (Closed / Open)
...

Sheet PMC Report- District level
A1: Section 1: General Information
A2: Report Number: | B2: ='GRAND MOSQUE'!B2 -> 0 | E2: Report Date: | F2: ='GRAND MOSQUE'!F2
A3: District Name: | B3: Boulevard Southwest | E3: District Abbreviation : | F3: BSW
A4: PMC: | B4: DII-Jasara | E4: Sub- Program: | F4: BV-Boulevard Community
A5: Section 2: QMS and Submittals Status
B6: Total | C6: Code A | D6: Code B | E6: Code C | F6: Code D | G6: Approved % (A & B) | H6: Remarks/Justifications
A7: PEP | B7: =SUM(C7:F7) -> #REF! | C7: ='GRAND MOSQUE'!C7+'OPERA HOUSE '!C7+'Waldorf Astoria Hotel & Branded'!C7+#REF! -> #REF! | D7: ='GRAND MOSQUE'!D7+'OPERA HOUSE '!D7+'Waldorf Astoria Hotel & Branded'!D7+#REF! -> #REF! | E7: ='GRAND MOSQUE'!E7+'OPERA HOUSE '!E7+'Waldorf Astoria Hotel & Branded'!E7+#REF! -> #REF! | F7: ='GRAND MOSQUE'!F7+'OPERA HOUSE '!F7+'Waldorf Astoria Hotel & Branded'!F7+#REF! -> #REF! | G7: =IFERROR((C7+D7)/B7, "0") -> 0
A8: PQP | B8: =SUM(C8:F8) -> #REF! | C8: ='GRAND MOSQUE'!C8+'OPERA HOUSE '!C8+'Waldorf Astoria Hotel & Branded'!C8+#REF! -> #REF! | D8: ='GRAND MOSQUE'!D8+'OPERA HOUSE '!D8+'Waldorf Astoria Hotel & Branded'!D8+#REF! -> #REF! | E8: ='GRAND MOSQUE'!E8+'OPERA HOUSE '!E8+'Waldorf Astoria Hotel & Branded'!E8+#REF! -> #REF! | F8: ='GRAND MOSQUE'!F8+'OPERA HOUSE '!F8+'Waldorf Astoria Hotel & Branded'!F8+#REF! -> #REF! | G8: =IFERROR((C8+D8)/B8, "0") -> 0
A9: QA/QC Procedures | B9: =SUM(C9:F9) -> #REF! | C9: ='GRAND MOSQUE'!C9+'OPERA HOUSE '!C9+'Waldorf Astoria Hotel & Branded'!C9+#REF! -> #REF! | D9: ='GRAND MOSQUE'!D9+'OPERA HOUSE '!D9+'Waldorf Astoria Hotel & Branded'!D9+#REF! -> #REF! | E9: ='GRAND MOSQUE'!E9+'OPERA HOUSE '!E9+'Waldorf Astoria Hotel & Branded'!E9+#REF! -> #REF! | F9: ='GRAND MOSQUE'!F9+'OPERA HOUSE '!F9+'Waldorf Astoria Hotel & Branded'!F9+#REF! -> #REF! | G9: =IFERROR((C9+D9)/B9, "0") -> 0
A10: MS | B10: =SUM(C10:F10) -> #REF! | C10: ='GRAND MOSQUE'!C10+'OPERA HOUSE '!C10+'Waldorf Astoria Hotel & Branded'!C10+#REF! -> #REF! | D10: ='GRAND MOSQUE'!D10+'OPERA HOUSE '!D10+'Waldorf Astoria Hotel & Branded'!D10+#REF! -> #REF! | E10: ='GRAND MOSQUE'!E10+'OPERA HOUSE '!E10+'Waldorf Astoria Hotel & Branded'!E10+#REF! -> #REF! | F10: ='GRAND MOSQUE'!F10+'OPERA HOUSE '!F10+'Waldorf Astoria Hotel & Branded'!F10+#REF! -> #REF! | G10: =IFERROR((C10+D10)/B10, "0") -> 0
A11: ITP | B11: =SUM(C11:F11) -> #REF! | C11: ='GRAND MOSQUE'!C11+'OPERA HOUSE '!C11+'Waldorf Astoria Hotel & Branded'!C11+#REF! -> #REF! | D11: ='GRAND MOSQUE'!D11+'OPERA HOUSE '!D11+'Waldorf Astoria Hotel & Branded'!D11+#REF! -> #REF! | E11: ='GRAND MOSQUE'!E11+'OPERA HOUSE '!E11+'Waldorf Astoria Hotel & Branded'!E11+#REF! -> #REF! | F11: ='GRAND MOSQUE'!F11+'OPERA HOUSE '!F11+'Waldorf Astoria Hotel & Branded'!F11+#REF! -> #REF! | G11: =IFERROR((C11+D11)/B11, "0") -> 0
A12: MAR | B12: =SUM(C12:F12) -> #REF! | C12: ='GRAND MOSQUE'!C12+'OPERA HOUSE '!C12+'Waldorf Astoria Hotel & Branded'!C12+#REF! -> #REF! | D12: ='GRAND MOSQUE'!D12+'OPERA HOUSE '!D12+'Waldorf Astoria Hotel & Branded'!D12+#REF! -> #REF! | E12: ='GRAND MOSQUE'!E12+'OPERA HOUSE '!E12+'Waldorf Astoria Hotel & Branded'!E12+#REF! -> #REF! | F12: ='GRAND MOSQUE'!F12+'OPERA HOUSE '!F12+'Waldorf Astoria Hotel & Branded'!F12+#REF! -> #REF! | G12: =IFERROR((C12+D12)/B12, "0") -> 0
A13: RFR | B13: =SUM(C13:F13) -> #REF! | C13: ='GRAND MOSQUE'!C13+'OPERA HOUSE '!C13+'Waldorf Astoria Hotel & Branded'!C13+#REF! -> #REF! | D13: ='GRAND MOSQUE'!D13+'OPERA HOUSE '!D13+'Waldorf Astoria Hotel & Branded'!D13+#REF! -> #REF! | E13: ='GRAND MOSQUE'!E13+'OPERA HOUSE '!E13+'Waldorf Astoria Hotel & Branded'!E13+#REF! -> #REF! | F13: ='GRAND MOSQUE'!F13+'OPERA HOUSE '!F13+'Waldorf Astoria Hotel & Branded'!F13+#REF! -> #REF! | G13: =IFERROR((C13+D13)/B13, "0") -> 0
A14: SDW | B14: =SUM(C14:F14) -> #REF! | C14: ='GRAND MOSQUE'!C14+'OPERA HOUSE '!C14+'Waldorf Astoria Hotel & Branded'!C14+#REF! -> #REF! | D14: ='GRAND MOSQUE'!D14+'OPERA HOUSE '!D14+'Waldorf Astoria Hotel & Branded'!D14+#REF! -> #REF! | E14: ='GRAND MOSQUE'!E14+'OPERA HOUSE '!E14+'Waldorf Astoria Hotel & Branded'!E14+#REF! -> #REF! | F14: ='GRAND MOSQUE'!F14+'OPERA HOUSE '!F14+'Waldorf Astoria Hotel & Branded'!F14+#REF! -> #REF! | G14: =IFERROR((C14+D14)/B14, "0") -> 0
A15: Section 3: Non-Conformance Reports (NCRs)
B16: Raised NCRs | C16: Open | D16: Closed | E16: Closed On-Time | F16: Closed % | G16: Closed On-Time % | H16: Raised WIRs | I16: Defect Rate % | J16: Overdue Open NCRs | K16: Remarks/Justifications
A17: This month | B17: ='GRAND MOSQUE'!B17+'OPERA HOUSE '!B17+'Waldorf Astoria Hotel & Branded'!B17+#REF! -> #REF! | C17: ='GRAND MOSQUE'!C17+'OPERA HOUSE '!C17+'Waldorf Astoria Hotel & Branded'!C17+#REF! -> #REF! | D17: ='GRAND MOSQUE'!D17+'OPERA HOUSE '!D17+'Waldorf Astoria Hotel & Branded'!D17+#REF! -> #REF! | E17: ='GRAND MOSQUE'!E17+'OPERA HOUSE '!E17+'Waldorf Astoria Hotel & Branded'!E17+#REF! -> #REF! | F17: =IFERROR(D17/B17, "NA") -> NA | G17: =IFERROR(E17/(D17+J17), "NA") -> NA | H17: =B25 -> #REF! | I17: =IFERROR(B17/H17, "NA") -> NA | J17: ='GRAND MOSQUE'!J17+'OPERA HOUSE '!J17+'Waldorf Astoria Hotel & Branded'!J17+#REF! -> #REF!
A18: Cumulative | B18: ='GRAND MOSQUE'!B18+'OPERA HOUSE '!B18+'Waldorf Astoria Hotel & Branded'!B18+#REF! -> #REF! | C18: ='GRAND MOSQUE'!C18+'OPERA HOUSE '!C18+'Waldorf Astoria Hotel & Branded'!C18+#REF! -> #REF! | D18: ='GRAND MOSQUE'!D18+'OPERA HOUSE '!D18+'Waldorf Astoria Hotel & Branded'!D18+#REF! -> #REF! | E18: ='GRAND MOSQUE'!E18+'OPERA HOUSE '!E18+'Waldorf Astoria Hotel & Branded'!E18+#REF! -> #REF! | F18: =IFERROR(D18/B18, "NA") -> NA | G18: =IFERROR(E18/(D18+J18), "NA") -> NA | H18: =B26 -> #REF! | I18: =IFERROR(B18/H18, "NA") -> NA | J18: ='GRAND MOSQUE'!J18+'OPERA HOUSE '!J18+'Waldorf Astoria Hotel & Branded'!J18+#REF! -> #REF!
A19: Section 4: Material Inspection Request (MIRs)
B20: Raised MIRs | C20: Approved (A & B) | D20: Approved 1st Time | E20: Approved % | F20: Approved 1st Time % | G20: Remarks/Justifications
A21: This month | B21: ='GRAND MOSQUE'!B21+'OPERA HOUSE '!B21+'Waldorf Astoria Hotel & Branded'!B21+#REF! -> #REF! | C21: ='GRAND MOSQUE'!C21+'OPERA HOUSE '!C21+'Waldorf Astoria Hotel & Branded'!C21+#REF! -> #REF! | D21: ='GRAND MOSQUE'!D21+'OPERA HOUSE '!D21+'Waldorf Astoria Hotel & Branded'!D21+#REF! -> #REF! | E21: =IFERROR(C21/B21, "NA") -> NA | F21: =IFERROR(D21/C21, "NA") -> NA
A22: Cumulative | B22: ='GRAND MOSQUE'!B22+'OPERA HOUSE '!B22+'Waldorf Astoria Hotel & Branded'!B22+#REF! -> #REF! | C22: ='GRAND MOSQUE'!C22+'OPERA HOUSE '!C22+'Waldorf Astoria Hotel & Branded'!C22+#REF! -> #REF! | D22: ='GRAND MOSQUE'!D22+'OPERA HOUSE '!D22+'Waldorf Astoria Hotel & Branded'!D22+#REF! -> #REF! | E22: =IFERROR(C22/B22, "NA") -> NA | F22: =IFERROR(D22/C22, "NA") -> NA
A23: Section 5: Work Inspection Request (WIRs)
B24: Raised WIRs | C24: Approved (A & B) | D24: Approved 1st Time | E24: Approved % | F24: Approved 1st Time % | G24: Remarks/Justifications
A25: This month | B25: ='GRAND MOSQUE'!B25+'OPERA HOUSE '!B25+'Waldorf Astoria Hotel & Branded'!B25+#REF! -> #REF! | C25: ='GRAND MOSQUE'!C25+'OPERA HOUSE '!C25+'Waldorf Astoria Hotel & Branded'!C25+#REF! -> #REF! | D25: ='GRAND MOSQUE'!D25+'OPERA HOUSE '!D25+'Waldorf Astoria Hotel & Branded'!D25+#REF! -> #REF! | E25: =IFERROR(C25/B25, "NA") -> NA | F25: =IFERROR(D25/C25, "NA") -> NA
A26: Cumulative | B26: ='GRAND MOSQUE'!B26+'OPERA HOUSE '!B26+'Waldorf Astoria Hotel & Branded'!B26+#REF! -> #REF! | C26: ='GRAND MOSQUE'!C26+'OPERA HOUSE '!C26+'Waldorf Astoria Hotel & Branded'!C26+#REF! -> #REF! | D26: ='GRAND MOSQUE'!D26+'OPERA HOUSE '!D26+'Waldorf Astoria Hotel & Branded'!D26+#REF! -> #REF! | E26: =IFERROR(C26/B26, "NA") -> NA | F26: =IFERROR(D26/C26, "NA") -> NA
A27: Section 6: Request For Information (RFIs)
B28: Total | C28: Responded | D28: Responded on Time | E28: Responded % | F28: Responded on Time % | G28: Overdue Open RFIs | H28: Remarks/Justifications
A29: This month | B29: ='GRAND MOSQUE'!B29+'OPERA HOUSE '!B29+'Waldorf Astoria Hotel & Branded'!B29+#REF! -> #REF! | C29: ='GRAND MOSQUE'!C29+'OPERA HOUSE '!C29+'Waldorf Astoria Hotel & Branded'!C29+#REF! -> #REF! | D29: ='GRAND MOSQUE'!D29+'OPERA HOUSE '!D29+'Waldorf Astoria Hotel & Branded'!D29+#REF! -> #REF! | E29: =IFERROR(C29/B29, "-") -> - | F29: =IFERROR(D29/(C29+G29), "-") -> - | G29: ='GRAND MOSQUE'!G29+'OPERA HOUSE '!G29+'Waldorf Astoria Hotel & Branded'!G29+#REF! -> #REF!
A30: Cumulative | B30: ='GRAND MOSQUE'!B30+'OPERA HOUSE '!B30+'Waldorf Astoria Hotel & Branded'!B30+#REF! -> #REF! | C30: ='GRAND MOSQUE'!C30+'OPERA HOUSE '!C30+'Waldorf Astoria Hotel & Branded'!C30+#REF! -> #REF! | D30: ='GRAND MOSQUE'!D30+'OPERA HOUSE '!D30+'Waldorf Astoria Hotel & Branded'!D30+#REF! -> #REF! | E30: =IFERROR(C30/B30, "-") -> - | F30: =IFERROR(D30/(C30+G30), "-") -> - | G30: ='GRAND MOSQUE'!G30+'OPERA HOUSE '!G30+'Waldorf Astoria Hotel & Branded'!G30+#REF! -> #REF!
A31: Section 7: Status of Internal Audits
B32: Planned | C32: Conducted | D32: (%) Conducted | E32: Remarks/Justifications
A33: This Month | B33: ='GRAND MOSQUE'!B33+'OPERA HOUSE '!B33+'Waldorf Astoria Hotel & Branded'!B33+#REF! -> #REF! | C33: ='GRAND MOSQUE'!C33+'OPERA HOUSE '!C33+'Waldorf Astoria Hotel & Branded'!C33+#REF! -> #REF! | D33: =IFERROR(C33/B33, "NA") -> NA
A34: Cumulative | B34: ='GRAND MOSQUE'!B34+'OPERA HOUSE '!B34+'Waldorf Astoria Hotel & Branded'!B34+#REF! -> #REF! | C34: ='GRAND MOSQUE'!C34+'OPERA HOUSE '!C34+'Waldorf Astoria Hotel & Branded'!C34+#REF! -> #REF! | D34: =IFERROR(C34/B34, "NA") -> NA
A35: Section 8: Audit Findings - Corrective Actions (CARs)
B36: Total | C36: Open | D36: Closed | E36: Closed % | F36: Remarks/Justifications
A37: This Month | B37: ='GRAND MOSQUE'!B37+'OPERA HOUSE '!B37+'Waldorf Astoria Hotel & Branded'!B37+#REF! -> #REF! | C37: ='GRAND MOSQUE'!C37+'OPERA HOUSE '!C37+'Waldorf Astoria Hotel & Branded'!C37+#REF! -> #REF! | D37: ='GRAND MOSQUE'!D37+'OPERA HOUSE '!D37+'Waldorf Astoria Hotel & Branded'!D37+#REF! -> #REF! | E37: =IFERROR(D37/B37, "NA") -> NA
A38: Cumulative | B38: ='GRAND MOSQUE'!B38+'OPERA HOUSE '!B38+'Waldorf Astoria Hotel & Branded'!B38+#REF! -> #REF! | C38: ='GRAND MOSQUE'!C38+'OPERA HOUSE '!C38+'Waldorf Astoria Hotel & Branded'!C38+#REF! -> #REF! | D38: ='GRAND MOSQUE'!D38+'OPERA HOUSE '!D38+'Waldorf Astoria Hotel & Branded'!D38+#REF! -> #REF! | E38: =IFERROR(D38/B38, "NA") -> NA
A39: Section 9: Quality Issues and Mitigation Actions | E39: Mention top 5, and mention the total number
A40: SN. | B40: Quality Issues | C40: Mitigation Plan | D40: Status (Closed / Open)
...

Sheet Metrics
A1: SN. | B1: P. Areas | C1: Metrics | D1: Description | E1: PMC Cumulative | F1: Target | G1: (RAG) Criteria | H1: Score Weight. | I1: Target Value | J1: Value | K1: Remarks
A2: 1 | B2: Leadership Enagement | C2: M03 | D2: The rate of conducting regular leadership Quality site walks (Monthly, Weekly). Monthly weight 40% weekly weight 60% | E2: Weekly | F2: Monthly: 1Weekly: 3 (excluding the monthly meeting week )100% | G2: Green = 100% Amber = > 40% –60% Red = < 40% | H2: 0.05 | I2: 1 | J2: ='PMC Report- District level'!D66 -> NA
E3: Monthly | J3: ='PMC Report- District level'!D69 -> NA
C4: M04 | D4: The rate of conducting regular project quality meetings (Monthly, Weekly). Monthly weight: 40%weekly weight: 60% | E4: Weekly | F4: Monthly: 1Weekly: 3 (excluding the monthly meeting week)100% | G4: Green = 100% Amber = > 40% –60% Red = < 40% | H4: 0.05 | I4: 1 | J4: ='PMC Report- District level'!D58 -> NA
E5: Monthly | J5: ='PMC Report- District level'!D61 -> NA
A6: 2 | B6: Right First-Time | C6: M05 | D6: The rate of First-time approval of submissions (WIR, MIR) | E6: WIR | F6: 0.85 | G6: Green = > 85% Amber = 70 - 84% Red < 70% | H6: 0.15 | I6: 0.85 | J6: ='PMC Report- District level'!F26 -> NA
E7: MIR | J7: ='PMC Report- District level'!F22 -> NA
A8: 3 | B8: Submittals Approval | C8: M06 | D8: The rate of approval of submittals (MS, ITP, MAR, SDW, RFR). (Code A+B) | E8: MS | F8: 0.9 | G8: Green = > 90% Amber = 70 - 89% Red < 70% | H8: 0.05 | I8: 0.9 | J8: ='PMC Report- District level'!$G$10 -> 0
E9: ITP | J9: ='PMC Report- District level'!$G$11 -> 0
E10: MAR | J10: ='PMC Report- District level'!$G$12 -> 0
E11: SDW | J11: ='PMC Report- District level'!$G$14 -> 0
E12: RFR | J12: ='PMC Report- District level'!$G$13 -> 0
A13: 4 | B13: QMS Approval | C13: M07 | D13: The rate of QMS plans and procedures approved and revised as required (PEP, PQP, QA/QC Procedures). (Code A+B) | E13: PEP | F13: 0.9 | G13: Green = > 90% Amber = 70 - 89% Red < 70% | H13: 0.05 | I13: 0.9 | J13: ='PMC Report- District level'!$G$7 -> 0
E14: PQP | J14: ='PMC Report- District level'!$G$8 -> 0
E15: QA/QC Procedures | J15: ='PMC Report- District level'!$G$9 -> 0
A16: 5 | B16: Non-Conformance | C16: M09 | D16: The rate of closeout of NCRs. | E16: Closed% | F16: 0.9 | G16: Green = > 90% Amber = 70 - 89% Red < 70% | H16: 0.05 | I16: 0.9 | J16: ='PMC Report- District level'!$F$18 -> NA
D17: The Rate of NCRs Closed on time% | E17: Closed on time% | F17: 0.9 | G17: Green = > 90% Amber = 70 - 89% Red < 70% | H17: 0.1 | I17: 0.9 | J17: ='PMC Report- District level'!$G$18 -> NA
A18: 6 | B18: Inspection Performance | C18: M10 | D18: The rate of Approved WIRs (Code A+B) | E18: WIR Approved % | F18: 0.9 | G18: Green = > 90% Amber = 70 - 89% Red < 70% | H18: 0.05 | I18: 0.9 | J18: ='PMC Report- District level'!$E$26 -> NA
C19: M11 | D19: The rate of Approved MIRs (Code A+B). | E19: MIR Approved % | F19: 0.9 | G19: Green = > 90% Amber = 70 - 89% Red < 70% | H19: 0.05 | I19: 0.9 | J19: ='PMC Report- District level'!$E$22 -> NA
A20: 7 | B20: Defect Rate | C20: M12 | D20: The rate of raised NCRs to conducted WIRs. | E20: Defect Rate % | F20: =< 2% | G20: Green = < 2% Amber = 2.1 – 5% Red > 5% | H20: 0.2 | I20: 0.02 | J20: ='PMC Report- District level'!$I$18 -> NA
A21: 8 | B21: Audits | C21: M13 | D21: The rate of audits conducted as planned and reports are issued within the designated timeframe. | E21: (%) Conducted | F21: 0.9 | G21: Green = > 90% Amber = 70 - 89% Red < 70% | H21: 0.05 | I21: 0.9 | J21: ='PMC Report- District level'!$D$34 -> NA
C22: M14 | D22: The rate of timely close-out for audit findings (CARs) | E22: Closed % | F22: 0.9 | G22: Green = > 90% Amber = 70 - 89% Red < 70% | H22: 0.05 | I22: 0.9 | J22: ='PMC Report- District level'!$E$38 -> NA
A23: 9 | B23: Design / Engineering | C23: M15 | D23: The rate of Contractor-issued RFIs responded | E23: Responded % | F23: 0.9 | G23: Green = > 90% Amber = 70 - 89% Red < 70% | H23: 0.05 | I23: 0.9 | J23: ='PMC Report- District level'!$E$30 -> -
D24: The rate of Contractor-issued RFIs responded within the agreed time frame. | E24: Responded on Time % | F24: 0.9 | G24: Green = > 90% Amber = 70 - 89% Red < 70% | H24: 0.05 | I24: 0.9 | J24: ='PMC Report- District level'!$F$30 -> -
G25: Overall
G26: 80%-100% | H26: Satisfactory
G27: 60%-79% | H27: Fair
G28: Below 60% | H28: Poor

Sheet Consolidated Q. Register - 01 
A1: Programme/ Project Details | M1: QA/QC Procedures & Plans Submittals | AH1: Non - Conformance- NCRs | AR1: Inspection Performance | BH1: Request For Information (RFIs) | BP1: Status of Internal Audits & Audit Findings (CARs) | BZ1: Quality Issues & Mitigations | CC1: Lessons Learned | CF1: Quality Meetings & Site Walks | CP1: Remarks/Justifications
A2: S.N. | B2: Programme | C2: Sub- Programme | D2: District | E2: Project Name | F2: Project WBS unique Code | G2: CSC | H2: Contractor | I2: Project lifecycle Phase | J2: PEP | M2: PQP | P2: QA/QC Procedures (QMPs) | S2: Method Statements (MS) | V2: Inspection Test Plans ( ITPs) | Y2: Material Approval Request ( MARs) | AB2: Request For Replacement (RFR) | AE2: Shop- Drawings (SWD) | AH2: Non - Conformance- NCRs | AR2: Material Inspection Requests( MIRs) | AZ2: Work Inspection Requests( WIRs) | BH2: Request For Information (RFIs) | BP2: Status of Internal Audits | BU2: Status of Audit Findings | BZ2: Quality Issues & Mitigations | CC2: Lessons Learned | CF2: Quality Meetings | CK2: Quality Site Walks | CP2: Section 2: QMS and Submittals Status | CX2: Section 3: Non-Conformance Reports (NCRs) | CZ2: Section 4: Material Inspection Request (MIRs) | DB2: Section 5: Work Inspection Request (WIRs) | DD2: Section 6: Request For Information (RFIs) | DF2: Section 7: Status of Internal Audits | DH2: Section 8: Audit Findings - Corrective Actions (CARs)
J3: Total | K3: Approved ( A+B) | L3: Approved % | M3: Total | N3: Approved ( A+B) | O3: Approved % | P3: Total | Q3: Approved ( A+B) | R3: Approved % | S3: Total | T3: Approved ( A+B) | U3: Approved % | V3: Total | W3: Approved ( A+B) | X3: Approved % | Y3: Total | Z3: Approved ( A+B) | AA3: Approved % | AB3: Total | AC3: Approved ( A+B) | AD3: Approved % | AE3: Total | AF3: Approved ( A+B) | AG3: Approved % | AH3: This Month | AK3: To Date ( Cumulative) | AR3: This Month | AU3: To Date ( Cumulative) | AZ3: This Month | BC3: To Date ( Cumulative) | BH3: This Month | BK3: To Date ( Cumulative) | BP3: This Month | BR3: To Date ( Cumulative) | BU3: This Month | BW3: To Date ( Cumulative) | BZ3: To Date (Cumulative) | CC3: To Date (Cumulative) | CF3: This Month | CH3: To Date (Cumulative) | CK3: This Month | CM3: To Date ( Cumulative)
AH4: Total | AI4: Closed | AJ4: Closed On-Time | AK4: Total | AL4: Closed | AM4: Closed (%) | AN4: Closed On-time | AO4: Closed On-time (%) | AP4: Total WIRs | AQ4: Defect Rate % | AR4: Total | AS4: Approved | AT4: Approved 1st Time | AU4: Total | AV4: Approved | AW4: Approval (%) | AX4: Approved 1st Time | AY4: Approved 1st Time % | AZ4: Total | BA4: Approved | BB4: Approved 1st Time | BC4: Total | BD4: Approved | BE4: Approval (%) | BF4: Approved 1st Time | BG4: Approved 1st Time % | BH4: Total | BI4: Responded | BJ4: Responded On-time | BK4: Total | BL4: Responded | BM4: Responded (%) | BN4: Responded On-time | BO4: Responded On-time % | BP4: Total Planned | BQ4: Conducted | BR4: Total Planned | BS4: Conducted | BT4: Conducted (%) | BU4: Total | BV4: Closed | BW4: Total | BX4: Closed | BY4: Closed (%) | BZ4: Total Identified Issues | CA4: Total Mitigated Issues | CB4: Mitigated (%) | CC4: Total Documented LL | CD4: Total Deployed LL | CE4: Deployed (%) | CF4: Total Planned | CG4: Conducted | CH4: Total Planned | CI4: Conducted | CJ4: Conducted (%) | CK4: Total Planned | CL4: Conducted | CM4: Planned | CN4: Conducted | CO4: Conducted(%) | CP4: PEP | CQ4: PQP | CR4: QA/QC Procedures | CS4: MS | CT4: ITP | CU4: MAR | CV4: RFR | CW4: SDW | CX4: This month | CY4: Cumulative | CZ4: This month | DA4: Cumulative | DB4: This month | DC4: Cumulative | DD4: This month | DE4: Cumulative | DF4: This month | DG4: Cumulative | DH4: This month | DI4: Cumulative
A5: 1 | B5: DG2 - Diriyah II | C5: BV - Boulevard Community | D5: BSE - Boulevard South-East | E5: ='GRAND MOSQUE'!$B$3 -> Diriyah II Grand Mosque | F5: DD-DG2-BV-BSE-110 | G5: ='GRAND MOSQUE'!D4 -> X-ARCHITECTS | H5: ='GRAND MOSQUE'!F4 -> MAG-MAN JV | I5: Construction | J5: ='GRAND MOSQUE'!$B$7 -> 1 | K5: ='GRAND MOSQUE'!$C$7+'GRAND MOSQUE'!$D$7 -> 1 | L5: ='GRAND MOSQUE'!$G$7 -> 1 | M5: ='GRAND MOSQUE'!$B$8 -> 3 | N5: ='GRAND MOSQUE'!$C$8+'GRAND MOSQUE'!$D$8 -> 3 | O5: ='GRAND MOSQUE'!$G$8 -> 1 | P5: ='GRAND MOSQUE'!$B$9 -> 11 | Q5: ='GRAND MOSQUE'!$C$9+'GRAND MOSQUE'!$D$9 -> 11 | R5: ='GRAND MOSQUE'!$G$9 -> 1 | S5: ='GRAND MOSQUE'!$B$10 -> 71 | T5: ='GRAND MOSQUE'!$C$10+'GRAND MOSQUE'!$D$10 -> 59 | U5: ='GRAND MOSQUE'!$G$10 -> 0.83098592 | V5: ='GRAND MOSQUE'!$B$11 -> 55 | W5: ='GRAND MOSQUE'!$C$11+'GRAND MOSQUE'!$D$11 -> 54 | X5: ='GRAND MOSQUE'!$G$11 -> 0.98181818 | Y5: ='GRAND MOSQUE'!$B$12 -> 171 | Z5: ='GRAND MOSQUE'!$C$12+'GRAND MOSQUE'!$D$12 -> 121 | AA5: ='GRAND MOSQUE'!$G$12 -> 0.70760234 | AB5: ='GRAND MOSQUE'!$B$13 -> 0 | AC5: ='GRAND MOSQUE'!$C$13+'GRAND MOSQUE'!$D$13 -> 0 | AD5: ='GRAND MOSQUE'!$G$13 -> 0 | AE5: ='GRAND MOSQUE'!$B$14 -> 853 | AF5: ='GRAND MOSQUE'!$C$14+'GRAND MOSQUE'!$D$14 -> 613 | AG5: ='GRAND MOSQUE'!$G$14 -> 0.71864009 | AH5: ='GRAND MOSQUE'!$B$17 -> 13 | AI5: ='GRAND MOSQUE'!$D$17 -> 3 | AJ5: ='GRAND MOSQUE'!$E$17 -> 0 | AK5: ='GRAND MOSQUE'!$B$18 -> 34 | AL5: ='GRAND MOSQUE'!$D$18 -> 23 | AM5: ='GRAND MOSQUE'!$F$18 -> 0.67647059 | AN5: ='GRAND MOSQUE'!$E$18 -> 3 | AO5: ='GRAND MOSQUE'!$G$18 -> 0.13043478 | AP5: ='GRAND MOSQUE'!$B$26 -> 1171 | AQ5: ='GRAND MOSQUE'!$I$18 -> 0.029035013 | AR5: ='GRAND MOSQUE'!$B$21 -> 20 | AS5: ='GRAND MOSQUE'!$C$21 -> 12 | AT5: ='GRAND MOSQUE'!$D$21 -> 12 | AU5: ='GRAND MOSQUE'!$B$22 -> 114 | AV5: ='GRAND MOSQUE'!$C$22 -> 94 | AW5: ='GRAND MOSQUE'!$E$22 -> 0.8245614 | AX5: ='GRAND MOSQUE'!$D$22 -> 81 | AY5: ='GRAND MOSQUE'!$F$22 -> 0.86170213 | AZ5: ='GRAND MOSQUE'!$B$25 -> 258 | BA5: ='GRAND MOSQUE'!$C$25 -> 158 | BB5: ='GRAND MOSQUE'!$D$25 -> 139 | BC5: ='GRAND MOSQUE'!$B$26 -> 1171 | BD5: ='GRAND MOSQUE'!$C$26 -> 1007 | BE5: ='GRAND MOSQUE'!$E$26 -> 0.85994876 | BF5: ='GRAND MOSQUE'!$D$26 -> 910 | BG5: ='GRAND MOSQUE'!$F$26 -> 0.90367428 | BH5: ='GRAND MOSQUE'!$B$29 -> 13 | BI5: ='GRAND MOSQUE'!$C$29 -> 4 | BJ5: ='GRAND MOSQUE'!$D$29 -> 4 | BK5: ='GRAND MOSQUE'!$B$30 -> 161 | BL5: ='GRAND MOSQUE'!$C$30 -> 140 | BM5: ='GRAND MOSQUE'!$E$30 -> 0.86956522 | BN5: ='GRAND MOSQUE'!$D$30 -> 140 | BO5: ='GRAND MOSQUE'!$F$30 -> 1 | BP5: ='GRAND MOSQUE'!$B$33 -> 0 | BQ5: ='GRAND MOSQUE'!$C$33 -> 0 | BR5: ='GRAND MOSQUE'!$B$34 -> 6 | BS5: ='GRAND MOSQUE'!$C$34 -> 1 | BT5: ='GRAND MOSQUE'!$D$34 -> 0.16666667 | BU5: ='GRAND MOSQUE'!$B$37 -> 0 | BV5: ='GRAND MOSQUE'!$D$37 -> 0 | BW5: ='GRAND MOSQUE'!$B$38 -> 0 | BX5: ='GRAND MOSQUE'!$D$38 -> 0 | BY5: ='GRAND MOSQUE'!$E$38 -> NA | BZ5: ='GRAND MOSQUE'!$B$46 -> 17 | CA5: ='GRAND MOSQUE'!$C$46 -> 17 | CB5: ='GRAND MOSQUE'!$D$46 -> 0 | CC5: ='GRAND MOSQUE'!$B$54 -> 12 | CD5: ='GRAND MOSQUE'!$D$54 -> 11 | CE5: ='GRAND MOSQUE'!$D$54 -> 11 | CF5: ='GRAND MOSQUE'!$B$57+'GRAND MOSQUE'!$B$60 -> 4 | CG5: ='GRAND MOSQUE'!$C$57+'GRAND MOSQUE'!$C$60 -> 4 | CH5: ='GRAND MOSQUE'!$B$62 -> 38 | CI5: ='GRAND MOSQUE'!$C$62 -> 38 | CJ5: ='GRAND MOSQUE'!$D$62 -> 1 | CK5: ='GRAND MOSQUE'!$B$65+'GRAND MOSQUE'!$B$68 -> 4 | CL5: ='GRAND MOSQUE'!$C$65+'GRAND MOSQUE'!$C$68 -> 4 | CM5: ='GRAND MOSQUE'!$B$70 -> 27 | CN5: ='GRAND MOSQUE'!$C$70 -> 27 | CO5: ='GRAND MOSQUE'!$D$70 -> 1 | CP5: ='GRAND MOSQUE'!$H$7 -> 0 | CQ5: ='GRAND MOSQUE'!$H$8 -> 0 | CR5: ='GRAND MOSQUE'!$H$9 -> 0 | CS5: ='GRAND MOSQUE'!$H$10 -> 0 | CT5: ='GRAND MOSQUE'!$H$11 -> 0 | CU5: ='GRAND MOSQUE'!$H$12 -> 0 | CV5: ='GRAND MOSQUE'!$H$13 -> 0 | CW5: ='GRAND MOSQUE'!$H$14 -> 0 | CX5: ='GRAND MOSQUE'!$K$17 -> 0 | CY5: ='GRAND MOSQUE'!$K$18 -> 0 | CZ5: ='GRAND MOSQUE'!$G$21 -> 0 | DA5: ='GRAND MOSQUE'!$G$22 -> 0 | DB5: ='GRAND MOSQUE'!$G$25 -> 0 | DC5: ='GRAND MOSQUE'!$G$26 -> 0 | DD5: ='GRAND MOSQUE'!$H$29 -> 0 | DE5: ='GRAND MOSQUE'!$H$30 -> 0 | DF5: ='GRAND MOSQUE'!$E$33 -> 0 | DG5: ='GRAND MOSQUE'!$E$34 -> 0 | DH5: ='GRAND MOSQUE'!$F$37 -> 0 | DI5: ='GRAND MOSQUE'!$F$38 -> 0
A6: 2 | B6: DG2 - Diriyah II | C6: BV - Boulevard Community | D6: BSW - Boulevard South-West | E6: ='OPERA HOUSE '!$B$3 -> Royal Diriyah Opera House | F6: DD-DG2-BV-BSW-105 | G6: ='OPERA HOUSE '!D4 -> Snohetta/ Saudi Diyar | H6: ='OPERA HOUSE '!F4 -> ECM JV | I6: Construction | J6: ='OPERA HOUSE '!$B$7 -> 1 | K6: ='OPERA HOUSE '!$C$7+'OPERA HOUSE '!$D$7 -> 1 | L6: ='OPERA HOUSE '!$G$7 -> 1 | M6: ='OPERA HOUSE '!$B$8 -> 1 | N6: ='OPERA HOUSE '!$C$8+'OPERA HOUSE '!$D$8 -> 1 | O6: ='OPERA HOUSE '!$G$8 -> 1 | P6: ='OPERA HOUSE '!$B$9 -> 11 | Q6: ='OPERA HOUSE '!$C$9+'OPERA HOUSE '!$D$9 -> 11 | R6: ='OPERA HOUSE '!$G$9 -> 1 | S6: ='OPERA HOUSE '!$B$10 -> 78 | T6: ='OPERA HOUSE '!$C$10+'OPERA HOUSE '!$D$10 -> 60 | U6: ='OPERA HOUSE '!$G$10 -> 0.76923077 | V6: ='OPERA HOUSE '!$B$11 -> 47 | W6: ='OPERA HOUSE '!$C$11+'OPERA HOUSE '!$D$11 -> 36 | X6: ='OPERA HOUSE '!$G$11 -> 0.76595745 | Y6: ='OPERA HOUSE '!$B$12 -> 264 | Z6: ='OPERA HOUSE '!$C$12+'OPERA HOUSE '!$D$12 -> 163 | AA6: ='OPERA HOUSE '!$G$12 -> 0.61742424 | AB6: ='OPERA HOUSE '!$B$13 -> 0 | AC6: ='OPERA HOUSE '!$C$13+'OPERA HOUSE '!$D$13 -> 0 | AD6: ='OPERA HOUSE '!$G$13 -> 0 | AE6: ='OPERA HOUSE '!$B$14 -> 7990 | AF6: ='OPERA HOUSE '!$C$14+'OPERA HOUSE '!$D$14 -> 6538 | AG6: ='OPERA HOUSE '!$G$14 -> 0.81827284 | AH6: ='OPERA HOUSE '!$B$17 -> 10 | AI6: ='OPERA HOUSE '!$D$17 -> 1 | AJ6: ='OPERA HOUSE '!$E$17 -> 0 | AK6: ='OPERA HOUSE '!$B$18 -> 41 | AL6: ='OPERA HOUSE '!$D$18 -> 21 | AM6: ='OPERA HOUSE '!$F$18 -> 0.51219512 | AN6: ='OPERA HOUSE '!$E$18 -> 18 | AO6: ='OPERA HOUSE '!$G$18 -> 0.5625 | AP6: ='OPERA HOUSE '!$B$26 -> 6315 | AQ6: ='OPERA HOUSE '!$I$18 -> 0.0064924782 | AR6: ='OPERA HOUSE '!$B$21 -> 66 | AS6: ='OPERA HOUSE '!$C$21 -> 54 | AT6: ='OPERA HOUSE '!$D$21 -> 50 | AU6: ='OPERA HOUSE '!$B$22 -> 385 | AV6: ='OPERA HOUSE '!$C$22 -> 365 | AW6: ='OPERA HOUSE '!$E$22 -> 0.94805195 | AX6: ='OPERA HOUSE '!$D$22 -> 315 | AY6: ='OPERA HOUSE '!$F$22 -> 0.8630137 | AZ6: ='OPERA HOUSE '!$B$25 -> 701 | BA6: ='OPERA HOUSE '!$C$25 -> 605 | BB6: ='OPERA HOUSE '!$D$25 -> 550 | BC6: ='OPERA HOUSE '!$B$26 -> 6315 | BD6: ='OPERA HOUSE '!$C$26 -> 6051 | BE6: ='OPERA HOUSE '!$E$26 -> 0.95819477 | BF6: ='OPERA HOUSE '!$D$26 -> 5218 | BG6: ='OPERA HOUSE '!$F$26 -> 0.8623368 | BH6: ='OPERA HOUSE '!$B$29 -> 119 | BI6: ='OPERA HOUSE '!$C$29 -> 93 | BJ6: ='OPERA HOUSE '!$D$29 -> 66 | BK6: ='OPERA HOUSE '!$B$30 -> 1320 | BL6: ='OPERA HOUSE '!$C$30 -> 1294 | BM6: ='OPERA HOUSE '!$E$30 -> 0.98030303 | BN6: ='OPERA HOUSE '!$D$30 -> 882 | BO6: ='OPERA HOUSE '!$F$30 -> 0.68108108 | BP6: ='OPERA HOUSE '!$B$33 -> 1 | BQ6: ='OPERA HOUSE '!$C$33 -> 1 | BR6: ='OPERA HOUSE '!$B$34 -> 1 | BS6: ='OPERA HOUSE '!$C$34 -> 1 | BT6: ='OPERA HOUSE '!$D$34 -> 1 | BU6: ='OPERA HOUSE '!$B$37 -> 0 | BV6: ='OPERA HOUSE '!$D$37 -> 0 | BW6: ='OPERA HOUSE '!$B$38 -> 0 | BX6: ='OPERA HOUSE '!$D$38 -> 0 | BY6: ='OPERA HOUSE '!$E$38 -> NA | BZ6: ='OPERA HOUSE '!$B$46 -> 3 | CA6: ='OPERA HOUSE '!$C$46 -> 3 | CB6: ='OPERA HOUSE '!$D$46 -> 1 | CC6: ='OPERA HOUSE '!$B$54 -> 2 | CD6: ='OPERA HOUSE '!$D$54 -> 100 | CE6: ='OPERA HOUSE '!$D$54 -> 100 | CF6: ='OPERA HOUSE '!$B$57+'OPERA HOUSE '!$B$60 -> 5 | CG6: ='OPERA HOUSE '!$C$57+'OPERA HOUSE '!$C$60 -> 5 | CH6: ='OPERA HOUSE '!$B$62 -> 49 | CI6: ='OPERA HOUSE '!$C$62 -> 49 | CJ6: ='OPERA HOUSE '!$D$62 -> 1 | CK6: ='OPERA HOUSE '!$B$65+'OPERA HOUSE '!$B$68 -> 5 | CL6: ='OPERA HOUSE '!$C$65+'OPERA HOUSE '!$C$68 -> 5 | CM6: ='OPERA HOUSE '!$B$70 -> 49 | CN6: ='OPERA HOUSE '!$C$70 -> 49 | CO6: ='OPERA HOUSE '!$D$70 -> 1 | CP6: ='OPERA HOUSE '!$H$7 -> 0 | CQ6: ='OPERA HOUSE '!$H$8 -> 0 | CR6: ='OPERA HOUSE '!$H$9 -> 0 | CS6: ='OPERA HOUSE '!$H$10 -> The Process/ procedure's of Installation are either Incompete / Inaccurate | CT6: ='OPERA HOUSE '!$H$11 -> The Inspection Hold points requires update | CU6: ='OPERA HOUSE '!$H$12 -> The MAR's submitted by Sub-Contractors are not Reviewed | CV6: ='OPERA HOUSE '!$H$13 -> 0 | CW6: ='OPERA HOUSE '!$H$14 -> The Shop Drawings require detailed review by ECM Teams | CX6: ='OPERA HOUSE '!$K$17 -> 0 | CY6: ='OPERA HOUSE '!$K$18 -> Delayed CAPA & Correction by ECM JV | CZ6: ='OPERA HOUSE '!$G$21 -> 0 | DA6: ='OPERA HOUSE '!$G$22 -> 0 | DB6: ='OPERA HOUSE '!$G$25 -> 0 | DC6: ='OPERA HOUSE '!$G$26 -> 0 | DD6: ='OPERA HOUSE '!$H$29 -> 0 | DE6: ='OPERA HOUSE '!$H$30 -> 0 | DF6: ='OPERA HOUSE '!$E$33 -> Pending Audit Findings | DG6: ='OPERA HOUSE '!$E$34 -> 0 | DH6: ='OPERA HOUSE '!$F$37 -> 0 | DI6: ='OPERA HOUSE '!$F$38 -> 0
A7: 3 | B7: DG2 - Diriyah II | C7: BV - Boulevard Community | D7: BSW - Boulevard South-West | E7: =#REF! -> #REF! | F7: DD-DG2-BV-BSW-106 | G7: =#REF! -> #REF! | H7: =#REF! -> #REF! | I7: Construction | J7: =#REF! -> #REF! | K7: =#REF!+#REF! -> #REF! | L7: =#REF! -> #REF! | M7: =#REF! -> #REF! | N7: =#REF!+#REF! -> #REF! | O7: =#REF! -> #REF! | P7: =#REF! -> #REF! | Q7: =#REF!+#REF! -> #REF! | R7: =#REF! -> #REF! | S7: =#REF! -> #REF! | T7: =#REF!+#REF! -> #REF! | U7: =#REF! -> #REF! | V7: =#REF! -> #REF! | W7: =#REF!+#REF! -> #REF! | X7: =#REF! -> #REF! | Y7: =#REF! -> #REF! | Z7: =#REF!+#REF! -> #REF! | AA7: =#REF! -> #REF! | AB7: =#REF! -> #REF! | AC7: =#REF!+#REF! -> #REF! | AD7: =#REF! -> #REF! | AE7: =#REF! -> #REF! | AF7: =#REF!+#REF! -> #REF! | AG7: =#REF! -> #REF! | AH7: =#REF! -> #REF! | AI7: =#REF! -> #REF! | AJ7: =#REF! -> #REF! | AK7: =#REF! -> #REF! | AL7: =#REF! -> #REF! | AM7: =#REF! -> #REF! | AN7: =#REF! -> #REF! | ... CE7: =#REF! -> #REF! | CF7: =#REF!+#REF! -> #REF! | CG7: =#REF!+#REF! -> #REF! | CH7: =#REF! -> #REF! | CI7: =#REF! -> #REF! | CJ7: =#REF! -> #REF! | CK7: =#REF!+#REF! -> #REF! | CL7: =#REF!+#REF! -> #REF! | CM7: =#REF! -> #REF! | CN7: =#REF! -> #REF! | CO7: =#REF! -> #REF! | CP7: =#REF! -> #REF! | CQ7: =#REF! -> #REF! | CR7: =#REF! -> #REF! | CS7: =#REF! -> #REF! | CT7: =#REF! -> #REF! | ... DI7: =#REF! -> #REF!
A8: 4 | B8: DG2 - Diriyah II | C8: BV - Boulevard Community | D8: BNW - Boulevard North-West | E8: ='Waldorf Astoria Hotel & Branded'!$B$3 -> Waldorf Astoria Hotel & Branded Residences | F8: DD-DG2-BV-BNW-108 | G8: ='Waldorf Astoria Hotel & Branded'!D4 -> 0 | H8: ='Waldorf Astoria Hotel & Branded'!F4 -> 0 | I8: Construction | J8: ='Waldorf Astoria Hotel & Branded'!$B$7 -> 0 | K8: ='Waldorf Astoria Hotel & Branded'!$C$7+'Waldorf Astoria Hotel & Branded'!$D$7 -> 0 | L8: ='Waldorf Astoria Hotel & Branded'!$G$7 -> 0 | M8: ='Waldorf Astoria Hotel & Branded'!$B$8 -> 0 | N8: ='Waldorf Astoria Hotel & Branded'!$C$8+'Waldorf Astoria Hotel & Branded'!$D$8 -> 0 | O8: ='Waldorf Astoria Hotel & Branded'!$G$8 -> 0 | P8: ='Waldorf Astoria Hotel & Branded'!$B$9 -> 0 | Q8: ='Waldorf Astoria Hotel & Branded'!$C$9+'Waldorf Astoria Hotel & Branded'!$D$9 -> 0 | R8: ='Waldorf Astoria Hotel & Branded'!$G$9 -> 0 | S8: ='Waldorf Astoria Hotel & Branded'!$B$10 -> 0 | T8: ='Waldorf Astoria Hotel & Branded'!$C$10+'Waldorf Astoria Hotel & Branded'!$D$10 -> 0 | U8: ='Waldorf Astoria Hotel & Branded'!$G$10 -> 0 | V8: ='Waldorf Astoria Hotel & Branded'!$B$11 -> 0 | W8: ='Waldorf Astoria Hotel & Branded'!$C$11+'Waldorf Astoria Hotel & Branded'!$D$11 -> 0 | X8: ='Waldorf Astoria Hotel & Branded'!$G$11 -> 0 | Y8: ='Waldorf Astoria Hotel & Branded'!$B$12 -> 0 | Z8: ='Waldorf Astoria Hotel & Branded'!$C$12+'Waldorf Astoria Hotel & Branded'!$D$12 -> 0 | AA8: ='Waldorf Astoria Hotel & Branded'!$G$12 -> 0 | AB8: ='Waldorf Astoria Hotel & Branded'!$B$13 -> 0 | AC8: ='Waldorf Astoria Hotel & Branded'!$C$13+'Waldorf Astoria Hotel & Branded'!$D$13 -> 0 | AD8: ='Waldorf Astoria Hotel & Branded'!$G$13 -> 0 | AE8: ='Waldorf Astoria Hotel & Branded'!$B$14 -> 0 | AF8: ='Waldorf Astoria Hotel & Branded'!$C$14+'Waldorf Astoria Hotel & Branded'!$D$14 -> 0 | AG8: ='Waldorf Astoria Hotel & Branded'!$G$14 -> 0 | AH8: ='Waldorf Astoria Hotel & Branded'!$B$17 -> 0 | AI8: ='Waldorf Astoria Hotel & Branded'!$D$17 -> 0 | AJ8: ='Waldorf Astoria Hotel & Branded'!$E$17 -> 0 | AK8: ='Waldorf Astoria Hotel & Branded'!$B$18 -> 0 | AL8: ='Waldorf Astoria Hotel & Branded'!$D$18 -> 0 | AM8: ='Waldorf Astoria Hotel & Branded'!$F$18 -> NA | AN8: ='Waldorf Astoria Hotel & Branded'!$E$18 -> 0 | AO8: ='Waldorf Astoria Hotel & Branded'!$G$18 -> NA | AP8: ='Waldorf Astoria Hotel & Branded'!$B$26 -> 0 | AQ8: ='Waldorf Astoria Hotel & Branded'!$I$18 -> NA | AR8: ='Waldorf Astoria Hotel & Branded'!$B$21 -> 0 | AS8: ='Waldorf Astoria Hotel & Branded'!$C$21 -> 0 | AT8: ='Waldorf Astoria Hotel & Branded'!$D$21 -> 0 | AU8: ='Waldorf Astoria Hotel & Branded'!$B$22 -> 0 | AV8: ='Waldorf Astoria Hotel & Branded'!$C$22 -> 0 | AW8: ='Waldorf Astoria Hotel & Branded'!$E$22 -> NA | AX8: ='Waldorf Astoria Hotel & Branded'!$D$22 -> 0 | AY8: ='Waldorf Astoria Hotel & Branded'!$F$22 -> NA | AZ8: ='Waldorf Astoria Hotel & Branded'!$B$25 -> 0 | BA8: ='Waldorf Astoria Hotel & Branded'!$C$25 -> 0 | BB8: ='Waldorf Astoria Hotel & Branded'!$D$25 -> 0 | BC8: ='Waldorf Astoria Hotel & Branded'!$B$26 -> 0 | BD8: ='Waldorf Astoria Hotel & Branded'!$C$26 -> 0 | BE8: ='Waldorf Astoria Hotel & Branded'!$E$26 -> NA | BF8: ='Waldorf Astoria Hotel & Branded'!$D$26 -> 0 | BG8: ='Waldorf Astoria Hotel & Branded'!$F$26 -> NA | BH8: ='Waldorf Astoria Hotel & Branded'!$B$29 -> 0 | BI8: ='Waldorf Astoria Hotel & Branded'!$C$29 -> 0 | BJ8: ='Waldorf Astoria Hotel & Branded'!$D$29 -> 0 | BK8: ='Waldorf Astoria Hotel & Branded'!$B$30 -> 0 | BL8: ='Waldorf Astoria Hotel & Branded'!$C$30 -> 0 | BM8: ='Waldorf Astoria Hotel & Branded'!$E$30 -> - | BN8: ='Waldorf Astoria Hotel & Branded'!$D$30 -> 0 | BO8: ='Waldorf Astoria Hotel & Branded'!$F$30 -> - | BP8: ='Waldorf Astoria Hotel & Branded'!$B$33 -> 0 | BQ8: ='Waldorf Astoria Hotel & Branded'!$C$33 -> 0 | BR8: ='Waldorf Astoria Hotel & Branded'!$B$34 -> 0 | BS8: ='Waldorf Astoria Hotel & Branded'!$C$34 -> 0 | BT8: ='Waldorf Astoria Hotel & Branded'!$D$34 -> NA | BU8: ='Waldorf Astoria Hotel & Branded'!$B$37 -> 0 | BV8: ='Waldorf Astoria Hotel & Branded'!$D$37 -> 0 | BW8: ='Waldorf Astoria Hotel & Branded'!$B$38 -> 0 | BX8: ='Waldorf Astoria Hotel & Branded'!$D$38 -> 0 | BY8: ='Waldorf Astoria Hotel & Branded'!$E$38 -> NA | BZ8: ='Waldorf Astoria Hotel & Branded'!$B$46 -> 0 | CA8: ='Waldorf Astoria Hotel & Branded'!$C$46 -> 0 | CB8: ='Waldorf Astoria Hotel & Branded'!$D$46 -> 0 | CC8: ='Waldorf Astoria Hotel & Branded'!$B$54 -> 0 | CD8: ='Waldorf Astoria Hotel & Branded'!$D$54 -> 0 | CE8: ='Waldorf Astoria Hotel & Branded'!$D$54 -> 0 | CF8: ='Waldorf Astoria Hotel & Branded'!$B$57+'Waldorf Astoria Hotel & Branded'!$B$60 -> 0 | CG8: ='Waldorf Astoria Hotel & Branded'!$C$57+'Waldorf Astoria Hotel & Branded'!$C$60 -> 0 | CH8: ='Waldorf Astoria Hotel & Branded'!$B$62 -> 0 | CI8: ='Waldorf Astoria Hotel & Branded'!$C$62 -> 0 | CJ8: ='Waldorf Astoria Hotel & Branded'!$D$62 -> NA | CK8: ='Waldorf Astoria Hotel & Branded'!$B$65+'Waldorf Astoria Hotel & Branded'!$B$68 -> 0 | CL8: ='Waldorf Astoria Hotel & Branded'!$C$65+'Waldorf Astoria Hotel & Branded'!$C$68 -> 0 | CM8: ='Waldorf Astoria Hotel & Branded'!$B$70 -> 0 | CN8: ='Waldorf Astoria Hotel & Branded'!$C$70 -> 0 | CO8: ='Waldorf Astoria Hotel & Branded'!$D$70 -> NA | CP8: ='Waldorf Astoria Hotel & Branded'!$H$7 -> 0 | CQ8: ='Waldorf Astoria Hotel & Branded'!$H$8 -> 0 | CR8: ='Waldorf Astoria Hotel & Branded'!$H$9 -> 0 | CS8: ='Waldorf Astoria Hotel & Branded'!$H$10 -> 0 | CT8: ='Waldorf Astoria Hotel & Branded'!$H$11 -> 0 | CU8: ='Waldorf Astoria Hotel & Branded'!$H$12 -> 0 | CV8: ='Waldorf Astoria Hotel & Branded'!$H$13 -> 0 | CW8: ='Waldorf Astoria Hotel & Branded'!$H$14 -> 0 | CX8: ='Waldorf Astoria Hotel & Branded'!$K$17 -> 0 | CY8: ='Waldorf Astoria Hotel & Branded'!$K$18 -> 0 | CZ8: ='Waldorf Astoria Hotel & Branded'!$G$21 -> 0 | DA8: ='Waldorf Astoria Hotel & Branded'!$G$22 -> 0 | DB8: ='Waldorf Astoria Hotel & Branded'!$G$25 -> 0 | DC8: ='Waldorf Astoria Hotel & Branded'!$G$26 -> 0 | DD8: ='Waldorf Astoria Hotel & Branded'!$H$29 -> 0 | DE8: ='Waldorf Astoria Hotel & Branded'!$H$30 -> 0 | DF8: ='Waldorf Astoria Hotel & Branded'!$E$33 -> 0 | DG8: ='Waldorf Astoria Hotel & Branded'!$E$34 -> 0 | DH8: ='Waldorf Astoria Hotel & Branded'!$F$37 -> 0 | DI8: ='Waldorf Astoria Hotel & Branded'!$F$38 -> 0

Sheet Consolidated Q. Register - 01
