Workbook

Sheet Cast In Situ Tracker
A1: Diriyah II Management Contracting – Opera Block DD-2023-329
A3: Concrete Tracker
X4: Batching Plant | AB4: Fresh Concrete Test (at Checkpoint) | AM4: Compressive Strength 3 days | AX4: Compressive Strength 7 days | BI4: Compressive Strength 14 days | BT4: Compressive Strength 28 days | CF4: Opening Time of Formwork
X5: Departure Time | Y5: Temperature (Each mixer) C | Z5: Flow Each Mixer (each mixer) (mm) | AB5: Report Number | AC5: Temperature (Each mixer) C | AD5: Flow/ Slump Each Mixer (each mixer) (mm) | AE5: Air Content Test % | AF5: Density Test kg/m3 | AG5: Setting Time Of Concrete | AI5: Report Number | AJ5: Setting Time of Concrete | AM5: Crush Date for 4 Days CS. | AN5: WIR No. For 4 Days CS. | AO5: Report Number | AP5: CYLINDERS | AX5: Crush Date for 7 Days CS. | AY5: WIR No. For 7 Days CS. | AZ5: Report Number | BA5: CYLINDERS | BI5: Crush Date for 7 Days CS. | BJ5: WIR No. For 7 Days CS. | BK5: Report Number | BL5: CYLINDERS | BT5: Crush Date for 28 Days CS. | BU5: WIR No. For 28 Days CS. | BV5: Report Number | BW5: CYLINDERS | CE5: Draft Report | CF5: Duration | CK5: Result (MPa)
A6: S.No. | B6: CAP No. | C6: WIR No. | D6: Element and Inspection Description | E6: Grids/ Locations | F6: Building Area | G6: Zone | H6: Basement/Floor | I6: Permanent Works / Temporary Works | J6: Truck Number | K6: Ticket Number | L6: Date of Casting | M6: Third Party | N6: Concrete Suppiler | O6: Concrete Name | P6: Area | Q6: Concrete Quantity (m3) | R6: Batch Plant No. | S6: Sample Taken | T6: Casting Type | U6: REJECTED DUE TO JV ISSUE (m3) | V6: REMARKS | AJ6: Initial Setting Time (500 psi) | AK6: Final Setting Time (4000 psi) | AP6: 3 Days | AV6: 4 Day Avarage | BA6: 7 Days | BG6: 7 Day Avarage | BL6: 7 Days | BR6: 7 Day Avarage | BW6: 28 Days | CC6: 28 Days Avarage
A7: 1 | B7: - | C7: BV-BSW-105-0000-ECM-WIR-CE-000003 | D7: Blinding Concrete | E7: Mess Hall 2 | F7: Opera House | I7: Temporary Works | J7: 84712 | K7: 93617 | L7: 45855 | M7: Aces | N7: Saudi RM | O7: C-10 SRC (150±40mm Slump) | P7: Blinding | Q7: 10 | R7: RM 109 | T7: Temporary | AB7: RH.MCR25006530 | AC7: 24 | AD7: 180 | AE7: - | AF7: - | AM7: =L7+3 -> 45858 | AX7: =IF(L7=0, 0,L7+7) -> 45862 | BT7: =IF(L7=0, 0, L7+28) -> 45883
A8: 2 | B8: - | C8: BV-BSW-105-0000-ECM-WIR-CE-000003 | D8: Blinding Concrete | E8: Mess Hall 2 | F8: Opera House | I8: Temporary Works | J8: 82512 | K8: 93619 | L8: 45855 | M8: Aces | N8: Saudi RM | O8: C-10 SRC (150±40mm Slump) | P8: Blinding | Q8: 10 | R8: RM 109 | T8: Temporary | AC8: 23 | AD8: 190 | AE8: - | AF8: - | AM8: =L8+3 -> 45858 | AX8: =IF(L8=0, 0,L8+7) -> 45862 | BT8: =IF(L8=0, 0, L8+28) -> 45883
A9: 3 | B9: - | C9: BV-BSW-105-0000-ECM-WIR-CE-000003 | D9: Blinding Concrete | E9: Mess Hall 2 | F9: Opera House | I9: Temporary Works | J9: 84712 | K9: 93620 | L9: 45855 | M9: Aces | N9: Saudi RM | O9: C-10 SRC (150±40mm Slump) | P9: Blinding | Q9: 10 | R9: RM 109 | T9: Temporary | AC9: 25 | AD9: 170 | AE9: - | AF9: - | AM9: =L9+3 -> 45858 | AX9: =IF(L9=0, 0,L9+7) -> 45862 | BT9: =IF(L9=0, 0, L9+28) -> 45883
A10: 4 | B10: - | C10: BV-BSW-105-0000-ECM-WIR-CE-000003 | D10: Blinding Concrete | E10: Mess Hall 2 | F10: Opera House | I10: Temporary Works | J10: 82312 | K10: 93621 | L10: 45855 | M10: Aces | N10: Saudi RM | O10: C-10 SRC (150±40mm Slump) | P10: Blinding | Q10: 10 | R10: RM 109 | T10: Temporary | AC10: 25 | AD10: 180 | AE10: - | AF10: - | AM10: =L10+3 -> 45858 | AX10: =IF(L10=0, 0,L10+7) -> 45862 | BT10: =IF(L10=0, 0, L10+28) -> 45883
A11: 5 | B11: - | C11: BV-BSW-105-0000-ECM-WIR-CE-000003 | D11: Blinding Concrete | E11: Mess Hall 2 | F11: Opera House | I11: Temporary Works | J11: 77112 | K11: 93623 | L11: 45855 | M11: Aces | N11: Saudi RM | O11: C-10 SRC (150±40mm Slump) | P11: Blinding | Q11: 10 | R11: RM 109 | S11: 6 | T11: Temporary | AC11: 24 | AD11: 180 | AE11: - | AF11: - | AM11: =L11+3 -> 45858 | AX11: =IF(L11=0, 0,L11+7) -> 45862 | BT11: =IF(L11=0, 0, L11+28) -> 45883
A12: 6 | B12: - | C12: BV-BSW-105-0000-ECM-WIR-CE-000003 | D12: Blinding Concrete | E12: Mess Hall 2 | F12: Opera House | I12: Temporary Works | J12: 83812 | K12: 93624 | L12: 45855 | M12: Aces | N12: Saudi RM | O12: C-10 SRC (150±40mm Slump) | P12: Blinding | Q12: 5 | R12: RM 109 | T12: Temporary | AC12: 25 | AD12: 180 | AE12: - | AF12: - | AM12: =L12+3 -> 45858 | AX12: =IF(L12=0, 0,L12+7) -> 45862 | BT12: =IF(L12=0, 0, L12+28) -> 45883
A13: 7 | B13: - | C13: BV-BSW-105-0000-ECM-WIR-CE-000004 | D13: Blinding Concrete | E13: Mess Hall 2 | F13: Opera House | I13: Temporary Works | J13: 82812 | K13: 84660 | L13: 45858 | M13: Aces | N13: Saudi RM | O13: C-10 SRC (150±40mm Slump) | P13: Blinding | Q13: 10 | R13: RM 109 | S13: 2 | T13: Temporary | AB13: RH.MCR25008597 | AC13: 29.5 | AD13: 160 | AE13: - | AF13: - | AM13: =L13+3 -> 45861 | AX13: =IF(L13=0, 0,L13+7) -> 45865 | AY13: WIR-CE-000004 | AZ13: RH.MCR25008597@7 | BA13: 13.1 | BB13: 13.9 | BC13: 15.1 | BG13: =AVERAGE(BA13:BC17) -> 14.033333 | BT13: =IF(L13=0, 0, L13+28) -> 45886 | BU13: WIR-CE-000004 | BV13: RH.MCR25008597@28 | BW13: 29.8 | BX13: 29.7 | BY13: 38.9 | CC13: =AVERAGE(BW13:BY17) -> 32.8
A14: 8 | B14: - | C14: BV-BSW-105-0000-ECM-WIR-CE-000004 | D14: Blinding Concrete | E14: Mess Hall 2 | F14: Opera House | I14: Temporary Works | J14: 83012 | K14: 84659 | L14: 45858 | M14: Aces | N14: Saudi RM | O14: C-10 SRC (150±40mm Slump) | P14: Blinding | Q14: 11 | R14: RM 109 | S14: 2 | T14: Temporary | AC14: 29.6 | AD14: 135 | AE14: - | AF14: - | AM14: =L14+3 -> 45861 | AX14: =IF(L14=0, 0,L14+7) -> 45865 | AY14: WIR-CE-000004 | BT14: =IF(L14=0, 0, L14+28) -> 45886 | BU14: WIR-CE-000004
A15: 9 | B15: - | C15: BV-BSW-105-0000-ECM-WIR-CE-000004 | D15: Blinding Concrete | E15: Mess Hall 2 | F15: Opera House | I15: Temporary Works | J15: 82612 | K15: 84661 | L15: 45858 | M15: Aces | N15: Saudi RM | O15: C-10 SRC (150±40mm Slump) | P15: Blinding | Q15: 11 | R15: RM 109 | T15: Temporary | AC15: 28.5 | AD15: 140 | AE15: - | AF15: - | AM15: =L15+3 -> 45861 | AX15: =IF(L15=0, 0,L15+7) -> 45865 | AY15: WIR-CE-000004 | BT15: =IF(L15=0, 0, L15+28) -> 45886 | BU15: WIR-CE-000004
A16: 10 | B16: - | C16: BV-BSW-105-0000-ECM-WIR-CE-000004 | D16: Blinding Concrete | E16: Mess Hall 2 | F16: Opera House | I16: Temporary Works | J16: 83412 | K16: 84662 | L16: 45858 | M16: Aces | N16: Saudi RM | O16: C-10 SRC (150±40mm Slump) | P16: Blinding | Q16: 11 | R16: RM 109 | S16: 2 | T16: Temporary | AC16: 29.2 | AD16: 130 | AE16: - | AF16: - | AM16: =L16+3 -> 45861 | AX16: =IF(L16=0, 0,L16+7) -> 45865 | AY16: WIR-CE-000004 | BT16: =IF(L16=0, 0, L16+28) -> 45886 | BU16: WIR-CE-000004
A17: 11 | B17: - | C17: BV-BSW-105-0000-ECM-WIR-CE-000004 | D17: Blinding Concrete | E17: Mess Hall 2 | F17: Opera House | I17: Temporary Works | J17: 84812 | K17: 84663 | L17: 45858 | M17: Aces | N17: Saudi RM | O17: C-10 SRC (150±40mm Slump) | P17: Blinding | Q17: 11 | R17: RM 109 | T17: Temporary | AC17: 28 | AD17: 160 | AE17: - | AF17: - | AM17: =L17+3 -> 45861 | AX17: =IF(L17=0, 0,L17+7) -> 45865 | AY17: WIR-CE-000004 | BT17: =IF(L17=0, 0, L17+28) -> 45886 | BU17: WIR-CE-000004
A18: 12 | B18: - | C18: N/A | D18: Concrete Blocks | E18: Offices Foundation | F18: Opera House | I18: Temporary Works | J18: 83812 | K18: 84434 | L18: 45861 | M18: Aces | N18: Saudi RM | O18: C-40 OPC {200±40mm Slump) | P18: Blinding | Q18: 5 | R18: RM 109 | T18: Temporary | AC18: - | AD18: - | AE18: - | AF18: - | AM18: =L18+3 -> 45864 | AX18: =IF(L18=0, 0,L18+7) -> 45868 | BT18: =IF(L18=0, 0, L18+28) -> 45889
A19: 13 | B19: - | C19: BV-BSW-105-0000-ECM-WIR-CE-000005 | D19: Trial Mix | E19: SRM Batch Plant | F19: Opera House | I19: Trial Mix | J19: 66010 | K19: 84503 | L19: 45862 | M19: Aces | N19: Saudi RM | O19: C-10 SRC (150±40mm Slump) | P19: Blinding | Q19: 3 | R19: RM 109 | S19: 12 | T19: Trial | AB19: RH.MCR25007345 | AC19: 18 | AD19: 215 | AE19: 1.9 | AF19: 2387 | AI19: RH.MMR25040243 | AJ19: 6 hrs 20 min | AK19: 8 hrs 12 min | AM19: =L19+3 -> 45865 | AN19: WIR-CE-000005 | AO19: RH.MCR25007345@3 | AP19: 11 | AQ19: 11.5 | AR19: 11.3 | AV19: =AVERAGE(AP19:AU19) -> 11.266667 | AX19: =IF(L19=0, 0,L19+7) -> 45869 | AY19: WIR-CE-000005 | AZ19: RH.MCR25007345@7 | BA19: 14.5 | BB19: 14.9 | BC19: 15.2 | BG19: =AVERAGE(BA19:BF19) -> 14.866667 | BT19: =IF(L19=0, 0, L19+28) -> 45890 | BU19: WIR-CE-000005 | BV19: RH.MCR25007345@28 | BW19: 18.2 | BX19: 19.6 | BY19: 18 | CC19: =+AVERAGE(BW19:BY19) -> 18.6
A20: 14 | B20: - | C20: BV-BSW-105-0000-ECM-WIR-CE-000005 | D20: Trial Mix | E20: SRM Batch Plant | F20: Opera House | I20: Trial Mix | J20: 84612 | K20: 84508 | L20: 45862 | M20: Aces | N20: Saudi RM | O20: C-10 SRC (150±40mm Slump) | P20: Blinding | Q20: 3 | R20: RM 109 | S20: 12 | T20: Trial | AC20: 20.5 | AD20: 200 | AE20: 1.6 | AF20: 2391 | AM20: =L20+3 -> 45865 | AN20: WIR-CE-000005 | AO20: RH.MCR25007346@3 | AP20: 11.2 | AQ20: 11.5 | AR20: 11.4 | AV20: =AVERAGE(AP20:AU20) -> 11.366667 | AX20: =IF(L20=0, 0,L20+7) -> 45869 | AY20: WIR-CE-000005 | AZ20: RH.MCR25007346@7 | BA20: 14.6 | BB20: 16.1 | BC20: 15.4 | BG20: =AVERAGE(BA20:BF20) -> 15.366667 | BT20: =IF(L20=0, 0, L20+28) -> 45890 | BU20: WIR-CE-000005 | BV20: RH.MCR25007346@28 | BW20: 21.7 | BX20: 19.5 | BY20: 19.4 | CC20: =+AVERAGE(BW20:BY20) -> 20.2
A21: 15 | B21: - | C21: BV-BSW-105-0000-ECM-WIR-CE-000005 | D21: Trial Mix | E21: SRM Batch Plant | F21: Opera House | I21: Trial Mix | J21: 83012 | K21: 84515 | L21: 45862 | M21: Aces | N21: Saudi RM | O21: C-10 SRC (150±40mm Slump) | P21: Blinding | Q21: 3 | R21: RM 109 | S21: 12 | T21: Trial | AC21: 20.5 | AD21: 220 | AE21: 1.2 | AF21: 2402 | AM21: =L21+3 -> 45865 | AN21: WIR-CE-000005 | AO21: RH.MCR25007347@3 | AP21: 12.3 | AQ21: 11.7 | AR21: 11.9 | AV21: =AVERAGE(AP21:AU21) -> 11.966667 | AX21: =IF(L21=0, 0,L21+7) -> 45869 | AY21: WIR-CE-000005 | AZ21: RH.MCR25007347@7 | BA21: 15.9 | BB21: 15 | BC21: 15.2 | BG21: =AVERAGE(BA21:BF21) -> 15.366667 | BT21: =IF(L21=0, 0, L21+28) -> 45890 | BU21: WIR-CE-000005 | BV21: RH.MCR25007347@28 | BW21: 18.7 | BX21: 19 | BY21: 18 | CC21: =+AVERAGE(BW21:BY21) -> 18.566667
A22: 16 | B22: - | C22: N/A | D22: Concrete Blocks office Foundation | E22: Offices | F22: Opera House | I22: Temporary Works | J22: 83012 | K22: 121413 | L22: 45864 | M22: Aces | N22: Saudi RM | O22: C-40 OPC {200±40mm Slump) | P22: Blinding | Q22: 6 | R22: RM 109 | T22: Temporary | AC22: - | AD22: - | AE22: - | AF22: - | AM22: =L22+3 -> 45867 | AX22: =IF(L22=0, 0,L22+7) -> 45871 | BT22: =IF(L22=0, 0, L22+28) -> 45892
A23: 17 | B23: - | C23: N/A | D23: Survey Bench Mark | E23: Offices | F23: Opera House | I23: Temporary Works | J23: 83812 | K23: 121458 | L23: 45865 | M23: Aces | N23: Saudi RM | O23: C-10 SRC (150±40mm Slump) | P23: Blinding | Q23: 3 | R23: RM 109 | T23: Temporary | AC23: - | AD23: - | AE23: - | AF23: - | AM23: =L23+3 -> 45868 | AX23: =IF(L23=0, 0,L23+7) -> 45872 | BT23: =IF(L23=0, 0, L23+28) -> 45893
A24: 18 | B24: - | C24: BV-BSW-105-0000-ECM-WIR-CE-000006 | D24: Trial Mix | E24: SRM Batch Plant | F24: Opera House | I24: Trial Mix | J24: 84812 | K24: 121480 | L24: 45865 | M24: Aces | N24: Saudi RM | O24: C-40 HOH (SRC+60% GGBFS) (200±40mm Slump) | P24: Footing, Slab | Q24: 6 | R24: RM 109 | S24: 12 | T24: Trial | AB24: RH.MCR25007332 | AC24: 28.3 | AD24: 210 | AE24: 1.2 | AF24: 2398 | AI24: RH.MMR25040232 | AJ24: 6 hrs 3 min | AK24: 8 hrs 15 min | AM24: =L24+3 -> 45868 | AN24: WIR-CE-000006 | AO24: RH.MCR25006427@3 | AP24: 36.1 | AQ24: 37.3 | AR24: 35.7 | AV24: =AVERAGE(AP24:AU24) -> 36.366667 | AX24: =IF(L24=0, 0,L24+7) -> 45872 | AY24: WIR-CE-000006 | AZ24: RH.MCR25006427@7 | BA24: 44.9 | BB24: 43.8 | BC24: 44.4 | BG24: =AVERAGE(BA24:BF24) -> 44.366667 | BT24: =IF(L24=0, 0, L24+28) -> 45893 | BU24: WIR-CE-000006 | BV24: RH.MCR25007332@28 | BW24: 66.2 | BX24: 67.5 | BY24: 69.3 | CC24: =AVERAGE(BW24:BY24) -> 67.666667
A25: 19 | B25: - | C25: BV-BSW-105-0000-ECM-WIR-CE-000006 | D25: Trial Mix | E25: SRM Batch Plant | F25: Opera House | I25: Trial Mix | J25: 82812 | K25: 121487 | L25: 45865 | M25: Aces | N25: Saudi RM | O25: C-40 HOH (SRC+60% GGBFS) (200±40mm Slump) | P25: Footing, Slab | Q25: 6 | R25: RM 109 | S25: 12 | T25: Trial | AB25: RH.MCR25007333 | AC25: 23.8 | AD25: 220 | AE25: 1.5 | AF25: 2399 | AM25: =L25+3 -> 45868 | AN25: WIR-CE-000006 | AO25: RH.MCR25006428@3 | AP25: 38 | AQ25: 39.4 | AR25: 37.7 | AV25: =AVERAGE(AP25:AU25) -> 38.366667 | AX25: =IF(L25=0, 0,L25+7) -> 45872 | AY25: WIR-CE-000006 | AZ25: RH.MCR25006428@7 | BA25: 45.1 | BB25: 42.8 | BC25: 43.9 | BG25: =AVERAGE(BA25:BF25) -> 43.933333 | BT25: =IF(L25=0, 0, L25+28) -> 45893 | BU25: WIR-CE-000006 | BV25: RH.MCR25007333@28 | BW25: 66.1 | BX25: 65.8 | BY25: 68.4 | CC25: =AVERAGE(BW25:BY25) -> 66.766667
A26: 20 | B26: - | C26: BV-BSW-105-0000-ECM-WIR-CE-000006 | D26: Trial Mix | E26: SRM Batch Plant | F26: Opera House | I26: Trial Mix | J26: 83812 | K26: 121491 | L26: 45865 | M26: Aces | N26: Saudi RM | O26: C-40 HOH (SRC+60% GGBFS) (200±40mm Slump) | P26: Footing, Slab | Q26: 6 | R26: RM 109 | S26: 12 | T26: Trial | AB26: RH.MCR25007333 | AC26: 24.1 | AD26: 220 | AE26: 1.2 | AF26: 2414 | AM26: =L26+3 -> 45868 | AN26: WIR-CE-000006 | AO26: RH.MCR25006429@3 | AP26: 39.6 | AQ26: 38.4 | AR26: 38.2 | AV26: =AVERAGE(AP26:AU26) -> 38.733333 | AX26: =IF(L26=0, 0,L26+7) -> 45872 | AY26: WIR-CE-000006 | AZ26: RH.MCR25006429@7 | BA26: 46.4 | BB26: 47.6 | BC26: 44.6 | BG26: =AVERAGE(BA26:BF26) -> 46.2 | BT26: =IF(L26=0, 0, L26+28) -> 45893 | BU26: WIR-CE-000006 | BV26: RH.MCR25007334@28 | BW26: 66.9 | BX26: 68.9 | BY26: 71.4 | CC26: =AVERAGE(BW26:BY26) -> 69.066667
A27: 21 | B27: - | C27: BV-BSW-105-0000-ECM-WIR-CE-000008 | D27: Trial Mix | E27: SRM Batch Plant | F27: Opera House | I27: Trial Mix | J27: 82612 | K27: 121569 | L27: 45866 | M27: Aces | N27: Saudi RM | O27: C-40 SRC {200±40mm Slump) | P27: Slab & Beam, Stair | Q27: 3 | R27: RM 109 | S27: 12 | T27: Trial | AB27: RH.MCR25007335 | AC27: 27.9 | AD27: 220 | AE27: 1.4 | AF27: 2437 | AI27: RH.MMR25040237 | AJ27: 6 hrs 53 min | AK27: 8 hrs 31 min | AM27: =L27+3 -> 45869 | AN27: WIR-CE-000008 | AO27: RH.MCR25007335@3 | AP27: 41.5 | AQ27: 41 | AR27: 42.8 | AV27: =AVERAGE(AP27:AU27) -> 41.766667 | AX27: =IF(L27=0, 0,L27+7) -> 45873 | AY27: WIR-CE-000008 | AZ27: RH.MCR25007335@7 | BA27: 60.7 | BB27: 58.9 | BC27: 60.1 | BG27: =AVERAGE(BA27:BF27) -> 59.9 | BT27: =IF(L27=0, 0, L27+28) -> 45894 | BU27: WIR-CE-000008 | BV27: RH.MCR25007335@28 | BW27: 69.5 | BX27: 68.4 | BY27: 65.5 | CC27: =AVERAGE(BW27:BY27) -> 67.8
A28: 22 | B28: - | C28: BV-BSW-105-0000-ECM-WIR-CE-000008 | D28: Trial Mix | E28: SRM Batch Plant | F28: Opera House | I28: Trial Mix | J28: 83412 | K28: 121574 | L28: 45866 | M28: Aces | N28: Saudi RM | O28: C-40 SRC {200±40mm Slump) | P28: Slab & Beam, Stair | Q28: 3 | R28: RM 109 | S28: 12 | T28: Trial | AB28: RH.MCR25007336 | AC28: 27.9 | AD28: 220 | AE28: 1.4 | AF28: 2415 | AM28: =L28+3 -> 45869 | AN28: WIR-CE-000008 | AO28: RH.MCR25007336@3 | AP28: 44.8 | AQ28: 42.7 | AR28: 43.7 | AV28: =AVERAGE(AP28:AU28) -> 43.733333 | AX28: =IF(L28=0, 0,L28+7) -> 45873 | AY28: WIR-CE-000008 | AZ28: RH.MCR25007336@7 | BA28: 61.2 | BB28: 59.9 | BC28: 60 | BG28: =AVERAGE(BA28:BF28) -> 60.366667 | BT28: =IF(L28=0, 0, L28+28) -> 45894 | BU28: WIR-CE-000008 | BV28: RH.MCR25007336@28 | BW28: 68.8 | BX28: 65.5 | BY28: 67.5 | CC28: =AVERAGE(BW28:BY28) -> 67.266667
A29: 23 | B29: - | C29: BV-BSW-105-0000-ECM-WIR-CE-000008 | D29: Trial Mix | E29: SRM Batch Plant | F29: Opera House | I29: Trial Mix | J29: 82812 | K29: 121580 | L29: 45866 | M29: Aces | N29: Saudi RM | O29: C-40 SRC {200±40mm Slump) | P29: Slab & Beam, Stair | Q29: 3 | R29: RM 109 | S29: 12 | T29: Trial | AB29: RH.MCR25007337 | AC29: 27 | AD29: 220 | AE29: 1.1 | AF29: 2430 | AM29: =L29+3 -> 45869 | AN29: WIR-CE-000008 | AO29: RH.MCR25007337@3 | AP29: 43.7 | AQ29: 42.1 | AR29: 42.3 | AV29: =AVERAGE(AP29:AU29) -> 42.7 | AX29: =IF(L29=0, 0,L29+7) -> 45873 | AY29: WIR-CE-000008 | AZ29: RH.MCR25007337@7 | BA29: 58.9 | BB29: 59.6 | BC29: 58.9 | BG29: =AVERAGE(BA29:BF29) -> 59.133333 | BT29: =IF(L29=0, 0, L29+28) -> 45894 | BU29: WIR-CE-000008 | BV29: RH.MCR25007337@28 | BW29: 66.8 | BX29: 68.4 | BY29: 64.5 | CC29: =AVERAGE(BW29:BY29) -> 66.566667
A30: 24 | B30: - | C30: N/A | D30: Wall/ Foundation | E30: Offices Foundation | F30: Opera House | I30: Temporary Works | J30: 82812 | K30: 121578 | L30: 45866 | M30: Aces | N30: Saudi RM | O30: C-40 SRC {200±40mm Slump) | P30: Column and Retaining Wall | Q30: 6 | R30: RM 109 | T30: Temporary | AC30: - | AD30: - | AE30: - | AF30: - | AM30: =L30+3 -> 45869 | AX30: =IF(L30=0, 0,L30+7) -> 45873 | BT30: =IF(L30=0, 0, L30+28) -> 45894
A31: 25 | B31: - | C31: BV-BSW-105-0000-ECM-WIR-CE-000013 | D31: Trial Mix | E31: SRM Batch Plant | F31: Opera House | I31: Trial Mix | J31: 81512 | K31: 121752 | L31: 45868 | M31: Aces | N31: Saudi RM | O31: C-50 SRC {200±40mm Slump) | P31: Wall, Column and Retaining Wall | Q31: 6 | R31: RM 109 | S31: 12 | T31: Trial | AC31: 21.6 | AD31: 210 | AE31: 1.6 | AF31: 2403 | AI31: RH.MMR25040239 | AJ31: 5 hrs 33 min | AK31: 8 hrs 3 min | AM31: =L31+3 -> 45871 | AN31: WIR-CE-000013 | AO31: RH.MCR25007348@3 | AP31: 39.4 | AQ31: 38.1 | AR31: 40.5 | AV31: =AVERAGE(AP31:AU31) -> 39.333333 | AX31: =IF(L31=0, 0,L31+7) -> 45875 | AY31: WIR-CE-000013 | AZ31: RH.MCR25007348@7 | BA31: 50 | BB31: 48.8 | BC31: 49.5 | BG31: =AVERAGE(BA31:BF31) -> 49.433333 | BT31: =IF(L31=0, 0, L31+28) -> 45896 | BU31: WIR-CE-000013 | BV31: RH.MCR25007348@28 | BW31: 56.1 | BX31: 56 | BY31: 57.5 | CC31: =AVERAGE(BW31:BY31) -> 56.533333
A32: 26 | B32: - | C32: BV-BSW-105-0000-ECM-WIR-CE-000013 | D32: Trial Mix | E32: SRM Batch Plant | F32: Opera House | I32: Trial Mix | J32: 84012 | K32: 121754 | L32: 45868 | M32: Aces | N32: Saudi RM | O32: C-50 SRC {200±40mm Slump) | P32: Wall, Column and Retaining Wall | Q32: 6 | R32: RM 109 | S32: 12 | T32: Trial | AC32: 23.9 | AD32: 210 | AE32: 1.5 | AF32: 2404 | AM32: =L32+3 -> 45871 | AN32: WIR-CE-000013 | AO32: RH.MCR25007349@3 | AP32: 40.7 | AQ32: 40.7 | AR32: 38.8 | AV32: =AVERAGE(AP32:AU32) -> 40.066667 | AX32: =IF(L32=0, 0,L32+7) -> 45875 | AY32: WIR-CE-000013 | AZ32: RH.MCR25007349@7 | BA32: 50 | BB32: 49.2 | BC32: 50.2 | BG32: =AVERAGE(BA32:BF32) -> 49.8 | BT32: =IF(L32=0, 0, L32+28) -> 45896 | BU32: WIR-CE-000013 | BV32: RH.MCR25007349@28 | BW32: 56.9 | BX32: 54.3 | BY32: 56.1 | CC32: =AVERAGE(BW32:BY32) -> 55.766667
A33: 27 | B33: - | C33: BV-BSW-105-0000-ECM-WIR-CE-000013 | D33: Trial Mix | E33: SRM Batch Plant | F33: Opera House | I33: Trial Mix | J33: 84612 | K33: 121758 | L33: 45868 | M33: Aces | N33: Saudi RM | O33: C-50 SRC {200±40mm Slump) | P33: Wall, Column and Retaining Wall | Q33: 6 | R33: RM 109 | S33: 12 | T33: Trial | AC33: 25.9 | AD33: 210 | AE33: 1.1 | AF33: 2398 | AM33: =L33+3 -> 45871 | AN33: WIR-CE-000013 | AO33: RH.MCR25007350@3 | AP33: 39.8 | AQ33: 40.8 | AR33: 39.2 | AV33: =AVERAGE(AP33:AU33) -> 39.933333 | AX33: =IF(L33=0, 0,L33+7) -> 45875 | AY33: WIR-CE-000013 | AZ33: RH.MCR25007350@7 | BA33: 51.4 | BB33: 50.3 | BC33: 49.3 | BG33: =AVERAGE(BA33:BF33) -> 50.333333 | BT33: =IF(L33=0, 0, L33+28) -> 45896 | BU33: WIR-CE-000013 | BV33: RH.MCR25007349@28 | BW33: 57 | BX33: 56 | BY33: 53.5 | CC33: =AVERAGE(BW33:BY33) -> 55.5
A34: 28 | B34: - | C34: BV-BSW-105-0000-ECM-WIR-CE-000017 | D34: Blinding Concrete | E34: Towe Crane 01 | F34: Opera House | H34: B2 | I34: Permanent Works | J34: 84212 | K34: 121755 | L34: 45868 | M34: Aces | N34: Saudi RM | O34: C-10 SRC (150±40mm Slump) | P34: Blinding | Q34: 11 | R34: RM 109 | T34: Permanent | AB34: RH.MCR25007740 | AC34: 27.5 | AD34: 190 | AE34: - | AF34: - | AM34: =L34+3 -> 45871 | AX34: =IF(L34=0, 0,L34+7) -> 45875 | AY34: WIR-CE-000017-000018-000019 | AZ34: RH.MCR25007740@7 | BA34: 12 | BB34: 13.1 | BC34: 12.5 | BD34: 13.7 | BE34: 13.4 | BF34: 14.3 | BG34: =AVERAGE(BA34:BF34) -> 13.166667 | BT34: =IF(L34=0, 0, L34+28) -> 45896 | BU34: WIR-CE-000017-000018-000019 | BV34: RH.MCR25007740@28 | BW34: 19.7 | BX34: 20.2 | BY34: 18.4 | BZ34: 20.6 | CA34: 18 | CB34: 21.5 | CC34: =AVERAGE(BW34:CB34) -> 19.733333
A35: 29 | B35: - | C35: BV-BSW-105-0000-ECM-WIR-CE-000017 | D35: Blinding Concrete | E35: Towe Crane 01 | F35: Opera House | H35: B2 | I35: Permanent Works | J35: 84612 | K35: 121757 | L35: 45868 | M35: Aces | N35: Saudi RM | O35: C-10 SRC (150±40mm Slump) | P35: Blinding | Q35: 11 | R35: RM 109 | T35: Permanent | AC35: 27.5 | AD35: 180 | AE35: - | AF35: - | AM35: =L35+3 -> 45871 | AX35: =IF(L35=0, 0,L35+7) -> 45875 | BT35: =IF(L35=0, 0, L35+28) -> 45896
A36: 30 | B36: - | C36: BV-BSW-105-0000-ECM-WIR-CE-000017 | D36: Blinding Concrete | E36: Towe Crane 01 | F36: Opera House | H36: B2 | I36: Permanent Works | J36: 67610 | K36: 121766 | L36: 45868 | M36: Aces | N36: Saudi RM | O36: C-10 SRC (150±40mm Slump) | P36: Blinding | Q36: 9 | R36: RM 109 | S36: 6 | T36: Permanent | AC36: 27.2 | AD36: 180 | AE36: - | AF36: - | AM36: =L36+3 -> 45871 | AX36: =IF(L36=0, 0,L36+7) -> 45875 | BT36: =IF(L36=0, 0, L36+28) -> 45896
A37: 31 | B37: - | C37: BV-BSW-105-0000-ECM-WIR-CE-000017 | D37: Blinding Concrete | E37: Towe Crane 01 | F37: Opera House | H37: B2 | I37: Permanent Works | J37: 66010 | K37: 121762 | L37: 45868 | M37: Aces | N37: Saudi RM | O37: C-10 SRC (150±40mm Slump) | P37: Blinding | Q37: 9 | R37: RM 109 | T37: Permanent | AC37: 28.2 | AD37: 190 | AE37: - | AF37: - | AM37: =L37+3 -> 45871 | AX37: =IF(L37=0, 0,L37+7) -> 45875 | BT37: =IF(L37=0, 0, L37+28) -> 45896
A38: 32 | B38: - | C38: BV-BSW-105-0000-ECM-WIR-CE-000018 | D38: Blinding Concrete | E38: Towe Crane 02 | F38: Opera House | H38: B2 | I38: Permanent Works | J38: 62810 | K38: 121768 | L38: 45868 | M38: Aces | N38: Saudi RM | O38: C-10 SRC (150±40mm Slump) | P38: Blinding | Q38: 9 | R38: RM 109 | T38: Permanent | AC38: 26.4 | AD38: 190 | AE38: - | AF38: - | AM38: =L38+3 -> 45871 | AX38: =IF(L38=0, 0,L38+7) -> 45875 | BT38: =IF(L38=0, 0, L38+28) -> 45896
A39: 33 | B39: - | C39: BV-BSW-105-0000-ECM-WIR-CE-000018 | D39: Blinding Concrete | E39: Towe Crane 02 | F39: Opera House | H39: B2 | I39: Permanent Works | J39: 84012 | K39: 121776 | L39: 45868 | M39: Aces | N39: Saudi RM | O39: C-10 SRC (150±40mm Slump) | P39: Blinding | Q39: 10 | R39: RM 109 | T39: Permanent | AC39: 26.6 | AD39: 190 | AE39: - | AF39: - | AM39: =L39+3 -> 45871 | AX39: =IF(L39=0, 0,L39+7) -> 45875 | BT39: =IF(L39=0, 0, L39+28) -> 45896
A40: 34 | B40: - | C40: BV-BSW-105-0000-ECM-WIR-CE-000018 | D40: Blinding Concrete | E40: Towe Crane 02 | F40: Opera House | H40: B2 | I40: Permanent Works | J40: 81512 | K40: 121797 | L40: 45868 | M40: Aces | N40: Saudi RM | O40: C-10 SRC (150±40mm Slump) | P40: Blinding | Q40: 11 | R40: RM 109 | S40: 6 | T40: Permanent | AC40: 27.7 | AD40: 170 | AE40: - | AF40: - | AM40: =L40+3 -> 45871 | AX40: =IF(L40=0, 0,L40+7) -> 45875 | BT40: =IF(L40=0, 0, L40+28) -> 45896
A41: 35 | B41: - | C41: BV-BSW-105-0000-ECM-WIR-CE-000018 | D41: Blinding Concrete | E41: Towe Crane 02 | F41: Opera House | H41: B2 | I41: Permanent Works | J41: 77112 | K41: 121778 | L41: 45868 | M41: Aces | N41: Saudi RM | O41: C-10 SRC (150±40mm Slump) | P41: Blinding | Q41: 11 | R41: RM 109 | T41: Permanent | AC41: 25.8 | AD41: 160 | AE41: - | AF41: - | AM41: =L41+3 -> 45871 | AX41: =IF(L41=0, 0,L41+7) -> 45875 | BT41: =IF(L41=0, 0, L41+28) -> 45896
...

Sheet BASE Locked 
A1: Plants | B1: Laboratory | C1: Location | D1: Conctractor | F1: m3 | G1: Concrete Type | H1: rejected jv issue m3 | J1: Casting Type | K1: Zone | M1: Opening Time of Formwork | N1: Basement/ Floor
A2: Saudi RM | B2: ACES | C2: Opera House | D2: CSCEC | E2: Temporary | F2: 1 | G2: C-10 SRC (150±40mm Slump) | H2: 1 | J2: Blinding | K2: 1 | M2: 6 hours | N2: B2
A3: BEC Arabia Concrete Solution | B3: Al Hoty Stanger | C3: Langham Hotel | D3: ESEC | E3: Permanent | F3: 1.5 | G3: C-50 SRC {200±40mm Slump) | H3: 1.5 | J3: Slab & Beam, Stair | K3: 2 | M3: 8 hours | N3: B1
A4: Unibeton Ready Mix | C4: Mixed Use Residential | D4: MIDMAC | E4: Trial | F4: 2 | G4: C-40 SRC {200±40mm Slump) | H4: 2 | J4: Wall, Column and Retaining Wall | K4: 3 | M4: 10 hours | N4: L0
A5: UBCC Ready Mix | C5: Public Realm | D5: ECMJV | E5: Rejected | F5: 2.5 | G5: C-40 (SRC+60% GGBFS) (200±40mm Slump) | H5: 2.5 | J5: Footing, Slab | K5: 4 | M5: 12 hours | N5: L1
A6: Green Concrete Ready Mix | C6: Energy Centre | F6: 3 | G6: C-40 OPC {200±40mm Slump) | H6: 3 | J6: Foundation | K6: 5 | M6: 14 hours | N6: L2
F7: 3.5 | G7: C-10/20 (SRC) - Blinding | H7: 3.5 | J7: Structural Walls and Columns | K7: 6 | M7: 16 hours | N7: L3
F8: 4 | G8: C50/10 (OPC) 190 ± 40mm Slump | H8: 4 | J8: Raft (Thick Section) | K8: 7 | M8: 17 hours | N8: Fourth Floor
F9: 4.5 | G9: C40/20 (SRC+60% GGFBS) | H9: 4.5 | J9: Retaining Wall | K9: 8 | M9: 18 hours | N9: Fifth Floor
F10: 5 | G10: C-50/20 SRC {190±40mm Slump) | H10: 5 | K10: 9 | M10: 19 hours | N10: Six Floor
F11: 5.5 | G11: C-40 OPC {190±40mm Slump) | H11: 5.5 | K11: 10 | M11: 20 hours
F12: 6 | G12: C50/10 (OPC) 200 ± 40mm Slump | H12: 6 | K12: 11 | M12: 21 hours
F13: 6.5 | G13: C50/20 (SRC) 200 ± 40mm Slump | H13: 6.5 | K13: 12 | M13: 22 hours
F14: 7 | G14: C 50/10 MPa (OPC+40%GGBS) | H14: 7 | M14: 22.5 hours
F15: 7.5 | G15: C40/10 (OPC) 220 ± 40 | H15: 7.5 | M15: 23 hours
F16: 8 | G16: C50/10 (OPC) 220 ± 40 | H16: 8 | M16: 24 hours
F17: 8.5 | G17: C50/10 (60% OPC+40%GGBFS) 220 ± 40mm | H17: 8.5
F18: 9 | H18: 9
F19: 9.5 | H19: 9.5
F20: 10 | H20: 10
F21: 10.5 | H21: 10.5
F22: 11 | H22: 11
F23: 11.5 | H23: 11.5
F25: 12 | H25: 12
F26: 12.5 | H26: 12.5
F27: 13 | H27: 13
G37: 1 | H37: The Royal Diriyah Opera House (DE4-CO-01)
G38: 2 | H38: Langham Hotel (DE4-CH-02)
G39: 3 | H39: Mixed Use Residential (DE4-MUR-03 & DE4-MUR-04)
G40: 4 | H40: Public Realm
G41: 5 | H41: Energy Centre

Sheet Sheet1
A1: S.No. | B1: CAP No. | C1: WIR No. | D1: Element and Inspection Description | E1: Grids/ Locations | F1: Building Area | G1: Zone | H1: Basement/Floor | I1: Permanent Works / Temporary Works | J1: Truck Number | K1: Ticket Number | L1: Date of Casting | M1: 3rd Party Laboratory Name | N1: Concrete Suppiler | O1: Concrete Name | P1: Area | Q1: Concrete Quantity (m3) | R1: Batch Plant No. | S1: Sample Taken | T1: Casting Type | U1: REJECTED DUE TO JV ISSUE (m3) | V1: REMARKS
A2: 541 | B2: BV-BSW-105-0000-ECM-CAP-CE-000033 | C2: BV-BSW-105-0000-ECM-WIR-CE-000266 | D2: Blinding Concrete | E2: 639.95 ,639.65 & 640.25 | F2: Opera House | G2: 5 | H2: B2 | I2: Permanent Works | J2: 82012 | K2: 95797 | L2: 45904 | M2: ACES | N2: Saudi RM | O2: C-10 SRC (150±40mm Slump) | P2: Blinding | Q2: 10 | R2: RM 109 | T2: Rejected | U2: 10 | V2: Time Exceeded
A3: 540 | B3: BV-BSW-105-0000-ECM-CAP-CE-000033 | C3: BV-BSW-105-0000-ECM-WIR-CE-000266 | D3: Blinding Concrete | E3: 639.95 ,639.65 & 640.25 | F3: Opera House | G3: 5 | H3: B2 | I3: Permanent Works | J3: 84812 | K3: 95794 | L3: 45904 | M3: ACES | N3: Saudi RM | O3: C-10 SRC (150±40mm Slump) | P3: Blinding | Q3: 10 | R3: RM 109 | T3: Rejected | U3: 10 | V3: Time Exceeded
A4: 1589 | B4: BV-BSW-105-0000-ECM-CAP-CE-000040 | C4: BV-BSW-105-0000-ECM-WIR-CE-000481 | D4: Raft Foundation Concrete | E4: Raft Foundation Concrete Zone 10 First Casting | F4: Opera House | G4: 10 | H4: B2 | I4: Permanent Works | J4: 278 | K4: 2285364 | L4: 45945 | M4: ACES | N4: Unibeton Ready Mix | O4: C-40 (SRC+60% GGBFS) (200±40mm Slump) | P4: Foundation | Q4: 8 | R4: Sully | T4: Rejected | V4: Rejected due to over time
A5: 1389 | B5: BV-BSW-105-0000-ECM-CAP-CE-000037 | C5: BV-BSW-105-0000-ECM-WIR-CE-000444 | D5: Raft Foundation Concrete | F5: Opera House | G5: 2 | H5: B2 | I5: Permanent Works | J5: 7792 | K5: 108850 | L5: 45941 | M5: ACES | N5: BEC Arabia Concrete Solution | O5: C40/20 (SRC+60% GGBS) | P5: Foundation | Q5: 8 | T5: Rejected | U5: 8 | V5: Rejected due to Time Delay
A6: 1382 | B6: BV-BSW-105-0000-ECM-CAP-CE-000037 | C6: BV-BSW-105-0000-ECM-WIR-CE-000444 | D6: Raft Foundation Concrete | F6: Opera House | G6: 2 | H6: B2 | I6: Permanent Works | J6: 5707 | K6: 108843 | L6: 45941 | M6: ACES | N6: BEC Arabia Concrete Solution | O6: C40/20 (SRC+60% GGBS) | P6: Foundation | Q6: 10 | T6: Rejected | V6: Rejected dur to high slump
A7: 1282 | B7: BV-BSW-105-0000-ECM-CAP-CE-000036 | C7: BV-BSW-105-0000-ECM-WIR-CE-000412 | D7: Raft Foundation Concrete | F7: Opera House | G7: 11 | H7: B2 | I7: Permanent Works | J7: 62810 | K7: 75336 | L7: 45931 | M7: ACES | N7: Saudi RM | O7: C-40 (SRC+60% GGBFS) (200±40mm Slump) | P7: Foundation | Q7: 9 | R7: RM 109 | S7: Rejected | T7: Rejected | V7: Rejected due to high slump
A8: 1273 | B8: BV-BSW-105-0000-ECM-CAP-CE-000036 | C8: BV-BSW-105-0000-ECM-WIR-CE-000412 | D8: Raft Foundation Concrete | F8: Opera House | G8: 11 | H8: B2 | I8: Permanent Works | J8: 82812 | K8: 75327 | L8: 45931 | M8: ACES | N8: Saudi RM | O8: C-40 (SRC+60% GGBFS) (200±40mm Slump) | P8: Foundation | Q8: 10 | R8: RM 109 | S8: Rejected | T8: Rejected | V8: Rejected due to high slump
A9: 1239 | B9: BV-BSW-105-0000-ECM-CAP-CE-000036 | C9: BV-BSW-105-0000-ECM-WIR-CE-000412 | D9: Raft Foundation Concrete | F9: Opera House | G9: 11 | H9: B2 | I9: Permanent Works | J9: 78012 | K9: 75289 | L9: 45931 | M9: ACES | N9: Saudi RM | O9: C-40 (SRC+60% GGBFS) (200±40mm Slump) | P9: Foundation | Q9: 10 | R9: RM 109 | S9: Rejected | T9: Rejected | V9: Rejected due to high slump
A10: 1153 | B10: BV-BSW-105-0000-ECM-CAP-CE-000036 | C10: BV-BSW-105-0000-ECM-WIR-CE-000412 | D10: Raft Foundation Concrete | F10: Opera House | G10: 11 | H10: B2 | I10: Permanent Works | J10: 94112 | K10: 90272 | L10: 45931 | M10: ACES | N10: Saudi RM | O10: C-40 (SRC+60% GGBFS) (200±40mm Slump) | P10: Foundation | Q10: 10 | R10: RM 64 | T10: Rejected | V10: Rejected
A11: 808 | B11: BV-BSW-105-0000-ECM-CAP-CE-000035 | C11: BV-BSW-105-0000-ECM-WIR-CE-000342 | D11: Raft Foundation Concrete | F11: Opera House | G11: 2 | H11: B2 | I11: Permanent Works | J11: 76012 | K11: 60974 | L11: 45917 | M11: ACES | N11: Saudi RM | O11: C-40 (SRC+60% GGBFS) (200±40mm Slump) | P11: Foundation | Q11: 10 | R11: RM 64 | S11: Rejected | T11: Rejected | V11: Rejected due to low Slump
A12: 805 | B12: BV-BSW-105-0000-ECM-CAP-CE-000035 | C12: BV-BSW-105-0000-ECM-WIR-CE-000342 | D12: Raft Foundation Concrete | F12: Opera House | G12: 2 | H12: B2 | I12: Permanent Works | J12: 94312 | K12: 60971 | L12: 45917 | M12: ACES | N12: Saudi RM | O12: C-40 (SRC+60% GGBFS) (200±40mm Slump) | P12: Foundation | Q12: 10 | R12: RM 64 | S12: Rejected | T12: Rejected | V12: Rejected due to low Slump
A13: 254 | B13: BV-BSW-105-0000-ECM-CAP-CE-000022 | C13: BV-BSW-105-0000-ECM-WIR-CE-000136 | D13: Foundation Concrete | E13: Tower Crane 04 | F13: Opera House | G13: 2 | H13: B2 | I13: Permanent Works | J13: 81512 | K13: 132757 | L13: 45893 | M13: ACES | N13: Saudi RM | O13: C-40 (SRC+60% GGBFS) (200±40mm Slump) | P13: Foundation | Q13: 10 | R13: RM 109 | T13: Rejected | U13: 10 | V13: Rejected due to delay in time
A14: 616 | B14: - | C14: BV-BSW-105-0000-ECM-WIR-CE-000317 | D14: Trial Mix | E14: BEC Batch Plant | F14: Opera House | I14: Trial Mix | J14: 7792 | K14: 85284 | L14: 45909 | M14: ACES | N14: BEC Arabia Concrete Solution | O14: C50/10 (OPC) 190 ± 40mm Slump | P14: Wall, Column and Retaining Wall | Q14: 3 | T14: Rejected | V14: Due to High Temp
A15: 615 | B15: - | C15: BV-BSW-105-0000-ECM-WIR-CE-000317 | D15: Trial Mix | E15: BEC Batch Plant | F15: Opera House | I15: Trial Mix | J15: 7792 | K15: 85277 | L15: 45909 | M15: ACES | N15: BEC Arabia Concrete Solution | O15: C50/10 (OPC) 190 ± 40mm Slump | P15: Wall, Column and Retaining Wall | Q15: 3 | T15: Rejected | V15: Due to High Slump

Sheet Pivot
A3: Row Labels | B3: Sum of Concrete Quantity (m3)
A4: Permanent | B4: 15815
A5: Blinding | B5: 7910
A6: Foundation | B6: 7899
A7: Wall, Column and Retaining Wall | B7: 6
A8: Rejected | B8: 121
A9: Blinding | B9: 20
A10: Foundation | B10: 95
A11: Wall, Column and Retaining Wall | B11: 6
A12: Temporary | B12: 405
A13: Blinding | B13: 399
A14: Column and Retaining Wall | B14: 6
A15: Trial | B15: 147
... A22: Grand Total | B22: 16488

Sheet Summary
N1: 1 No samples per 40 m3 | R1: 1 No samples per 40 m3 | T1: 1 No samples per 40 m3
E3: ³ | N3: Teoric Application | R3: Teoric Application | T3: Teoric Application | X3: Teoric Application
C5: Project | D5: Location | E5: Basement/ Floors | F5: Slab & Beam, Stair (Qty m³) | G5: BLINDING (Qty m³) | H5: Column and Retaining Wall (Qty m³) | I5: Raft/Foundation (Qty m³) | J5: Dry Mix Mortor | L5: Rejected (Qty m³) | M5: Concrete Quantity Site (Qty m³) | N5: Number of samples to be taken | Q5: Number of samples taken | R5: Number of samples to be taken | S5: Number of samples taken | T5: Number of samples to be taken | W5: Number of samples taken | X5: Number of samples to be taken | AA5: Number of samples taken
C7: Opera House | D7: Permanent Work | E7: Basement 2 (B2) | F7: =SUMIFS('Cast In Situ Tracker'!Q5:Q15011,'Cast In Situ Tracker'!T5:T15011,"Permanent*",'Cast In Situ Tracker'!P5:P15011,"Slab & Beam, Stair ",'Cast In Situ Tracker'!H5:H15011,"B2") -> 33 | G7: =SUMIFS('Cast In Situ Tracker'!Q5:Q15011,'Cast In Situ Tracker'!T5:T15011,"Permanent*",'Cast In Situ Tracker'!P5:P15011,"Blinding",'Cast In Situ Tracker'!H5:H15011,"B2") -> 9404 | H7: =SUMIFS('Cast In Situ Tracker'!Q5:Q15011,'Cast In Situ Tracker'!T5:T15011,"Permanent*",'Cast In Situ Tracker'!P5:P15011,"Wall, Column and Retaining Wall",'Cast In Situ Tracker'!H5:H15011,"B2") -> 7488 | I7: =SUMIFS('Cast In Situ Tracker'!Q5:Q15011,'Cast In Situ Tracker'!T5:T15011,"Permanent*",'Cast In Situ Tracker'!P5:P15011,"Foundation",'Cast In Situ Tracker'!H5:H15011,"B2") -> 33303 | J7: 7 | L7: =SUMIFS('Cast In Situ Tracker'!Q7:Q12593,'Cast In Situ Tracker'!T7:T12593,"Rejected") -> 282 | M7: =SUM(F7:I8) -> 50228 | N7: =ROUNDUP(M7/57,0) -> 882 | Q7: 47 | R7: =N7 -> 882 | S7: =Q7 -> 47 | T7: =ROUNDUP(I7/100,0) -> 334
E9: Basement 1 (B1) | F9: =SUMIFS('Cast In Situ Tracker'!Q7:Q15013,'Cast In Situ Tracker'!T7:T15013,"Permanent*",'Cast In Situ Tracker'!P7:P15013,"Slab & Beam, Stair ",'Cast In Situ Tracker'!H7:H15013,"B1") -> 7056 | G9: =SUMIFS('Cast In Situ Tracker'!Q7:Q15013,'Cast In Situ Tracker'!T7:T15013,"Permanent*",'Cast In Situ Tracker'!P7:P15013,"Blinding",'Cast In Situ Tracker'!H7:H15013,"B1") -> 0 | H9: =SUMIFS('Cast In Situ Tracker'!Q7:Q15013,'Cast In Situ Tracker'!T7:T15013,"Permanent*",'Cast In Situ Tracker'!P7:P15013,"Wall, Column and Retaining Wall",'Cast In Situ Tracker'!H7:H15013,"B1") -> 5653 | I9: =SUMIFS('Cast In Situ Tracker'!Q7:Q15013,'Cast In Situ Tracker'!T7:T15013,"Permanent*",'Cast In Situ Tracker'!P7:P15013,"Foundation",'Cast In Situ Tracker'!H7:H15013,"B1") -> 0 | J9: 0 | M9: =SUM(F9:I10) -> 12709 | N9: =ROUNDUP(M9/40,0) -> 318 | R9: =N9 -> 318 | T9: =ROUNDUP(I9/100,0) -> 0
E11: Ground Level (L0) | F11: =SUMIFS('Cast In Situ Tracker'!Q7:Q15013,'Cast In Situ Tracker'!T7:T15013,"Permanent*",'Cast In Situ Tracker'!P7:P15013,"Slab & Beam, Stair ",'Cast In Situ Tracker'!H7:H15013,"L0") -> 7334 | G11: =SUMIFS('Cast In Situ Tracker'!Q9:Q15015,'Cast In Situ Tracker'!T9:T15015,"Permanent*",'Cast In Situ Tracker'!P9:P15015,"Blinding",'Cast In Situ Tracker'!H9:H15015,"L0") -> 34 | H11: =SUMIFS('Cast In Situ Tracker'!Q9:Q15015,'Cast In Situ Tracker'!T9:T15015,"Permanent*",'Cast In Situ Tracker'!P9:P15015,"Wall, Column and Retaining Wall",'Cast In Situ Tracker'!H9:H15015,"L0") -> 3019 | I11: =SUMIFS('Cast In Situ Tracker'!Q9:Q15015,'Cast In Situ Tracker'!T9:T15015,"Permanent*",'Cast In Situ Tracker'!P9:P15015,"Foundation",'Cast In Situ Tracker'!H9:H15015,"L0") -> 260 | J11: 0 | M11: =SUM(F11:I12) -> 10647 | N11: =ROUNDUP(M11/40,0) -> 267 | R11: =N11 -> 267 | T11: =ROUNDUP(I11/100,0) -> 3
E13: First Floor (L1) | F13: =SUMIFS('Cast In Situ Tracker'!Q9:Q15015,'Cast In Situ Tracker'!T9:T15015,"Permanent*",'Cast In Situ Tracker'!P9:P15015,"Slab & Beam, Stair ",'Cast In Situ Tracker'!H9:H15015,"L1") -> 1050 | G13: =SUMIFS('Cast In Situ Tracker'!Q11:Q15017,'Cast In Situ Tracker'!T11:T15017,"Permanent*",'Cast In Situ Tracker'!P11:P15017,"Blinding",'Cast In Situ Tracker'!H11:H15017,"L1") -> 0 | H13: =SUMIFS('Cast In Situ Tracker'!Q11:Q15017,'Cast In Situ Tracker'!T11:T15017,"Permanent*",'Cast In Situ Tracker'!P11:P15017,"Wall, Column and Retaining Wall",'Cast In Situ Tracker'!H11:H15017,"L1") -> 1858 | I13: =SUMIFS('Cast In Situ Tracker'!Q11:Q15017,'Cast In Situ Tracker'!T11:T15017,"Permanent*",'Cast In Situ Tracker'!P11:P15017,"Foundation",'Cast In Situ Tracker'!H11:H15017,"L1") -> 0 | J13: 0 | M13: =SUM(F13:I14) -> 2908 | N13: =ROUNDUP(M13/40,0) -> 73 | R13: =N13 -> 73 | T13: =ROUNDUP(I13/100,0) -> 0
E15: Second Floor (L2) | F15: =SUMIFS('Cast In Situ Tracker'!Q11:Q15017,'Cast In Situ Tracker'!T11:T15017,"Permanent*",'Cast In Situ Tracker'!P11:P15017,"Slab & Beam, Stair ",'Cast In Situ Tracker'!H11:H15017,"L2") -> 0 | G15: =SUMIFS('Cast In Situ Tracker'!Q13:Q15019,'Cast In Situ Tracker'!T13:T15019,"Permanent*",'Cast In Situ Tracker'!P13:P15019,"Blinding",'Cast In Situ Tracker'!H13:H15019,"L2") -> 0 | H15: =SUMIFS('Cast In Situ Tracker'!Q13:Q15019,'Cast In Situ Tracker'!T13:T15019,"Permanent*",'Cast In Situ Tracker'!P13:P15019,"Wall, Column and Retaining Wall",'Cast In Situ Tracker'!H13:H15019,"L2") -> 188 | I15: =SUMIFS('Cast In Situ Tracker'!Q13:Q15019,'Cast In Situ Tracker'!T13:T15019,"Permanent*",'Cast In Situ Tracker'!P13:P15019,"Foundation",'Cast In Situ Tracker'!H13:H15019,"L2") -> 0 | J15: 0 | M15: =SUM(F15:I16) -> 188 | N15: =ROUNDUP(M15/40,0) -> 5 | R15: =N15 -> 5 | T15: =ROUNDUP(I15/100,0) -> 0
K16: =SUMIFS('Cast In Situ Tracker'!Q7:Q248,'Cast In Situ Tracker'!T7:T248,"L1-S1*",'Cast In Situ Tracker'!P7:P248,"Center Slab") -> 0 | X16: =ROUNDUP(I16/200,0) -> 0 | AA16: 9
E17: Third Floor (L3) | F17: =SUMIFS('Cast In Situ Tracker'!Q13:Q15019,'Cast In Situ Tracker'!T13:T15019,"Permanent*",'Cast In Situ Tracker'!P13:P15019,"Slab & Beam, Stair ",'Cast In Situ Tracker'!H13:H15019,"L3") -> 14 | G17: =SUMIFS('Cast In Situ Tracker'!Q15:Q15021,'Cast In Situ Tracker'!T15:T15021,"Permanent*",'Cast In Situ Tracker'!P15:P15021,"Blinding",'Cast In Situ Tracker'!H15:H15021,"L3") -> 0 | H17: =SUMIFS('Cast In Situ Tracker'!Q15:Q15021,'Cast In Situ Tracker'!T15:T15021,"Permanent*",'Cast In Situ Tracker'!P15:P15021,"Wall, Column and Retaining Wall",'Cast In Situ Tracker'!H15:H15021,"L3") -> 234 | I17: =SUMIFS('Cast In Situ Tracker'!Q15:Q15021,'Cast In Situ Tracker'!T15:T15021,"Permanent*",'Cast In Situ Tracker'!P15:P15021,"Foundation",'Cast In Situ Tracker'!H15:H15021,"L3") -> 0 | J17: 0 | M17: =SUM(F17:I18) -> 248
E19: Concrete Trials | F19: =SUMIFS('Cast In Situ Tracker'!Q5:Q15029,'Cast In Situ Tracker'!T5:T15029,"Trial*",'Cast In Situ Tracker'!P5:P15029,"Slab & Beam, Stair ") -> 48 | G19: =SUMIFS('Cast In Situ Tracker'!Q5:Q15411,'Cast In Situ Tracker'!T5:T15411,"Trial*",'Cast In Situ Tracker'!P5:P15411,"BLINDING") -> 21 | H19: =SUMIFS('Cast In Situ Tracker'!Q5:Q15011,'Cast In Situ Tracker'!T5:T15011,"Trial*",'Cast In Situ Tracker'!P5:P15011,"Wall, Column and Retaining Wall")+SUMIFS('Cast In Situ Tracker'!Q5:Q15031,'Cast In Situ Tracker'!T5:T15031,"Trial*",'Cast In Situ Tracker'!P5:P15031,"Structural Walls and Columns ") -> 123 | I19: =SUMIFS('Cast In Situ Tracker'!Q5:Q15031,'Cast In Situ Tracker'!T5:T15031,"Trial*",'Cast In Situ Tracker'!P5:P15031,"Footing, Slab ")+SUMIFS('Cast In Situ Tracker'!Q5:Q15031,'Cast In Situ Tracker'!T5:T15031,"Trial*",'Cast In Situ Tracker'!P5:P15031,"Raft (Thick Section)") -> 36 | J19: 0 | M19: =SUM(F19:I20) -> 228 | N19: 12 | Q19: 36 | R19: =N19 -> 12 | S19: =Q19 -> 36 | T19: =ROUNDUP(I19/100,0) -> 1
D21: Temporary | E21: Temporary Facilities | F21: =SUMIFS('Cast In Situ Tracker'!Q7:Q15231,'Cast In Situ Tracker'!T7:T15231,"Temporary*",'Cast In Situ Tracker'!P7:P15231,"BACKFILL") -> 0 | G21: =SUMIFS('Cast In Situ Tracker'!Q7:Q15411,'Cast In Situ Tracker'!T7:T15411,"Temporary*",'Cast In Situ Tracker'!P7:P15411,"Blinding") -> 753 | H21: =SUMIFS('Cast In Situ Tracker'!Q7:Q15231,'Cast In Situ Tracker'!T7:T15231,"Temporary*",'Cast In Situ Tracker'!P7:P15231,"Column and Retaining Wall") -> 6 | I21: =SUMIFS('Cast In Situ Tracker'!Q7:Q15411,'Cast In Situ Tracker'!T7:T15411,"Temporary*",'Cast In Situ Tracker'!P7:P15411,"Footing, Slab ") -> 0 | J21: 0 | K21: =SUMIFS('Cast In Situ Tracker'!Q7:Q248,'Cast In Situ Tracker'!T7:T248,"L1-N1*",'Cast In Situ Tracker'!P7:P248,"Center Slab") -> 0 | M21: =SUM(F21:I22) -> 759 | N21: =ROUNDUP(M21/40,0) -> 19 | Q21: 8 | R21: =N21 -> 19 | S21: =Q21 -> 8 | T21: =ROUNDUP(I21/100,0) -> 0 | W21: =COUNTIFS('Cast In Situ Tracker'!T11:T217,"Temporary*",'Cast In Situ Tracker'!#REF!,"<>") -> #REF! | X21: =ROUNDUP(I21/200,0) -> 0 | AA21: 9
C23: Langham Hotel | D23: Permanent Work | J23: 0 | K23: 0 | N23: =ROUNDUP(M23/40,0) -> 0 | R23: =N23 -> 0 | T23: =ROUNDUP(I23/100,0) -> 0 | X23: =ROUNDUP(I23/200,0) -> 0
D25: Temporary | J25: 0 | K25: 0 | N25: =ROUNDUP(M25/40,0) -> 0 | R25: =N25 -> 0 | T25: =ROUNDUP(I25/100,0) -> 0 | X25: =ROUNDUP(I25/200,0) -> 0
C27: Mixed Use Residential | D27: Permanent Work | J27: 0 | K27: 0 | N27: =ROUNDUP(M27/40,0) -> 0 | R27: =N27 -> 0 | T27: =ROUNDUP(I27/100,0) -> 0 | X27: =ROUNDUP(I27/200,0) -> 0
D29: Temporary | J29: 0 | K29: 0 | N29: =ROUNDUP(M29/40,0) -> 0 | R29: =N29 -> 0 | T29: =ROUNDUP(I29/100,0) -> 0 | X29: =ROUNDUP(I29/200,0) -> 0
C31: Public Realm | D31: Permanent Work | J31: 0 | K31: 0 | N31: =ROUNDUP(M31/40,0) -> 0 | R31: =N31 -> 0 | T31: =ROUNDUP(I31/100,0) -> 0 | X31: =ROUNDUP(I31/200,0) -> 0
D33: Temporary | J33: 0 | K33: 0 | N33: =ROUNDUP(M33/40,0) -> 0 | R33: =N33 -> 0 | T33: =ROUNDUP(I33/100,0) -> 0 | X33: =ROUNDUP(I33/200,0) -> 0
C35: Energy Centre | D35: Permanent Work | J35: 0 | K35: 0 | N35: =ROUNDUP(M35/40,0) -> 0 | R35: =N35 -> 0 | T35: =ROUNDUP(I35/100,0) -> 0 | X35: =ROUNDUP(I35/200,0) -> 0
D37: Temporary | J37: 0 | K37: 0 | N37: =ROUNDUP(M37/40,0) -> 0 | R37: =N37 -> 0 | T37: =ROUNDUP(I37/100,0) -> 0 | X37: =ROUNDUP(I37/200,0) -> 0
J39: 0 | K39: 0
C41: TOTAL | F41: =SUM(F7:F38) -> 15535 | G41: =SUM(G7:G40) -> 10212 | H41: =SUM(H7:H38) -> 18569 | I41: =SUM(I7:I38) -> 33599 | J41: 7 | K41: =SUM(K16:K38) -> 0 | L41: =SUM(L7:L38) -> 282 | M41: =SUM(M7:M22) -> 77915
